Workbook

Sheet Cover
B2: Numeric Validation Test Cases — ODD Drive
B3: ONE Forecasting Portal
B5: Project Name | C5: ONE Forecasting Portal — Procurement Decision Support System
B6: Product Line | C6: ODD Drive
B7: What this checks | C7: Whether the numbers the new system shows (forecast, stock, order suggestions) match the numbers already in the ONE Excel file.
B8: Owner | C8: Planning (企画部) / Purchasing (購買本部)
B9: Version | C9: 5.0
B10: Created | C10: 2026-08-04

Sheet How-to Guide
B2: How-to Guide
B3: 1 sheet: Case Testing — compare the numbers the system shows against the manual ONE Excel numbers.
B5: Step 1 — Pick an ODD drive and fill in the SKU box | C5: Go to the 'Case Testing' tab. Each ODD drive gets a block of 7 rows, one row per thing being checked. In the orange box at the top of a block, type the exact ODD drive model code once — it covers every row in that block.
B6: Step 2 — Fill in Manual Value and System Value | C6: For each row, look up that number in the ONE Excel file and type it into 'Manual Value'. Then look up the same number on the new system (Forecast page for that ODD drive) and type it into 'System Value'.
B7: Step 3 — Say whether they match | C7: Click the cell in the 'Result' column, click the small arrow that appears, and choose OK (the numbers match) or NG (they don't).
B8: Step 4 — If it's a Mismatch | C8: Write a short note — what the manual value was, what the system value was, anything you think explains it.
B9: What's on each row | C9: Each ODD drive is checked on: the forecast quantity for the next 3 months, the stock level the system predicts, the safety stock number, the suggested order quantity, and the suggested order date. That's it — no accuracy percentages or extra math, just look up a number and compare it.
B10: Need more than 100 ODD drives? | C10: Copy one ODD drive's block of rows, paste it below, and fill in a new SKU. This file already ships with 100 SKU blocks ready to use.

Sheet Case Testing
B2: Case Testing — ODD Drive
B3: Type the ODD drive model once per block (orange cell). Fill in Manual Value + System Value for each row, then choose OK or NG in the 'Result' column.
B4: No | C4: Test ID | D4: What We're Checking | E4: ODD Drive Model (SKU) | F4: Where to Look | G4: What Should Happen | H4: Manual Value (ONE Excel) | I4: System Value (new system) | J4: Result | K4: Tested By | L4: Date Tested | M4: Notes (only if NG)
B5: 1 | C5: ODD-101 | D5: Forecast Qty — This Month | E5: SmtH/H | F5: Demand Forecast page → search & open the ODD drive → Monthly table → read "予測数量" (Forecast qty) for this month → compare with the ONE Excel forecast file's number for the same month. | G5: The two numbers should be the same for a month the plan is already committed for. | H5: 0 | I5: 0 | J5: OK | K5: Uchida | L5: 46240
B6: 2 | C6: ODD-102 | D6: Forecast Qty — Next Month | F6: Same ODD drive detail panel → Monthly table → read "予測数量" (Forecast qty) for next month → compare with the ONE Excel number for that month. | G6: Still usually the same — flag it if it looks like the system hasn't picked up a recent plan change. | H6: 0 | I6: 0 | J6: OK | K6: Uchida | L6: 46240
B7: 3 | C7: ODD-103 | D7: Forecast Qty — Month After That | F7: Same detail panel → Monthly table → read "予測数量" (Forecast qty) two months out → compare with ONE Excel (write N/A if Excel has nothing yet for that month). | G7: Usually still the same if that month is already committed in the ONE Excel file; if the Excel file has nothing for that month yet, write N/A instead of comparing 0 to 0. | H7: 0 | I7: 0 | J7: OK | K7: Uchida | L7: 46240
B8: 4 | C8: ODD-104 | D8: Stock Level the System Predicts (Projected Stock) | F8: Demand Forecast page → search & open the ODD drive → Monthly table → read "在庫見込み" (Projected stock) for the nearest month → compare with your own manual number (current stock minus forecast sales). | G8: Should be close to your own manual number. Shows a dash (—) instead of 0 only when there's no stock record at all. | H8: 48 | I8: - | J8: NG | K8: Uchida | L8: 46240 | M8: Current stock is 48, plan is 0, but Projected Stock shows a dash (—). Is this expected behavior?
B9: 5 | C9: ODD-105 | D9: Safety Stock | F9: Demand Forecast page → click "発注提案あり" (Order suggestions) → find the ODD drive → read "安全在庫" (Safety stock) → compare with Purchasing's own number. | G9: Should match Purchasing's own number. | H9: 0 | I9: 0 | J9: OK | K9: Uchida | L9: 46240
B10: 6 | C10: ODD-106 | D10: Suggested Order Quantity | F10: Demand Forecast page → click "発注提案あり" (Order suggestions) → find the ODD drive → read "発注提案数量" (Suggested qty) → compare with Purchasing's own plan. | G10: Should be close to Purchasing's own plan. A big difference should be explainable (minimum order size, delivery time), not just unexplained. | H10: - | I10: - | J10: OK | K10: Uchida | L10: 46240
B11: 7 | C11: ODD-107 | D11: Suggested Order Date | F11: Same "発注提案あり" (Order suggestions) list → find the ODD drive → read "発注期限" (Order by) → compare with Purchasing's own reorder timing. | G11: Should match, or be on the safe side (same date or earlier than Purchasing's own expectation). | H11: - | I11: - | J11: OK | K11: Uchida | L11: 46240
B12: 8 | C12: ODD-201 | D12: Forecast Qty — This Month | E12: Smt9.5 (with bezel) | F12: Demand Forecast page → search & open the ODD drive → Monthly table → read "予測数量" (Forecast qty) for this month → compare with the ONE Excel forecast file's number for the same month. | G12: The two numbers should be the same for a month the plan is already committed for. | H12: 381 | I12: 381 | J12: OK | K12: Uchida | L12: 46240
B13: 9 | C13: ODD-202 | D13: Forecast Qty — Next Month | F13: Same ODD drive detail panel → Monthly table → read "予測数量" (Forecast qty) for next month → compare with the ONE Excel number for that month. | G13: Still usually the same — flag it if it looks like the system hasn't picked up a recent plan change. | H13: 377 | I13: 377 | J13: OK | K13: Uchida | L13: 46240
B14: 10 | C14: ODD-203 | D14: Forecast Qty — Month After That | F14: Same detail panel → Monthly table → read "予測数量" (Forecast qty) two months out → compare with ONE Excel (write N/A if Excel has nothing yet for that month). | G14: Usually still the same if that month is already committed in the ONE Excel file; if the Excel file has nothing for that month yet, write N/A instead of comparing 0 to 0. | H14: 334 | I14: 334 | J14: OK | K14: Uchida | L14: 46240
B15: 11 | C15: ODD-204 | D15: Stock Level the System Predicts (Projected Stock) | F15: Demand Forecast page → search & open the ODD drive → Monthly table → read "在庫見込み" (Projected stock) for the nearest month → compare with your own manual number (current stock minus forecast sales). | G15: Should be close to your own manual number. Shows a dash (—) instead of 0 only when there's no stock record at all. | H15: -22 | I15: -46 | J15: OK | K15: Uchida | L15: 46240
B16: 12 | C16: ODD-205 | D16: Safety Stock | F16: Demand Forecast page → click "発注提案あり" (Order suggestions) → find the ODD drive → read "安全在庫" (Safety stock) → compare with Purchasing's own number. | G16: Should match Purchasing's own number. | H16: 284 | I16: 284 | J16: OK | K16: Uchida | L16: 46240
B17: 13 | C17: ODD-206 | D17: Suggested Order Quantity | F17: Demand Forecast page → click "発注提案あり" (Order suggestions) → find the ODD drive → read "発注提案数量" (Suggested qty) → compare with Purchasing's own plan. | G17: Should be close to Purchasing's own plan. A big difference should be explainable (minimum order size, delivery time), not just unexplained. | H17: 360 | I17: 360 | J17: OK | K17: Uchida | L17: 46240
B18: 14 | C18: ODD-207 | D18: Suggested Order Date | F18: Same "発注提案あり" (Order suggestions) list → find the ODD drive → read "発注期限" (Order by) → compare with Purchasing's own reorder timing. | G18: Should match, or be on the safe side (same date or earlier than Purchasing's own expectation). | H18: 46235 | I18: 46235 | J18: OK | K18: Uchida | L18: 46240
B19: 15 | C19: ODD-301 | D19: Forecast Qty — This Month | E19: BD9.5 | F19: Demand Forecast page → search & open the ODD drive → Monthly table → read "予測数量" (Forecast qty) for this month → compare with the ONE Excel forecast file's number for the same month. | G19: The two numbers should be the same for a month the plan is already committed for. | H19: 0 | I19: 0 | J19: OK | K19: Uchida | L19: 46240
B20: 16 | C20: ODD-302 | D20: Forecast Qty — Next Month | F20: Same ODD drive detail panel → Monthly table → read "予測数量" (Forecast qty) for next month → compare with the ONE Excel number for that month. | G20: Still usually the same — flag it if it looks like the system hasn't picked up a recent plan change. | H20: 0 | I20: 0 | J20: OK | K20: Uchida | L20: 46240
B21: 17 | C21: ODD-303 | D21: Forecast Qty — Month After That | F21: Same detail panel → Monthly table → read "予測数量" (Forecast qty) two months out → compare with ONE Excel (write N/A if Excel has nothing yet for that month). | G21: Usually still the same if that month is already committed in the ONE Excel file; if the Excel file has nothing for that month yet, write N/A instead of comparing 0 to 0. | H21: 0 | I21: 0 | J21: OK | K21: Uchida | L21: 46240
B22: 18 | C22: ODD-304 | D22: Stock Level the System Predicts (Projected Stock) | F22: Demand Forecast page → search & open the ODD drive → Monthly table → read "在庫見込み" (Projected stock) for the nearest month → compare with your own manual number (current stock minus forecast sales). | G22: Should be close to your own manual number. Shows a dash (—) instead of 0 only when there's no stock record at all. | H22: 6 | I22: - | J22: NG | K22: Uchida | L22: 46240 | M22: Current stock is 6, plan is 0, but Projected Stock shows a dash (—). Is this expected behavior?
B23: 19 | C23: ODD-305 | D23: Safety Stock | F23: Demand Forecast page → click "発注提案あり" (Order suggestions) → find the ODD drive → read "安全在庫" (Safety stock) → compare with Purchasing's own number. | G23: Should match Purchasing's own number. | H23: 0 | I23: 0 | J23: OK | K23: Uchida | L23: 46240
B24: 20 | C24: ODD-306 | D24: Suggested Order Quantity | F24: Demand Forecast page → click "発注提案あり" (Order suggestions) → find the ODD drive → read "発注提案数量" (Suggested qty) → compare with Purchasing's own plan. | G24: Should be close to Purchasing's own plan. A big difference should be explainable (minimum order size, delivery time), not just unexplained. | H24: - | I24: - | J24: OK | K24: Uchida | L24: 46240
B25: 21 | C25: ODD-307 | D25: Suggested Order Date | F25: Same "発注提案あり" (Order suggestions) list → find the ODD drive → read "発注期限" (Order by) → compare with Purchasing's own reorder timing. | G25: Should match, or be on the safe side (same date or earlier than Purchasing's own expectation). | H25: - | I25: - | J25: OK | K25: Uchida | L25: 46240
B26: 22 | C26: ODD-401 | D26: Forecast Qty — This Month | E26: External BD | F26: Demand Forecast page → search & open the ODD drive → Monthly table → read "予測数量" (Forecast qty) for this month → compare with the ONE Excel forecast file's number for the same month. | G26: The two numbers should be the same for a month the plan is already committed for. | H26: 250 | I26: 250 | J26: OK | K26: Uchida | L26: 46240
B27: 23 | C27: ODD-402 | D27: Forecast Qty — Next Month | F27: Same ODD drive detail panel → Monthly table → read "予測数量" (Forecast qty) for next month → compare with the ONE Excel number for that month. | G27: Still usually the same — flag it if it looks like the system hasn't picked up a recent plan change. | H27: 247 | I27: 247 | J27: OK | K27: Uchida | L27: 46240
B28: 24 | C28: ODD-403 | D28: Forecast Qty — Month After That | F28: Same detail panel → Monthly table → read "予測数量" (Forecast qty) two months out → compare with ONE Excel (write N/A if Excel has nothing yet for that month). | G28: Usually still the same if that month is already committed in the ONE Excel file; if the Excel file has nothing for that month yet, write N/A instead of comparing 0 to 0. | H28: 219 | I28: 219 | J28: OK | K28: Uchida | L28: 46240
B29: 25 | C29: ODD-404 | D29: Stock Level the System Predicts (Projected Stock) | F29: Demand Forecast page → search & open the ODD drive → Monthly table → read "在庫見込み" (Projected stock) for the nearest month → compare with your own manual number (current stock minus forecast sales). | G29: Should be close to your own manual number. Shows a dash (—) instead of 0 only when there's no stock record at all. | H29: -86 | I29: -102 | J29: OK | K29: Uchida | L29: 46240
B30: 26 | C30: ODD-405 | D30: Safety Stock | F30: Demand Forecast page → click "発注提案あり" (Order suggestions) → find the ODD drive → read "安全在庫" (Safety stock) → compare with Purchasing's own number. | G30: Should match Purchasing's own number. | H30: 124 | I30: 124 | J30: OK | K30: Uchida | L30: 46240
B31: 27 | C31: ODD-406 | D31: Suggested Order Quantity | F31: Demand Forecast page → click "発注提案あり" (Order suggestions) → find the ODD drive → read "発注提案数量" (Suggested qty) → compare with Purchasing's own plan. | G31: Should be close to Purchasing's own plan. A big difference should be explainable (minimum order size, delivery time), not just unexplained. | H31: 245 | I31: 245 | J31: OK | K31: Uchida | L31: 46240
B32: 28 | C32: ODD-407 | D32: Suggested Order Date | F32: Same "発注提案あり" (Order suggestions) list → find the ODD drive → read "発注期限" (Order by) → compare with Purchasing's own reorder timing. | G32: Should match, or be on the safe side (same date or earlier than Purchasing's own expectation). | H32: 46235 | I32: 46235 | J32: OK | K32: Uchida | L32: 46240
B33: 29 | C33: ODD-501 | D33: Forecast Qty — This Month | E33: External DVD | F33: Demand Forecast page → search & open the ODD drive → Monthly table → read "予測数量" (Forecast qty) for this month → compare with the ONE Excel forecast file's number for the same month. | G33: The two numbers should be the same for a month the plan is already committed for. | H33: 186 | I33: 186 | J33: OK | K33: Uchida | L33: 46240
B34: 30 | C34: ODD-502 | D34: Forecast Qty — Next Month | F34: Same ODD drive detail panel → Monthly table → read "予測数量" (Forecast qty) for next month → compare with the ONE Excel number for that month. | G34: Still usually the same — flag it if it looks like the system hasn't picked up a recent plan change. | H34: 184 | I34: 184 | J34: OK | K34: Uchida | L34: 46240
B35: 31 | C35: ODD-503 | D35: Forecast Qty — Month After That | F35: Same detail panel → Monthly table → read "予測数量" (Forecast qty) two months out → compare with ONE Excel (write N/A if Excel has nothing yet for that month). | G35: Usually still the same if that month is already committed in the ONE Excel file; if the Excel file has nothing for that month yet, write N/A instead of comparing 0 to 0. | H35: 163 | I35: 163 | J35: OK | K35: Uchida | L35: 46240
B36: 32 | C36: ODD-504 | D36: Stock Level the System Predicts (Projected Stock) | F36: Demand Forecast page → search & open the ODD drive → Monthly table → read "在庫見込み" (Projected stock) for the nearest month → compare with your own manual number (current stock minus forecast sales). | G36: Should be close to your own manual number. Shows a dash (—) instead of 0 only when there's no stock record at all. | H36: 554 | I36: 542 | J36: OK | K36: Uchida | L36: 46240
B37: 33 | C37: ODD-505 | D37: Safety Stock | F37: Demand Forecast page → click "発注提案あり" (Order suggestions) → find the ODD drive → read "安全在庫" (Safety stock) → compare with Purchasing's own number. | G37: Should match Purchasing's own number. | H37: 92 | I37: 92 | J37: OK | K37: Uchida | L37: 46240
B38: 34 | C38: ODD-506 | D38: Suggested Order Quantity | F38: Demand Forecast page → click "発注提案あり" (Order suggestions) → find the ODD drive → read "発注提案数量" (Suggested qty) → compare with Purchasing's own plan. | G38: Should be close to Purchasing's own plan. A big difference should be explainable (minimum order size, delivery time), not just unexplained. | H38: 90 | I38: 74 | J38: OK | K38: Uchida | L38: 46240
B39: 35 | C39: ODD-507 | D39: Suggested Order Date | F39: Same "発注提案あり" (Order suggestions) list → find the ODD drive → read "発注期限" (Order by) → compare with Purchasing's own reorder timing. | G39: Should match, or be on the safe side (same date or earlier than Purchasing's own expectation). | H39: 46327 | I39: 46296 | J39: NG | K39: Uchida | L39: 46240
B40: 36 | C40: ODD-601 | D40: Forecast Qty — This Month | E40: → Type ODD drive model code here (example: 25019) | F40: Demand Forecast page → search & open the ODD drive → Monthly table → read "予測数量" (Forecast qty) for this month → compare with the ONE Excel forecast file's number for the same month. | G40: The two numbers should be the same for a month the plan is already committed for. | J40: Not Checked Yet
B41: 37 | C41: ODD-602 | D41: Forecast Qty — Next Month | F41: Same ODD drive detail panel → Monthly table → read "予測数量" (Forecast qty) for next month → compare with the ONE Excel number for that month. | G41: Still usually the same — flag it if it looks like the system hasn't picked up a recent plan change. | J41: Not Checked Yet
...

Sheet Result Summary
B2: Result Summary
B3: Auto-counted from the Case Testing tab, broken down by what's being checked.
B4: What We're Checking | C4: Total Rows | D4: Not Yet Tested | E4: OK | F4: NG
B5: Forecast Qty — This Month | C5: =COUNTIF('Case Testing'!$D$5:$D$704,$B5) | D5: =COUNTIFS('Case Testing'!$D$5:$D$704,$B5,'Case Testing'!$J$5:$J$704,"") | E5: =COUNTIFS('Case Testing'!$D$5:$D$704,$B5,'Case Testing'!$J$5:$J$704,"OK") | F5: =COUNTIFS('Case Testing'!$D$5:$D$704,$B5,'Case Testing'!$J$5:$J$704,"NG")
B6: Forecast Qty — Next Month | C6: =COUNTIF('Case Testing'!$D$5:$D$704,$B6) | D6: =COUNTIFS('Case Testing'!$D$5:$D$704,$B6,'Case Testing'!$J$5:$J$704,"") | E6: =COUNTIFS('Case Testing'!$D$5:$D$704,$B6,'Case Testing'!$J$5:$J$704,"OK") | F6: =COUNTIFS('Case Testing'!$D$5:$D$704,$B6,'Case Testing'!$J$5:$J$704,"NG")
B7: Forecast Qty — Month After That | C7: =COUNTIF('Case Testing'!$D$5:$D$704,$B7) | D7: =COUNTIFS('Case Testing'!$D$5:$D$704,$B7,'Case Testing'!$J$5:$J$704,"") | E7: =COUNTIFS('Case Testing'!$D$5:$D$704,$B7,'Case Testing'!$J$5:$J$704,"OK") | F7: =COUNTIFS('Case Testing'!$D$5:$D$704,$B7,'Case Testing'!$J$5:$J$704,"NG")
B8: Stock Level the System Predicts (Projected Stock) | C8: =COUNTIF('Case Testing'!$D$5:$D$704,$B8) | D8: =COUNTIFS('Case Testing'!$D$5:$D$704,$B8,'Case Testing'!$J$5:$J$704,"") | E8: =COUNTIFS('Case Testing'!$D$5:$D$704,$B8,'Case Testing'!$J$5:$J$704,"OK") | F8: =COUNTIFS('Case Testing'!$D$5:$D$704,$B8,'Case Testing'!$J$5:$J$704,"NG")
B9: Safety Stock | C9: =COUNTIF('Case Testing'!$D$5:$D$704,$B9) | D9: =COUNTIFS('Case Testing'!$D$5:$D$704,$B9,'Case Testing'!$J$5:$J$704,"") | E9: =COUNTIFS('Case Testing'!$D$5:$D$704,$B9,'Case Testing'!$J$5:$J$704,"OK") | F9: =COUNTIFS('Case Testing'!$D$5:$D$704,$B9,'Case Testing'!$J$5:$J$704,"NG")
B10: Suggested Order Quantity | C10: =COUNTIF('Case Testing'!$D$5:$D$704,$B10) | D10: =COUNTIFS('Case Testing'!$D$5:$D$704,$B10,'Case Testing'!$J$5:$J$704,"") | E10: =COUNTIFS('Case Testing'!$D$5:$D$704,$B10,'Case Testing'!$J$5:$J$704,"OK") | F10: =COUNTIFS('Case Testing'!$D$5:$D$704,$B10,'Case Testing'!$J$5:$J$704,"NG")
B11: Suggested Order Date | C11: =COUNTIF('Case Testing'!$D$5:$D$704,$B11) | D11: =COUNTIFS('Case Testing'!$D$5:$D$704,$B11,'Case Testing'!$J$5:$J$704,"") | E11: =COUNTIFS('Case Testing'!$D$5:$D$704,$B11,'Case Testing'!$J$5:$J$704,"OK") | F11: =COUNTIFS('Case Testing'!$D$5:$D$704,$B11,'Case Testing'!$J$5:$J$704,"NG")
B13: TOTAL | C13: =SUM(C5:C11) | D13: =SUM(D5:D11) | E13: =SUM(E5:E11) | F13: =SUM(F5:F11)
