Workbook

Sheet All Products
A1: No. | B1: Category | C1: Product (綽名) | D1: Type | E1: Physical Stock (SAP, 6/29) | F1: Current Stock (ONE plan, 6/30) | G1: Used-Sold This Week (Plan, w/c 6/29) | H1: Used-Sold This Week (Actual, w/c 6/29) | I1: Forecast Jul-2026 | J1: Forecast Aug-2026 | K1: Forecast Sep-2026 | L1: Forecast 3-Month Total (Jul-Sep)
A2: 1 | B2: CPU | C2: Ry53400G | D2: Product | E2: 90 | F2: 67 | G2: 20 | I2: 88.6 | J2: 62.8 | K2: 57.8 | L2: =IF(COUNT(I2:K2)=0,"",SUM(I2:K2)) -> 209.2
A3: 2 | B3: CPU | C3: Ry54500 | D3: Product | E3: 95 | F3: 46.9 | G3: 44 | I3: 194.9 | J3: 139 | K3: 127.9 | L3: =IF(COUNT(I3:K3)=0,"",SUM(I3:K3)) -> 461.8
A4: 3 | B4: CPU | C4: Ry55500GT | D4: Product | E4: 973 | F4: 893.4 | G4: 59 | I4: 261.3 | J4: 175.4 | K4: 160.9 | L4: =IF(COUNT(I4:K4)=0,"",SUM(I4:K4)) -> 597.6
A5: 4 | B5: CPU | C5: Ry55500GT MPK | D5: Product | E5: 973 | F5: 42.6 | G5: 40 | I5: 177.1 | J5: 155.5 | K5: 144.4 | L5: =IF(COUNT(I5:K5)=0,"",SUM(I5:K5)) -> 477
A6: 5 | B6: CPU | C6: Ry57500F | D6: Product | E6: 1957 | F6: 1751.1 | G6: 183 | I6: 810.4 | J6: 574 | K6: 528.1 | L6: =IF(COUNT(I6:K6)=0,"",SUM(I6:K6)) -> 1912.5
A7: 6 | B7: CPU | C7: Ry58500G | D7: Product | E7: 18 | F7: 16 | G7: 0.9 | I7: 3.8 | J7: 3.2 | K7: 3 | L7: =IF(COUNT(I7:K7)=0,"",SUM(I7:K7)) -> 10
A8: 7 | B8: CPU | C8: Ry58600G | D8: Product | E8: 13 | F8: 10.7 | G8: 1 | I8: 4.4 | J8: 3.8 | K8: 3.5 | L8: =IF(COUNT(I8:K8)=0,"",SUM(I8:K8)) -> 11.7
A9: 8 | B9: CPU | C9: Ry59600X | D9: Product | E9: 7 | F9: 7 | G9: 0 | I9: 0 | J9: 0 | K9: 0 | L9: =IF(COUNT(I9:K9)=0,"",SUM(I9:K9)) -> 0
A10: 9 | B10: CPU | C10: Ry75700X | D10: Product | E10: 2145 | F10: 2164.4 | G10: 72 | I10: 318.9 | J10: 1542.5 | K10: 1477.1 | L10: =IF(COUNT(I10:K10)=0,"",SUM(I10:K10)) -> 3338.5
A11: 10 | B11: CPU | C11: Ry77700 | D11: Product | E11: 1954 | F11: 1463.9 | G11: 1101 | I11: 4875.9 | J11: 3838.1 | K11: 3548.3 | L11: =IF(COUNT(I11:K11)=0,"",SUM(I11:K11)) -> 12262.3
A12: 11 | B12: CPU | C12: Ry77800X3D | D12: Product | E12: 452 | F12: 405.3 | G12: 73 | I12: 323.3 | J12: 237.3 | K12: 218.7 | L12: =IF(COUNT(I12:K12)=0,"",SUM(I12:K12)) -> 779.3
A13: 12 | B13: CPU | C13: Ry78700G | D13: Product | E13: 10 | F13: 12.7 | G13: 1 | I13: 4.4 | J13: 3.8 | K13: 3.5 | L13: =IF(COUNT(I13:K13)=0,"",SUM(I13:K13)) -> 11.7
... A19: 18 | B19: CPU | C19: Ry99950X3D2 | D19: Product | E19: 21 | F19: 19.4 | G19: 2 | I19: 8.9 | J19: 7.5 | K19: 7 | L19: =IF(COUNT(I19:K19)=0,"",SUM(I19:K19)) -> 23.4
A20: 19 | B20: CPU | C20: U5-225 | D20: Product | E20: 970 | F20: 125.7 | G20: 313 | H20: 544 | I20: 1386.1 | J20: 1211.6 | K20: 1162.3 | L20: =IF(COUNT(I20:K20)=0,"",SUM(I20:K20)) -> 3760
A21: 20 | B21: CPU | C21: U5-225F | D21: Product | E21: 701 | F21: 79.4 | G21: 198 | H21: 178 | I21: 876.9 | J21: 744.9 | K21: 714.3 | L21: =IF(COUNT(I21:K21)=0,"",SUM(I21:K21)) -> 2336.1
A22: 21 | B22: CPU | C22: U5-235 | D22: Product | E22: 63 | F22: 17.7 | G22: 18 | H22: 25 | I22: 79.7 | J22: 71.1 | K22: 67.4 | L22: =IF(COUNT(I22:K22)=0,"",SUM(I22:K22)) -> 218.2
A23: 22 | B23: CPU | C23: U5-245KF | D23: Product | E23: 167 | F23: 150.3 | G23: 9 | H23: 0 | I23: 39.9 | J23: 31 | K23: 25.7 | L23: =IF(COUNT(I23:K23)=0,"",SUM(I23:K23)) -> 96.6
A24: 23 | B24: CPU | C24: U7-265 | D24: Product | E24: 360 | F24: 76.6 | G24: 119 | H24: 163 | I24: 527 | J24: 458.7 | K24: 438.3 | L24: =IF(COUNT(I24:K24)=0,"",SUM(I24:K24)) -> 1424
A25: 24 | B25: CPU | C25: U7-265F | D25: Product | E25: 849 | F25: 441.1 | G25: 255 | H25: 320 | I25: 1129.3 | J25: 992.7 | K25: 1073.4 | L25: =IF(COUNT(I25:K25)=0,"",SUM(I25:K25)) -> 3195.4
A26: 25 | B26: CPU | C26: U7-265K | D26: Product | E26: 23 | F26: 24 | G26: 0 | H26: 0 | I26: 0 | J26: 0 | K26: 0 | L26: =IF(COUNT(I26:K26)=0,"",SUM(I26:K26)) -> 0
A27: 26 | B27: CPU | C27: U7-265KF | D27: Product | E27: 57 | F27: 52.7 | G27: 0 | H27: 20 | I27: 0 | J27: 0 | K27: 0 | L27: =IF(COUNT(I27:K27)=0,"",SUM(I27:K27)) -> 0
A28: 27 | B28: CPU | C28: U7-265T | D28: Product | E28: 15 | F28: 13.7 | G28: 1 | H28: 1 | I28: 4.4 | J28: 3.8 | K28: 3.5 | L28: =IF(COUNT(I28:K28)=0,"",SUM(I28:K28)) -> 11.7
A29: 28 | B29: CPU | C29: U7-270K Plus | D29: Product | E29: 874 | F29: 62.6 | G29: 68 | H29: 32 | I29: 301.1 | J29: 254.3 | K29: 243.4 | L29: =IF(COUNT(I29:K29)=0,"",SUM(I29:K29)) -> 798.8
A30: 29 | B30: CPU | C30: U9-285 | D30: Product | E30: 8 | F30: 10.6 | G30: 5 | H30: 5 | I30: 22.1 | J30: 22.1 | K30: 22.6 | L30: =IF(COUNT(I30:K30)=0,"",SUM(I30:K30)) -> 66.8
A31: 30 | B31: CPU | C31: U9-285K | D31: Product | E31: 328 | F31: 32.1 | G31: 37 | H31: 31 | I31: 163.9 | J31: 147 | K31: 144.6 | L31: =IF(COUNT(I31:K31)=0,"",SUM(I31:K31)) -> 455.5
A32: 31 | B32: CPU | C32: W11H64DSP | D32: Product | E32: 32 | F32: 21.6 | G32: 5 | I32: 22.1 | J32: 18.9 | K32: 17.5 | L32: =IF(COUNT(I32:K32)=0,"",SUM(I32:K32)) -> 58.5
A33: 32 | B33: CPU | C33: W11Pro64DSP | D33: Product | E33: 31 | F33: 22.6 | G33: 12 | I33: 53.1 | J33: 45.2 | K33: 42 | L33: =IF(COUNT(I33:K33)=0,"",SUM(I33:K33)) -> 140.3
A34: 33 | B34: CPU | C34: i512400 | D34: Product | E34: 1466 | F34: 1425.3 | G34: 49 | I34: 217 | J34: 187 | K34: 176 | L34: =IF(COUNT(I34:K34)=0,"",SUM(I34:K34)) -> 580
A35: 34 | B35: CPU | C35: i512400F | D35: Product | E35: 7 | F35: 7 | G35: 0 | I35: 0 | J35: 0 | K35: 0 | L35: =IF(COUNT(I35:K35)=0,"",SUM(I35:K35)) -> 0
A36: 35 | B36: CPU | C36: i514400 | D36: Product | E36: 133 | F36: 160 | G36: 0 | I36: 0 | J36: 0 | K36: 0 | L36: =IF(COUNT(I36:K36)=0,"",SUM(I36:K36)) -> 0
A37: 36 | B37: CPU | C37: i514400F | D37: Product | E37: 105 | F37: 35.6 | G37: 0 | I37: 0 | J37: 0 | K37: 0 | L37: =IF(COUNT(I37:K37)=0,"",SUM(I37:K37)) -> 0
A38: 37 | B38: CPU | C38: i714700 | D38: Product | F38: -16 | G38: 0 | I38: 0 | J38: 0 | K38: 0 | L38: =IF(COUNT(I38:K38)=0,"",SUM(I38:K38)) -> 0
A39: 38 | B39: CPU | C39: i714700F | D39: Product | E39: 590 | F39: 637.9 | G39: 54 | I39: 239.1 | J39: 205.1 | K39: 197.4 | L39: =IF(COUNT(I39:K39)=0,"",SUM(I39:K39)) -> 641.6
A40: 39 | B40: MB | C40: A520M | D40: Product | E40: 1656 | F40: 1616 | G40: 127.6 | I40: 580.3 | J40: 497.1 | K40: 487.9 | L40: =IF(COUNT(I40:K40)=0,"",SUM(I40:K40)) -> 1565.3
A41: 40 | B41: MB | C41: A620AM | D41: Product | F41: 7154 | G41: 557.5 | H41: 456 | I41: 2538.7 | J41: 1811 | K41: 1756.5 | L41: =IF(COUNT(I41:K41)=0,"",SUM(I41:K41)) -> 6106.2
A42: 41 | B42: MB | C42: A620AM WH | D42: Product | E42: 511 | F42: 507.9 | G42: 4.3 | H42: 4 | I42: 19.5 | J42: 16.5 | K42: 16.2 | L42: =IF(COUNT(I42:K42)=0,"",SUM(I42:K42)) -> 52.2
A43: 42 | B43: MB | C43: ASR B760M D5 | D43: Product | F43: 3 | G43: 0 | H43: -1 | I43: 0 | J43: 0 | K43: 0 | L43: =IF(COUNT(I43:K43)=0,"",SUM(I43:K43)) -> 0
A44: 43 | B44: MB | C44: B550M | D44: Product | E44: 5075 | F44: 5083.3 | G44: 103.3 | H44: 142 | I44: 470 | J44: 1101 | K44: 1079.6 | L44: =IF(COUNT(I44:K44)=0,"",SUM(I44:K44)) -> 2650.6
A45: 44 | B45: MB | C45: B760 TW D5 | D45: Product | F45: 532 | G45: 0 | H45: 24 | I45: 0 | J45: 0 | K45: 0 | L45: =IF(COUNT(I45:K45)=0,"",SUM(I45:K45)) -> 0
...

Sheet Category Summary
A1: Category | B1: Unique Products (excl. rollups) | C1: Physical Stock (SAP, units) | D1: Current Stock (ONE plan, units) | E1: Used-Sold This Week (Plan) | F1: Used-Sold This Week (Actual, tracked items) | G1: Forecast Jul-2026 | H1: Forecast Aug-2026 | I1: Forecast Sep-2026 | J1: Forecast 3-Month Total
A2: CPU | B2: =COUNTIFS('All Products'!B:B,A2,'All Products'!D:D,"Product") -> 38 | C2: =SUMIFS('All Products'!E:E,'All Products'!B:B,A2,'All Products'!D:D,"Product") -> 18895 | D2: =SUMIFS('All Products'!F:F,'All Products'!B:B,A2,'All Products'!D:D,"Product") -> 13154.9 | E2: =SUMIFS('All Products'!G:G,'All Products'!B:B,A2,'All Products'!D:D,"Product") -> 3186.9 | F2: =SUMIFS('All Products'!H:H,'All Products'!B:B,A2,'All Products'!D:D,"Product") -> 1319 | G2: =SUMIFS('All Products'!I:I,'All Products'!B:B,A2,'All Products'!D:D,"Product") -> 14113.2 | H2: =SUMIFS('All Products'!J:J,'All Products'!B:B,A2,'All Products'!D:D,"Product") -> 12492.2 | I2: =SUMIFS('All Products'!K:K,'All Products'!B:B,A2,'All Products'!D:D,"Product") -> 11854 | J2: =SUMIFS('All Products'!L:L,'All Products'!B:B,A2,'All Products'!D:D,"Product") -> 38459.4
A3: MB | B3: =COUNTIFS('All Products'!B:B,A3,'All Products'!D:D,"Product") -> 38 | C3: =SUMIFS('All Products'!E:E,'All Products'!B:B,A3,'All Products'!D:D,"Product") -> 45739 | D3: =SUMIFS('All Products'!F:F,'All Products'!B:B,A3,'All Products'!D:D,"Product") -> 83098.4 | E3: =SUMIFS('All Products'!G:G,'All Products'!B:B,A3,'All Products'!D:D,"Product") -> 3566.1 | F3: =SUMIFS('All Products'!H:H,'All Products'!B:B,A3,'All Products'!D:D,"Product") -> 2445 | G3: =SUMIFS('All Products'!I:I,'All Products'!B:B,A3,'All Products'!D:D,"Product") -> 15860.6 | H3: =SUMIFS('All Products'!J:J,'All Products'!B:B,A3,'All Products'!D:D,"Product") -> 13930.1 | I3: =SUMIFS('All Products'!K:K,'All Products'!B:B,A3,'All Products'!D:D,"Product") -> 13907.4 | J3: =SUMIFS('All Products'!L:L,'All Products'!B:B,A3,'All Products'!D:D,"Product") -> 43698.1
A4: MEM | B4: =COUNTIFS('All Products'!B:B,A4,'All Products'!D:D,"Product") -> 20 | C4: =SUMIFS('All Products'!E:E,'All Products'!B:B,A4,'All Products'!D:D,"Product") -> 92006 | D4: =SUMIFS('All Products'!F:F,'All Products'!B:B,A4,'All Products'!D:D,"Product") -> 142494.4 | E4: =SUMIFS('All Products'!G:G,'All Products'!B:B,A4,'All Products'!D:D,"Product") -> 6725 | F4: =SUMIFS('All Products'!H:H,'All Products'!B:B,A4,'All Products'!D:D,"Product") -> 0 | G4: =SUMIFS('All Products'!I:I,'All Products'!B:B,A4,'All Products'!D:D,"Product") -> 29559.9 | H4: =SUMIFS('All Products'!J:J,'All Products'!B:B,A4,'All Products'!D:D,"Product") -> 23189.7 | I4: =SUMIFS('All Products'!K:K,'All Products'!B:B,A4,'All Products'!D:D,"Product") -> 23211.8 | J4: =SUMIFS('All Products'!L:L,'All Products'!B:B,A4,'All Products'!D:D,"Product") -> 75961.4
A5: SSD | B5: =COUNTIFS('All Products'!B:B,A5,'All Products'!D:D,"Product") -> 45 | C5: =SUMIFS('All Products'!E:E,'All Products'!B:B,A5,'All Products'!D:D,"Product") -> 53674 | D5: =SUMIFS('All Products'!F:F,'All Products'!B:B,A5,'All Products'!D:D,"Product") -> 53071.6 | E5: =SUMIFS('All Products'!G:G,'All Products'!B:B,A5,'All Products'!D:D,"Product") -> 4227.8 | F5: =SUMIFS('All Products'!H:H,'All Products'!B:B,A5,'All Products'!D:D,"Product") -> 0 | G5: =SUMIFS('All Products'!I:I,'All Products'!B:B,A5,'All Products'!D:D,"Product") -> 18449.4 | H5: =SUMIFS('All Products'!J:J,'All Products'!B:B,A5,'All Products'!D:D,"Product") -> 15192 | I5: =SUMIFS('All Products'!K:K,'All Products'!B:B,A5,'All Products'!D:D,"Product") -> 14826.2 | J5: =SUMIFS('All Products'!L:L,'All Products'!B:B,A5,'All Products'!D:D,"Product") -> 48467.6
A6: HDD | B6: =COUNTIFS('All Products'!B:B,A6,'All Products'!D:D,"Product") -> 9 | C6: =SUMIFS('All Products'!E:E,'All Products'!B:B,A6,'All Products'!D:D,"Product") -> 5479 | D6: =SUMIFS('All Products'!F:F,'All Products'!B:B,A6,'All Products'!D:D,"Product") -> 5395.7 | E6: =SUMIFS('All Products'!G:G,'All Products'!B:B,A6,'All Products'!D:D,"Product") -> 336 | F6: =SUMIFS('All Products'!H:H,'All Products'!B:B,A6,'All Products'!D:D,"Product") -> 0 | G6: =SUMIFS('All Products'!I:I,'All Products'!B:B,A6,'All Products'!D:D,"Product") -> 1489.9 | H6: =SUMIFS('All Products'!J:J,'All Products'!B:B,A6,'All Products'!D:D,"Product") -> 1269 | I6: =SUMIFS('All Products'!K:K,'All Products'!B:B,A6,'All Products'!D:D,"Product") -> 1232.9 | J6: =SUMIFS('All Products'!L:L,'All Products'!B:B,A6,'All Products'!D:D,"Product") -> 3991.8
A7: VGA | B7: =COUNTIFS('All Products'!B:B,A7,'All Products'!D:D,"Product") -> 28 | C7: =SUMIFS('All Products'!E:E,'All Products'!B:B,A7,'All Products'!D:D,"Product") -> 69275 | D7: =SUMIFS('All Products'!F:F,'All Products'!B:B,A7,'All Products'!D:D,"Product") -> 69272.3 | E7: =SUMIFS('All Products'!G:G,'All Products'!B:B,A7,'All Products'!D:D,"Product") -> 2107.5 | F7: =SUMIFS('All Products'!H:H,'All Products'!B:B,A7,'All Products'!D:D,"Product") -> 2099 | G7: =SUMIFS('All Products'!I:I,'All Products'!B:B,A7,'All Products'!D:D,"Product") -> 9631.5 | H7: =SUMIFS('All Products'!J:J,'All Products'!B:B,A7,'All Products'!D:D,"Product") -> 8042.7 | I7: =SUMIFS('All Products'!K:K,'All Products'!B:B,A7,'All Products'!D:D,"Product") -> 8291.4 | J7: =SUMIFS('All Products'!L:L,'All Products'!B:B,A7,'All Products'!D:D,"Product") -> 25965.6
A8: RTX | B8: =COUNTIFS('All Products'!B:B,A8,'All Products'!D:D,"Product") -> 24 | C8: =SUMIFS('All Products'!E:E,'All Products'!B:B,A8,'All Products'!D:D,"Product") -> 316 | D8: =SUMIFS('All Products'!F:F,'All Products'!B:B,A8,'All Products'!D:D,"Product") -> 265.2 | E8: =SUMIFS('All Products'!G:G,'All Products'!B:B,A8,'All Products'!D:D,"Product") -> 21.2 | F8: =SUMIFS('All Products'!H:H,'All Products'!B:B,A8,'All Products'!D:D,"Product") -> 28 | G8: =SUMIFS('All Products'!I:I,'All Products'!B:B,A8,'All Products'!D:D,"Product") -> 90 | H8: =SUMIFS('All Products'!J:J,'All Products'!B:B,A8,'All Products'!D:D,"Product") -> 88 | I8: =SUMIFS('All Products'!K:K,'All Products'!B:B,A8,'All Products'!D:D,"Product") -> 114 | J8: =SUMIFS('All Products'!L:L,'All Products'!B:B,A8,'All Products'!D:D,"Product") -> 292
A9: PSU | B9: =COUNTIFS('All Products'!B:B,A9,'All Products'!D:D,"Product") -> 17 | C9: =SUMIFS('All Products'!E:E,'All Products'!B:B,A9,'All Products'!D:D,"Product") -> 67109 | D9: =SUMIFS('All Products'!F:F,'All Products'!B:B,A9,'All Products'!D:D,"Product") -> 67606.3 | E9: =SUMIFS('All Products'!G:G,'All Products'!B:B,A9,'All Products'!D:D,"Product") -> 2650.5 | F9: =SUMIFS('All Products'!H:H,'All Products'!B:B,A9,'All Products'!D:D,"Product") -> 0 | G9: =SUMIFS('All Products'!I:I,'All Products'!B:B,A9,'All Products'!D:D,"Product") -> 11466.1 | H9: =SUMIFS('All Products'!J:J,'All Products'!B:B,A9,'All Products'!D:D,"Product") -> 9907.8 | I9: =SUMIFS('All Products'!K:K,'All Products'!B:B,A9,'All Products'!D:D,"Product") -> 10254.6 | J9: =SUMIFS('All Products'!L:L,'All Products'!B:B,A9,'All Products'!D:D,"Product") -> 31628.5
A10: Case | B10: =COUNTIFS('All Products'!B:B,A10,'All Products'!D:D,"Product") -> 40 | C10: =SUMIFS('All Products'!E:E,'All Products'!B:B,A10,'All Products'!D:D,"Product") -> 77613 | D10: =SUMIFS('All Products'!F:F,'All Products'!B:B,A10,'All Products'!D:D,"Product") -> 82670.2 | E10: =SUMIFS('All Products'!G:G,'All Products'!B:B,A10,'All Products'!D:D,"Product") -> 3081.8 | F10: =SUMIFS('All Products'!H:H,'All Products'!B:B,A10,'All Products'!D:D,"Product") -> 2072 | G10: =SUMIFS('All Products'!I:I,'All Products'!B:B,A10,'All Products'!D:D,"Product") -> 13515.6 | H10: =SUMIFS('All Products'!J:J,'All Products'!B:B,A10,'All Products'!D:D,"Product") -> 12597.2 | I10: =SUMIFS('All Products'!K:K,'All Products'!B:B,A10,'All Products'!D:D,"Product") -> 12764.8 | J10: =SUMIFS('All Products'!L:L,'All Products'!B:B,A10,'All Products'!D:D,"Product") -> 38877.6
A11: Case_other | B11: =COUNTIFS('All Products'!B:B,A11,'All Products'!D:D,"Product") -> 19 | C11: =SUMIFS('All Products'!E:E,'All Products'!B:B,A11,'All Products'!D:D,"Product") -> 89246 | D11: =SUMIFS('All Products'!F:F,'All Products'!B:B,A11,'All Products'!D:D,"Product") -> 90274.6 | E11: =SUMIFS('All Products'!G:G,'All Products'!B:B,A11,'All Products'!D:D,"Product") -> 1278.9 | F11: =SUMIFS('All Products'!H:H,'All Products'!B:B,A11,'All Products'!D:D,"Product") -> 0 | G11: =SUMIFS('All Products'!I:I,'All Products'!B:B,A11,'All Products'!D:D,"Product") -> 5147.2 | H11: =SUMIFS('All Products'!J:J,'All Products'!B:B,A11,'All Products'!D:D,"Product") -> 4447 | I11: =SUMIFS('All Products'!K:K,'All Products'!B:B,A11,'All Products'!D:D,"Product") -> 4356.9 | J11: =SUMIFS('All Products'!L:L,'All Products'!B:B,A11,'All Products'!D:D,"Product") -> 13951.1
A12: Case_梱包 | B12: =COUNTIFS('All Products'!B:B,A12,'All Products'!D:D,"Product") -> 60 | C12: =SUMIFS('All Products'!E:E,'All Products'!B:B,A12,'All Products'!D:D,"Product") -> 23943 | D12: =SUMIFS('All Products'!F:F,'All Products'!B:B,A12,'All Products'!D:D,"Product") -> 100109.9 | E12: =SUMIFS('All Products'!G:G,'All Products'!B:B,A12,'All Products'!D:D,"Product") -> 10165.2 | F12: =SUMIFS('All Products'!H:H,'All Products'!B:B,A12,'All Products'!D:D,"Product") -> 0 | G12: =SUMIFS('All Products'!I:I,'All Products'!B:B,A12,'All Products'!D:D,"Product") -> 45703.5 | H12: =SUMIFS('All Products'!J:J,'All Products'!B:B,A12,'All Products'!D:D,"Product") -> 38931.9 | I12: =SUMIFS('All Products'!K:K,'All Products'!B:B,A12,'All Products'!D:D,"Product") -> 40247 | J12: =SUMIFS('All Products'!L:L,'All Products'!B:B,A12,'All Products'!D:D,"Product") -> 124882.4
A13: FAN | B13: =COUNTIFS('All Products'!B:B,A13,'All Products'!D:D,"Product") -> 77 | C13: =SUMIFS('All Products'!E:E,'All Products'!B:B,A13,'All Products'!D:D,"Product") -> 170869 | D13: =SUMIFS('All Products'!F:F,'All Products'!B:B,A13,'All Products'!D:D,"Product") -> 327117.6 | E13: =SUMIFS('All Products'!G:G,'All Products'!B:B,A13,'All Products'!D:D,"Product") -> 11110.3 | F13: =SUMIFS('All Products'!H:H,'All Products'!B:B,A13,'All Products'!D:D,"Product") -> 2512 | G13: =SUMIFS('All Products'!I:I,'All Products'!B:B,A13,'All Products'!D:D,"Product") -> 49894.8 | H13: =SUMIFS('All Products'!J:J,'All Products'!B:B,A13,'All Products'!D:D,"Product") -> 41740 | I13: =SUMIFS('All Products'!K:K,'All Products'!B:B,A13,'All Products'!D:D,"Product") -> 38173.3 | J13: =SUMIFS('All Products'!L:L,'All Products'!B:B,A13,'All Products'!D:D,"Product") -> 129808.1
... A18: NotePC | B18: =COUNTIFS('All Products'!B:B,A18,'All Products'!D:D,"Product") -> 81 | C18: =SUMIFS('All Products'!E:E,'All Products'!B:B,A18,'All Products'!D:D,"Product") -> 6852 | D18: =SUMIFS('All Products'!F:F,'All Products'!B:B,A18,'All Products'!D:D,"Product") -> 17297.1 | E18: =SUMIFS('All Products'!G:G,'All Products'!B:B,A18,'All Products'!D:D,"Product") -> 1754.4 | F18: =SUMIFS('All Products'!H:H,'All Products'!B:B,A18,'All Products'!D:D,"Product") -> 0 | G18: =SUMIFS('All Products'!I:I,'All Products'!B:B,A18,'All Products'!D:D,"Product") -> 7599.8 | H18: =SUMIFS('All Products'!J:J,'All Products'!B:B,A18,'All Products'!D:D,"Product") -> 5532.5 | I18: =SUMIFS('All Products'!K:K,'All Products'!B:B,A18,'All Products'!D:D,"Product") -> 5271.8 | J18: =SUMIFS('All Products'!L:L,'All Products'!B:B,A18,'All Products'!D:D,"Product") -> 18404.1
A19: TOTAL | B19: =SUM(B2:B18) -> 526 | C19: =SUM(C2:C18) -> 791373 | D19: =SUM(D2:D18) -> 1168112.9 | E19: =SUM(E2:E18) -> 56813.4 | F19: =SUM(F2:F18) -> 10475 | G19: =SUM(G2:G18) -> 251741.8 | H19: =SUM(H2:H18) -> 212479.3 | I19: =SUM(I2:I18) -> 208659.6 | J19: =SUM(J2:J18) -> 672880.7

Sheet ReadMe - Sources & Notes
A1: CONSOLIDATED PROCUREMENT MASTER - 534 unique products (526 real products + 8 rollup subtotal rows)
A3: Data as of: | B3: Stock = 29-30 Jun 2026 snapshots. Forecast = Jul, Aug, Sep 2026 (the 3 months after the stock date).
A5: COLUMN DEFINITIONS
A6: Physical Stock (SAP, 6/29) | B6: Actual physical units on hand across all warehouses. Source: purchasing/実在庫_貼付用_20260630 (built from 260629在庫.xlsx / SAP ZM13). Blank = item is not SAP-managed (all NotePC and packaging items are outside SAP by design; a few others are flagged 未対応 in the source master).
A7: Current Stock (ONE plan, 6/30) | B7: Stock balance (在庫残高) on 30 Jun 2026 in each ONE_08 category planning file, 部品詳細 sheet. Verified to match the purchasing master ONE在庫残高(現) column exactly for all 534 items.
A8: Used-Sold This Week (Plan) | B8: Units consumed in production, week commencing Mon 29 Jun 2026 (29 Jun - 5 Jul), summed from the daily 生産計画 rows in each category file. This is the operative production plan for the week - decimals occur because monthly plans are spread across days.
A9: Used-Sold This Week (Actual) | B9: Actual component usage for the same week (w/c 29 Jun) from planning/④部材利用数 全ブランド(週次). Only ~350 fast-moving desktop components (VGA, CPU, Case, MB, fans/coolers, RTX) are tracked there; blank = not tracked in that file, not zero.
A10: Forecast Jul/Aug/Sep-2026 | B10: Forecast demand (production usage) per month, summed from the daily 生産計画 in each category file. Cross-checked against ONE計画.xlsm 部品予測 monthly forecast: 97% of items agree within ±15% (median ratio 1.00).
A11: Forecast 3-Month Total | B11: Excel formula = Jul + Aug + Sep.
A13: DE-DUPLICATION
A14: 1 | B14: The two files 販売計画6月提出分...xlsx and ...(2).xlsx in purchasing are byte-identical duplicates of each other - counted once.
A15: 2 | B15: Products appearing in both the purchasing stock master and the ONE planning files were matched 1:1 on Category + 綽名 (534/534 matched, zero orphans on either side).
A16: 3 | B16: 8 rows are ROLLUPS (subtotals of their variants): 6 MEM 合計 rows and 2 Case SK/SKM 合計 rows. They are highlighted yellow, typed "Rollup", and EXCLUDED from the Category Summary so nothing is double counted. Real unique product count = 526.
A18: CAVEATS
A19: a | B19: "Sold this week" is measured as units built into / consumed by production (this is a component procurement operation; components are "sold" by being built into PCs). It is not retail sell-through.
A20: b | B20: Negative or fractional stock in the ONE plan column reflects the planning simulation, not physical reality - use the SAP column for physical units where available.
A21: c | B21: Finished-goods sales plans (planning/① and ②, by PC model, Jun-Nov 2026) drive these component forecasts and are already reflected in the forecast columns.
