Workbook

Sheet 解禁情報
A1: メーカー | B1: SKU | C1: 情報解禁 | D1: サプライヤー出荷 | E1: 出荷解禁
X73: 200
X74: 10
W75: 20
W78: 200 | X78: 2000
X79: 100
W80: 20 | X80: 120
X85: 300
W86: 100 | X86: 150
W93: 8720 | X93: 5300
W94: 1660 | X94: 1200
W102: 2225
W131: 360 | X131: 500
W134: 150 | X134: 1250
W135: 90 | X135: 950
W136: 250 | X136: 500 | Y136: =IF(Y$6="",X136*Y$4,X136*Y$6) -> 0
W142: 5300
W145: 3300
W146: 3100

Sheet 全体
G1: 月次日数→ | AR1: 手入力→ | AS1: 30
G2: 進捗日数→ | AS2: =結果貼付!$A$3 -> 14
A3: EOL | J3: 結果 | K3: 結果 | L3: 結果 | M3: 結果 | N3: 結果 | O3: 結果 | P3: 結果 | Q3: 結果 | R3: 結果 | S3: 結果 | T3: 結果 | U3: 結果 | V3: 結果 | W3: 結果 | AR3: 結果 | AS3: 着地見込 | AT3: 手動補正 | AU3: 手動補正 | AV3: 手動補正 | AW3: 手動補正 | AX3: 手動補正 | AY3: 手動補正
A4: 調整した部材 | G4: 前月比(補正値) | AT4: =HLOOKUP(AT20,係数計算!$B$21:$M$25,4,0) -> 1.1299426 | AU4: =HLOOKUP(AU20,係数計算!$B$21:$M$25,4,0) -> 1.1478954 | AV4: =HLOOKUP(AV20,係数計算!$B$21:$M$25,4,0) -> 0.84745459 | AW4: =HLOOKUP(AW20,係数計算!$B$21:$M$25,4,0) -> 0.98024011 | AX4: =HLOOKUP(AX20,係数計算!$B$21:$M$25,4,0) -> 0.86629134 | AY4: =HLOOKUP(AY20,係数計算!$B$21:$M$25,4,0) -> 0.99099277
A5: ブースト期間 | G5: 季節指数(参考値) | AT5: =HLOOKUP(AT20,係数計算!$B$21:$M$25,5,0) -> 0.95505496 | AU5: =HLOOKUP(AU20,係数計算!$B$21:$M$25,5,0) -> 1.0963032 | AV5: =HLOOKUP(AV20,係数計算!$B$21:$M$25,5,0) -> 0.92906718 | AW5: =HLOOKUP(AW20,係数計算!$B$21:$M$25,5,0) -> 0.91070892 | AX5: =HLOOKUP(AX20,係数計算!$B$21:$M$25,5,0) -> 0.78893925 | AY5: =HLOOKUP(AY20,係数計算!$B$21:$M$25,5,0) -> 0.78183309
A6: 新規追加もしくは通常調整外で更新 | G6: 全体手動補正(%)
AT7: =+AT8/AT9 -> 0.78223399 | AU7: =+AU8/AU9 -> 0.86979401 | AV7: =+AV8/AV9 -> 0.85131694 | AW7: =+AW8/AW9 -> 0.84173863 | AX7: =+AX8/AX9 -> 0.79082408 | AY7: =+AY8/AY9 -> 0.79082654
G8: VGA | J8: =J76 -> 7361 | K8: =K76 -> 6711 | L8: =L76 -> 5300 | M8: =M76 -> 6715 | N8: =N76 -> 9492 | O8: =O76 -> 9638 | P8: =P76 -> 6711 | Q8: =Q76 -> 7612 | ... AG8: =AG76 -> 18695 | AI8: 11927 | AK8: 11832 | AL8: 20509.355 | AM8: 14613.031 | AN8: 7987 | AO8: 9079 | AP8: 9624 | AQ8: 11021 | AR8: =AR76 -> 8227.5 | AS8: =AS76 -> 7658.5 | AT8: =AT76 -> 10062.855 | AU8: =AU76 -> 12033.276 | AV8: =AV76 -> 9689.2245 | AW8: =AW76 -> 9465.0664 | AX8: =AX76 -> 8349.6201 | AY8: =AY76 -> 8279.9528
G9: CPU | J9: =SUM(J109,J137) -> 3540 | K9: =SUM(K109,K137) -> 2969 | L9: =SUM(L109,L137) -> 2890 | M9: =SUM(M109,M137) -> 3616 | N9: =SUM(N109,N137) -> 5188 | O9: =SUM(O109,O137) -> 8450 | P9: =SUM(P109,P137) -> 14874 | Q9: =SUM(Q109,Q137) -> 16368 | ... AG9: =SUM(AG109,AG137) -> 29684 | AI9: 17469 | AK9: 14537 | AL9: 23007.097 | AM9: 17104.974 | AN9: 8804 | AO9: 10773 | AP9: 12038 | AQ9: 13322 | AR9: =SUM(AR109,AR137) -> 10808.036 | AS9: =SUM(AS109,AS137) -> 10944.536 | AT9: =SUM(AT109,AT137) -> 12864.252 | AU9: =SUM(AU109,AU137) -> 13834.627 | AV9: =SUM(AV109,AV137) -> 11381.454 | AW9: =SUM(AW109,AW137) -> 11244.662 | AX9: =SUM(AX109,AX137) -> 10558.126 | AY9: =SUM(AY109,AY137) -> 10469.999
G10: INTEL | J10: =J109/J9 -> 0.31638418 | K10: =K109/K9 -> 0.40114517 | L10: =L109/L9 -> 0.39896194 | M10: =M109/M9 -> 0.54120575 | N10: =N109/N9 -> 0.47841172 | O10: =O109/O9 -> 0.66426036 | P10: =P109/P9 -> 0.82546726 | Q10: =Q109/Q9 -> 0.81433284 | ... AG10: =AG109/AG9 -> 0.70307236 | AI10: 0.61938291 | AK10: 0.49205476 | AL10: 0.45638092 | AM10: 0.49942914 | AN10: 0.44388914 | AO10: 0.41928896 | AP10: 0.42739658 | AQ10: 0.45053295 | AR10: =AR109/AR9 -> 0.5151425 | AS10: =AS109/AS9 -> 0.5125095 | AT10: =AT109/AT9 -> 0.47907983 | AU10: =AU109/AU9 -> 0.42253464 | AV10: =AV109/AV9 -> 0.44172594 | AW10: =AW109/AW9 -> 0.43150941 | AX10: =AX109/AX9 -> 0.4145289 | AY10: =AY109/AY9 -> 0.41477591
G11: AMD | J11: =J137/J9 -> 0.68361582 | K11: =K137/K9 -> 0.59885483 | L11: =L137/L9 -> 0.60103806 | M11: =M137/M9 -> 0.45879425 | N11: =N137/N9 -> 0.52158828 | O11: =O137/O9 -> 0.33573964 | P11: =P137/P9 -> 0.17453274 | Q11: =Q137/Q9 -> 0.18566716 | ... AG11: =AG137/AG9 -> 0.29692764 | AI11: 0.38061709 | AK11: 0.50794524 | AL11: 0.54361908 | AM11: 0.50057086 | AN11: 0.55611086 | AO11: 0.58071104 | AP11: 0.57260342 | AQ11: 0.54946705 | AR11: =AR137/AR9 -> 0.4848575 | AS11: =AS137/AS9 -> 0.4874905 | AT11: =AT137/AT9 -> 0.52092017 | AU11: =AU137/AU9 -> 0.57746536 | AV11: =AV137/AV9 -> 0.55827406 | AW11: =AW137/AW9 -> 0.56849059 | AX11: =AX137/AX9 -> 0.5854711 | AY11: =AY137/AY9 -> 0.58522409
G12: MB | J12: =SUM(J156,J173) -> 1088 | K12: =SUM(K156,K173) -> 850 | L12: =SUM(L156,L173) -> 876 | M12: =SUM(M156,M173) -> 848 | N12: =SUM(N156,N173) -> 1409 | O12: =SUM(O156,O173) -> 1111 | P12: =SUM(P156,P173) -> 1021 | Q12: =SUM(Q156,Q173) -> 1045 | ... AG12: =SUM(AG156,AG173) -> 20166 | AI12: 18689 | AK12: 11665 | AL12: 17879.032 | AM12: 17151.097 | AN12: 7550 | AO12: 9538 | AP12: 10983 | AQ12: 12577 | AR12: =SUM(AR156,AR173) -> 7079.4643 | AS12: =SUM(AS156,AS173) -> 9270.5 | AT12: =SUM(AT156,AT173) -> 12870.718 | AU12: =SUM(AU156,AU173) -> 13944.316 | AV12: =SUM(AV156,AV173) -> 11591.125 | AW12: =SUM(AW156,AW173) -> 11607.486 | AX12: =SUM(AX156,AX173) -> 10961.328 | AY12: =SUM(AY156,AY173) -> 10861.231
G13: INTEL | J13: =J156/J12 -> 0 | K13: =K156/K12 -> 0 | L13: =L156/L12 -> 0 | M13: =M156/M12 -> 0 | N13: =N156/N12 -> 0 | O13: =O156/O12 -> 0 | P13: =P156/P12 -> 0 | Q13: =Q156/Q12 -> 0 | ... AG13: =AG156/AG12 -> 0.74233859 | AI13: 0.56642945 | AK13: 0.60385769 | AL13: 0.5797023 | AM13: 0.48893181 | AN13: 0.51443709 | AO13: 0.46246593 | AP13: 0.37558044 | AQ13: 0.39095174 | AR13: =AR156/AR12 -> 0.27120696 | AS13: =AS156/AS12 -> 0.44380408 | AT13: =AT156/AT12 -> 0.47482525 | AU13: =AU156/AU12 -> 0.42690261 | AV13: =AV156/AV12 -> 0.44570703 | AW13: =AW156/AW12 -> 0.44738282 | AX13: =AX156/AX12 -> 0.43057666 | AY13: =AY156/AY12 -> 0.43034087
G14: AMD | J14: =J173/J12 -> 1 | K14: =K173/K12 -> 1 | L14: =L173/L12 -> 1 | M14: =M173/M12 -> 1 | N14: =N173/N12 -> 1 | O14: =O173/O12 -> 1 | P14: =P173/P12 -> 1 | Q14: =Q173/Q12 -> 1 | ... AG14: =AG173/AG12 -> 0.25766141 | AI14: 0.43357055 | AK14: 0.39614231 | AL14: 0.4202977 | AM14: 0.51106819 | AN14: 0.48556291 | AO14: 0.53753407 | AP14: 0.62441956 | AQ14: 0.60904826 | AR14: =AR173/AR12 -> 0.72879304 | AS14: =AS173/AS12 -> 0.55619592 | AT14: =AT173/AT12 -> 0.52517475 | AU14: =AU173/AU12 -> 0.57309739 | AV14: =AV173/AV12 -> 0.55429297 | AW14: =AW173/AW12 -> 0.55261718 | AX14: =AX173/AX12 -> 0.56942334 | AY14: =AY173/AY12 -> 0.56965913
G15: CASE | J15: =J225 -> 3676 | K15: =K225 -> 3935 | L15: =L225 -> 4942 | M15: =M225 -> 8478 | N15: =N225 -> 9476 | O15: =O225 -> 13798 | P15: =P225 -> 14956 | Q15: =Q225 -> 17309 | ... AG15: =AG225 -> 24135 | AI15: 15756 | AK15: 9971 | AL15: 14078.71 | AM15: 17773.5 | AN15: 4564 | AO15: 6683 | AP15: 11409 | AQ15: 13627 | AR15: =AR225 -> 10922.679 | AS15: =AS225 -> 10895.929 | AT15: =AT225 -> 12940.99 | AU15: =AU225 -> 14032.023 | AV15: =AV225 -> 11999.204 | AW15: =AW225 -> 12425.948 | AX15: =AX225 -> 11164.076 | AY15: =AY225 -> 11353.433
G16: 予算 | AT16: =+予算!M3 -> 27062.866 | AU16: =+予算!N3 -> 21647.58 | AV16: =+予算!O3 -> 27533.343 | AW16: =+予算!P3 -> 21879.851 | AX16: =+予算!Q3 -> 20223.643 | AY16: =+予算!R3 -> 21233.239
G17: 予算に対してのCPU差 | AT17: =SUM(AT9-AT16) -> -14198.614 | AU17: =SUM(AU9-AU16) -> -7812.9524 | AV17: =SUM(AV9-AV16) -> -16151.889 | AW17: =SUM(AW9-AW16) -> -10635.19 | AX17: =SUM(AX9-AX16) -> -9665.5174 | AY17: =SUM(AY9-AY16) -> -10763.24
G18: 予算に対してのMB差 | AT18: =+AT12-AT16 -> -14192.148 | AU18: =+AU12-AU16 -> -7703.2635 | AV18: =+AV12-AV16 -> -15942.218 | AW18: =+AW12-AW16 -> -10272.365 | AX18: =+AX12-AX16 -> -9262.315 | AY18: =+AY12-AY16 -> -10372.007
G19: 予算に対してのケース差 | J19: 41期→ | AT19: =+AT15-AT16 -> -14121.876 | AU19: =+AU15-AU16 -> -7615.5571 | AV19: =+AV15-AV16 -> -15534.139 | AW19: =+AW15-AW16 -> -9453.9036 | AX19: =+AX15-AX16 -> -9059.5673 | AY19: =+AY15-AY16 -> -9879.8054
A20: 現在庫 | B20: 発注済 | C20: FCST | D20: 合計 | E20: 差分 | G20: 識別子1 | H20: コン | I20: コマ | J20: 8月 | K20: 9月 | L20: 10月 | M20: 11月 | N20: 12月 | O20: 1月 | P20: 2月 | Q20: 3月 | R20: 4月 | S20: 5月 | T20: 6月 | U20: 7月 | V20: 8月 | W20: 9月 | X20: 10月 | Y20: 11月 | Z20: 12月 | AA20: 1月 | AB20: 2月 | AC20: 3月 | AD20: 4月 | AE20: 5月 | AF20: 6月 | AG20: 7月 | AH20: 8月 | AI20: ９月 | AJ20: 10月 | AK20: 11月 | AL20: 12月 | AM20: 1月 | AN20: 2月 | AO20: 3月 | AP20: 4月 | AQ20: 5月 | AR20: 当月結果 | AS20: 当月見込 | AT20: 6月 | AU20: 7月 | AV20: 8月 | AW20: 9月 | AX20: 10月 | AY20: 11月
A21: =SUMIFS(SAP貼付!K:K,SAP貼付!C:C,全体!G21) -> 451 | B21: =SUMIFS(VGAMBFCST貼付!D:D,VGAMBFCST貼付!B:B,G21,VGAMBFCST貼付!C:C,全体!$B$20) -> 445 | C21: =SUMIFS(VGAMBFCST貼付!D:D,VGAMBFCST貼付!B:B,G21,VGAMBFCST貼付!C:C,全体!$C$20) -> 0 | D21: =SUM(A21:C21) -> 896 | E21: =IFERROR(D21-SUM(AT21:AV21)," ") -> 706.33909 | G21: RTX5090 | H21: =IFERROR(IF(MATCH($G21,コンシューマー!B:B,0),"Y"),"-") -> Y | I21: =IFERROR(IF(MATCH($G21,コマーシャル!B:B,0),"Y"),"-") -> Y | J21: =SUMIF(コンシューマー!$B:$B,全体!$G21,コンシューマー!D:D) -> 0 | K21: =SUMIF(コンシューマー!$B:$B,全体!$G21,コンシューマー!E:E) -> 0 | L21: =SUMIF(コンシューマー!$B:$B,全体!$G21,コンシューマー!F:F) -> 0 | M21: =SUMIF(コンシューマー!$B:$B,全体!$G21,コンシューマー!G:G) -> 0 | N21: =SUMIF(コンシューマー!$B:$B,全体!$G21,コンシューマー!H:H) -> 0 | O21: =SUMIF(コンシューマー!$B:$B,全体!$G21,コンシューマー!I:I) -> 0 | P21: =SUMIF(コンシューマー!$B:$B,全体!$G21,コンシューマー!J:J) -> 0 | Q21: =SUMIF(コンシューマー!$B:$B,全体!$G21,コンシューマー!K:K) -> 0 | R21: =SUMIF(コンシューマー!$B:$B,全体!$G21,コンシューマー!L:L) -> 0 | S21: =SUMIF(コンシューマー!$B:$B,全体!$G21,コンシューマー!M:M) -> 0 | T21: =SUMIF(コンシューマー!$B:$B,全体!$G21,コンシューマー!N:N) -> 0 | U21: =SUMIF(コンシューマー!$B:$B,全体!$G21,コンシューマー!O:O) -> 0 | V21: =SUMIF(コンシューマー!$B:$B,全体!$G21,コンシューマー!P:P) -> 0 | W21: =SUMIF(コンシューマー!$B:$B,全体!$G21,コンシューマー!Q:Q) -> 0 | X21: =SUMIF(コンシューマー!$B:$B,全体!$G21,コンシューマー!R:R) -> 0 | Y21: =SUMIF(コンシューマー!$B:$B,全体!$G21,コンシューマー!S:S) -> 0 | Z21: =SUMIF(コンシューマー!$B:$B,全体!$G21,コンシューマー!T:T) -> 0 | AA21: =SUMIF(コンシューマー!$B:$B,全体!$G21,コンシューマー!U:U) -> 0 | AB21: =SUMIF(コンシューマー!$B:$B,全体!$G21,コンシューマー!V:V) -> 40 | AC21: =SUMIF(コンシューマー!$B:$B,全体!$G21,コンシューマー!W:W) -> 144 | AD21: =SUMIF(コンシューマー!$B:$B,全体!$G21,コンシューマー!X:X) -> 92 | AE21: =SUMIF(コンシューマー!$B:$B,全体!$G21,コンシューマー!Y:Y) -> 113 | AF21: =SUMIF(コンシューマー!$B:$B,全体!$G21,コンシューマー!Z:Z) -> 109 | AG21: =SUMIF(コンシューマー!$B:$B,全体!$G21,コンシューマー!AA:AA) -> 175 | AI21: 97 | AK21: 144 | AL21: 224.51613 | AM21: 229.99333 | AN21: 61 | AO21: 89 | AP21: 78 | AQ21: 68 | AR21: =SUMIF(結果貼付!$A:$A,G21,結果貼付!$D:$D) -> 29 | AS21: =(AR21/AS$2)*AS$1 -> 62.142857 | AT21: =SUM(SUMIF(コンシューマー!$B:$B,全体!$G21,コンシューマー!AO:AO),SUMIF(コマーシャル!$B:$B,全体!$G21,コマーシャル!AK:AK)) -> 75 | AU21: =SUM(SUMIF(コンシューマー!$B:$B,全体!$G21,コンシューマー!AP:AP),SUMIF(コマーシャル!$B:$B,全体!$G21,コマーシャル!AL:AL)) -> 60 | AV21: =SUM(SUMIF(コンシューマー!$B:$B,全体!$G21,コンシューマー!AQ:AQ),SUMIF(コマーシャル!$B:$B,全体!$G21,コマーシャル!AM:AM)) -> 54.660911 | AW21: =SUM(SUMIF(コンシューマー!$B:$B,全体!$G21,コンシューマー!AR:AR),SUMIF(コマーシャル!$B:$B,全体!$G21,コマーシャル!AN:AN)) -> 54.074814 | AX21: =SUM(SUMIF(コンシューマー!$B:$B,全体!$G21,コンシューマー!AS:AS),SUMIF(コマーシャル!$B:$B,全体!$G21,コマーシャル!AO:AO)) -> 55.18726 | AY21: =SUM(SUMIF(コンシューマー!$B:$B,全体!$G21,コンシューマー!AT:AT),SUMIF(コマーシャル!$B:$B,全体!$G21,コマーシャル!AP:AP)) -> 54.960392
A22: =SUMIFS(SAP貼付!K:K,SAP貼付!C:C,全体!G22) -> 246 | B22: =SUMIFS(VGAMBFCST貼付!D:D,VGAMBFCST貼付!B:B,G22,VGAMBFCST貼付!C:C,全体!$B$20) -> 4739 | C22: =SUMIFS(VGAMBFCST貼付!D:D,VGAMBFCST貼付!B:B,G22,VGAMBFCST貼付!C:C,全体!$C$20) -> 3500 | D22: =SUM(A22:C22) -> 8485 | E22: =IFERROR(D22-SUM(AT22:AV22)," ") -> 5582.416 | G22: RTX5080 | H22: =IFERROR(IF(MATCH($G22,コンシューマー!B:B,0),"Y"),"-") -> Y | I22: =IFERROR(IF(MATCH($G22,コマーシャル!B:B,0),"Y"),"-") -> Y | J22: =SUMIF(コンシューマー!$B:$B,全体!$G22,コンシューマー!D:D) -> 0 | K22: =SUMIF(コンシューマー!$B:$B,全体!$G22,コンシューマー!E:E) -> 0 | L22: =SUMIF(コンシューマー!$B:$B,全体!$G22,コンシューマー!F:F) -> 0 | M22: =SUMIF(コンシューマー!$B:$B,全体!$G22,コンシューマー!G:G) -> 0 | N22: =SUMIF(コンシューマー!$B:$B,全体!$G22,コンシューマー!H:H) -> 0 | O22: =SUMIF(コンシューマー!$B:$B,全体!$G22,コンシューマー!I:I) -> 0 | P22: =SUMIF(コンシューマー!$B:$B,全体!$G22,コンシューマー!J:J) -> 0 | Q22: =SUMIF(コンシューマー!$B:$B,全体!$G22,コンシューマー!K:K) -> 0 | R22: =SUMIF(コンシューマー!$B:$B,全体!$G22,コンシューマー!L:L) -> 0 | S22: =SUMIF(コンシューマー!$B:$B,全体!$G22,コンシューマー!M:M) -> 0 | T22: =SUMIF(コンシューマー!$B:$B,全体!$G22,コンシューマー!N:N) -> 0 | U22: =SUMIF(コンシューマー!$B:$B,全体!$G22,コンシューマー!O:O) -> 0 | V22: =SUMIF(コンシューマー!$B:$B,全体!$G22,コンシューマー!P:P) -> 0 | W22: =SUMIF(コンシューマー!$B:$B,全体!$G22,コンシューマー!Q:Q) -> 0 | X22: =SUMIF(コンシューマー!$B:$B,全体!$G22,コンシューマー!R:R) -> 0 | Y22: =SUMIF(コンシューマー!$B:$B,全体!$G22,コンシューマー!S:S) -> 0 | Z22: =SUMIF(コンシューマー!$B:$B,全体!$G22,コンシューマー!T:T) -> 0 | AA22: =SUMIF(コンシューマー!$B:$B,全体!$G22,コンシューマー!U:U) -> 0 | AB22: =SUMIF(コンシューマー!$B:$B,全体!$G22,コンシューマー!V:V) -> 1175 | AC22: =SUMIF(コンシューマー!$B:$B,全体!$G22,コンシューマー!W:W) -> 725 | AD22: =SUMIF(コンシューマー!$B:$B,全体!$G22,コンシューマー!X:X) -> 628 | AE22: =SUMIF(コンシューマー!$B:$B,全体!$G22,コンシューマー!Y:Y) -> 511 | AF22: =SUMIF(コンシューマー!$B:$B,全体!$G22,コンシューマー!Z:Z) -> 495 | AG22: =SUMIF(コンシューマー!$B:$B,全体!$G22,コンシューマー!AA:AA) -> 986 | AI22: 395 | AK22: 514 | AL22: 970.64516 | AM22: 701.47833 | AN22: 326 | AO22: 216 | AP22: 539 | AQ22: 761 | AR22: =SUMIF(結果貼付!$A:$A,G22,結果貼付!$D:$D) -> 283 | AS22: =(AR22/AS$2)*AS$1 -> 606.42857 | AT22: =SUM(SUMIF(コンシューマー!$B:$B,全体!$G22,コンシューマー!AO:AO),SUMIF(コマーシャル!$B:$B,全体!$G22,コマーシャル!AK:AK)) -> 935.72 | AU22: =SUM(SUMIF(コンシューマー!$B:$B,全体!$G22,コンシューマー!AP:AP),SUMIF(コマーシャル!$B:$B,全体!$G22,コマーシャル!AL:AL)) -> 1115.864 | AV22: =SUM(SUMIF(コンシューマー!$B:$B,全体!$G22,コンシューマー!AQ:AQ),SUMIF(コマーシャル!$B:$B,全体!$G22,コマーシャル!AM:AM)) -> 851 | AW22: =SUM(SUMIF(コンシューマー!$B:$B,全体!$G22,コンシューマー!AR:AR),SUMIF(コマーシャル!$B:$B,全体!$G22,コマーシャル!AN:AN)) -> 834.87593 | AX22: =SUM(SUMIF(コンシューマー!$B:$B,全体!$G22,コンシューマー!AS:AS),SUMIF(コマーシャル!$B:$B,全体!$G22,コマーシャル!AO:AO)) -> 732.92559 | AY22: =SUM(SUMIF(コンシューマー!$B:$B,全体!$G22,コンシューマー!AT:AT),SUMIF(コマーシャル!$B:$B,全体!$G22,コマーシャル!AP:AP)) -> 726.68425
A23: =SUMIFS(SAP貼付!K:K,SAP貼付!C:C,全体!G23) -> 864 | B23: =SUMIFS(VGAMBFCST貼付!D:D,VGAMBFCST貼付!B:B,G23,VGAMBFCST貼付!C:C,全体!$B$20) -> 5057 | C23: =SUMIFS(VGAMBFCST貼付!D:D,VGAMBFCST貼付!B:B,G23,VGAMBFCST貼付!C:C,全体!$C$20) -> 5543 | D23: =SUM(A23:C23) -> 11464 | E23: =IFERROR(D23-SUM(AT23:AV23)," ") -> 10534.718 | G23: RTX5070Ti | H23: =IFERROR(IF(MATCH($G23,コンシューマー!B:B,0),"Y"),"-") -> Y | I23: =IFERROR(IF(MATCH($G23,コマーシャル!B:B,0),"Y"),"-") -> Y | J23: =SUMIF(コンシューマー!$B:$B,全体!$G23,コンシューマー!D:D) -> 0 | K23: =SUMIF(コンシューマー!$B:$B,全体!$G23,コンシューマー!E:E) -> 0 | L23: =SUMIF(コンシューマー!$B:$B,全体!$G23,コンシューマー!F:F) -> 0 | M23: =SUMIF(コンシューマー!$B:$B,全体!$G23,コンシューマー!G:G) -> 0 | N23: =SUMIF(コンシューマー!$B:$B,全体!$G23,コンシューマー!H:H) -> 0 | O23: =SUMIF(コンシューマー!$B:$B,全体!$G23,コンシューマー!I:I) -> 0 | P23: =SUMIF(コンシューマー!$B:$B,全体!$G23,コンシューマー!J:J) -> 0 | Q23: =SUMIF(コンシューマー!$B:$B,全体!$G23,コンシューマー!K:K) -> 0 | R23: =SUMIF(コンシューマー!$B:$B,全体!$G23,コンシューマー!L:L) -> 0 | S23: =SUMIF(コンシューマー!$B:$B,全体!$G23,コンシューマー!M:M) -> 0 | T23: =SUMIF(コンシューマー!$B:$B,全体!$G23,コンシューマー!N:N) -> 0 | U23: =SUMIF(コンシューマー!$B:$B,全体!$G23,コンシューマー!O:O) -> 0 | V23: =SUMIF(コンシューマー!$B:$B,全体!$G23,コンシューマー!P:P) -> 0 | W23: =SUMIF(コンシューマー!$B:$B,全体!$G23,コンシューマー!Q:Q) -> 0 | X23: =SUMIF(コンシューマー!$B:$B,全体!$G23,コンシューマー!R:R) -> 0 | Y23: =SUMIF(コンシューマー!$B:$B,全体!$G23,コンシューマー!S:S) -> 0 | Z23: =SUMIF(コンシューマー!$B:$B,全体!$G23,コンシューマー!T:T) -> 0 | AA23: =SUMIF(コンシューマー!$B:$B,全体!$G23,コンシューマー!U:U) -> 0 | AB23: =SUMIF(コンシューマー!$B:$B,全体!$G23,コンシューマー!V:V) -> 0 | AC23: =SUMIF(コンシューマー!$B:$B,全体!$G23,コンシューマー!W:W) -> 1480 | AD23: =SUMIF(コンシューマー!$B:$B,全体!$G23,コンシューマー!X:X) -> 1588 | AE23: =SUMIF(コンシューマー!$B:$B,全体!$G23,コンシューマー!Y:Y) -> 1062 | AF23: =SUMIF(コンシューマー!$B:$B,全体!$G23,コンシューマー!Z:Z) -> 1178 | AG23: =SUMIF(コンシューマー!$B:$B,全体!$G23,コンシューマー!AA:AA) -> 2495 | AI23: 769 | AK23: 837 | AL23: 1863.871 | AM23: 1393.3883 | AN23: 585 | AO23: 426 | AP23: 275 | AQ23: 218 | AR23: =SUMIF(結果貼付!$A:$A,G23,結果貼付!$D:$D) -> 80 | AS23: =(AR23/AS$2)*AS$1 -> 171.42857 | AT23: =SUM(SUMIF(コンシューマー!$B:$B,全体!$G23,コンシューマー!AO:AO),SUMIF(コマーシャル!$B:$B,全体!$G23,コマーシャル!AK:AK)) -> 289.54528 | AU23: =SUM(SUMIF(コンシューマー!$B:$B,全体!$G23,コンシューマー!AP:AP),SUMIF(コマーシャル!$B:$B,全体!$G23,コマーシャル!AL:AL)) -> 345.45433 | AV23: =SUM(SUMIF(コンシューマー!$B:$B,全体!$G23,コンシューマー!AQ:AQ),SUMIF(コマーシャル!$B:$B,全体!$G23,コマーシャル!AM:AM)) -> 294.28231 | AW23: =SUM(SUMIF(コンシューマー!$B:$B,全体!$G23,コンシューマー!AR:AR),SUMIF(コマーシャル!$B:$B,全体!$G23,コマーシャル!AN:AN)) -> 288.66493 | AX23: =SUM(SUMIF(コンシューマー!$B:$B,全体!$G23,コンシューマー!AS:AS),SUMIF(コマーシャル!$B:$B,全体!$G23,コマーシャル!AO:AO)) -> 211 | AY23: =SUM(SUMIF(コンシューマー!$B:$B,全体!$G23,コンシューマー!AT:AT),SUMIF(コマーシャル!$B:$B,全体!$G23,コマーシャル!AP:AP)) -> 209.18955
A24: =SUMIFS(SAP貼付!K:K,SAP貼付!C:C,全体!G24) -> 70 | B24: =SUMIFS(VGAMBFCST貼付!D:D,VGAMBFCST貼付!B:B,G24,VGAMBFCST貼付!C:C,全体!$B$20) -> 10313 | C24: =SUMIFS(VGAMBFCST貼付!D:D,VGAMBFCST貼付!B:B,G24,VGAMBFCST貼付!C:C,全体!$C$20) -> 6200 | D24: =SUM(A24:C24) -> 16583 | E24: =IFERROR(D24-SUM(AT24:AV24)," ") -> 4241.4 | G24: RTX5070 | H24: =IFERROR(IF(MATCH($G24,コンシューマー!B:B,0),"Y"),"-") -> Y | I24: =IFERROR(IF(MATCH($G24,コマーシャル!B:B,0),"Y"),"-") -> Y | J24: =SUMIF(コンシューマー!$B:$B,全体!$G24,コンシューマー!D:D) -> 0 | K24: =SUMIF(コンシューマー!$B:$B,全体!$G24,コンシューマー!E:E) -> 0 | L24: =SUMIF(コンシューマー!$B:$B,全体!$G24,コンシューマー!F:F) -> 0 | M24: =SUMIF(コンシューマー!$B:$B,全体!$G24,コンシューマー!G:G) -> 0 | N24: =SUMIF(コンシューマー!$B:$B,全体!$G24,コンシューマー!H:H) -> 0 | O24: =SUMIF(コンシューマー!$B:$B,全体!$G24,コンシューマー!I:I) -> 0 | P24: =SUMIF(コンシューマー!$B:$B,全体!$G24,コンシューマー!J:J) -> 0 | Q24: =SUMIF(コンシューマー!$B:$B,全体!$G24,コンシューマー!K:K) -> 0 | R24: =SUMIF(コンシューマー!$B:$B,全体!$G24,コンシューマー!L:L) -> 0 | S24: =SUMIF(コンシューマー!$B:$B,全体!$G24,コンシューマー!M:M) -> 0 | T24: =SUMIF(コンシューマー!$B:$B,全体!$G24,コンシューマー!N:N) -> 0 | U24: =SUMIF(コンシューマー!$B:$B,全体!$G24,コンシューマー!O:O) -> 0 | V24: =SUMIF(コンシューマー!$B:$B,全体!$G24,コンシューマー!P:P) -> 0 | W24: =SUMIF(コンシューマー!$B:$B,全体!$G24,コンシューマー!Q:Q) -> 0 | X24: =SUMIF(コンシューマー!$B:$B,全体!$G24,コンシューマー!R:R) -> 0 | Y24: =SUMIF(コンシューマー!$B:$B,全体!$G24,コンシューマー!S:S) -> 0 | Z24: =SUMIF(コンシューマー!$B:$B,全体!$G24,コンシューマー!T:T) -> 0 | AA24: =SUMIF(コンシューマー!$B:$B,全体!$G24,コンシューマー!U:U) -> 0 | AB24: =SUMIF(コンシューマー!$B:$B,全体!$G24,コンシューマー!V:V) -> 0 | AC24: =SUMIF(コンシューマー!$B:$B,全体!$G24,コンシューマー!W:W) -> 3854 | AD24: =SUMIF(コンシューマー!$B:$B,全体!$G24,コンシューマー!X:X) -> 4592 | AE24: =SUMIF(コンシューマー!$B:$B,全体!$G24,コンシューマー!Y:Y) -> 3139 | AF24: =SUMIF(コンシューマー!$B:$B,全体!$G24,コンシューマー!Z:Z) -> 3271 | AG24: =SUMIF(コンシューマー!$B:$B,全体!$G24,コンシューマー!AA:AA) -> 4684 | AI24: 3815 | AK24: 3730 | AL24: 6454.8387 | AM24: 3964.1558 | AN24: 1755 | AO24: 2128 | AP24: 3054 | AQ24: 4665 | AR24: =SUMIF(結果貼付!$A:$A,G24,結果貼付!$D:$D) -> 1529 | AS24: =(AR24/AS$2)*AS$1 -> 3276.4286 | AT24: =SUM(SUMIF(コンシューマー!$B:$B,全体!$G24,コンシューマー!AO:AO),SUMIF(コマーシャル!$B:$B,全体!$G24,コマーシャル!AK:AK)) -> 3888 | AU24: =SUM(SUMIF(コンシューマー!$B:$B,全体!$G24,コンシューマー!AP:AP),SUMIF(コマーシャル!$B:$B,全体!$G24,コマーシャル!AL:AL)) -> 4621.6 | AV24: =SUM(SUMIF(コンシューマー!$B:$B,全体!$G24,コンシューマー!AQ:AQ),SUMIF(コマーシャル!$B:$B,全体!$G24,コマーシャル!AM:AM)) -> 3832 | AW24: =SUM(SUMIF(コンシューマー!$B:$B,全体!$G24,コンシューマー!AR:AR),SUMIF(コマーシャル!$B:$B,全体!$G24,コマーシャル!AN:AN)) -> 3591 | AX24: =SUM(SUMIF(コンシューマー!$B:$B,全体!$G24,コンシューマー!AS:AS),SUMIF(コマーシャル!$B:$B,全体!$G24,コマーシャル!AO:AO)) -> 3300 | AY24: =SUM(SUMIF(コンシューマー!$B:$B,全体!$G24,コンシューマー!AT:AT),SUMIF(コマーシャル!$B:$B,全体!$G24,コマーシャル!AP:AP)) -> 3271.2669
E25: =IFERROR(D25-SUM(AT25:AV25)," ") -> -222.63776 | G25: RTX5070 WH | H25: =IFERROR(IF(MATCH($G25,コンシューマー!B:B,0),"Y"),"-") -> Y | I25: =IFERROR(IF(MATCH($G25,コマーシャル!B:B,0),"Y"),"-") -> - | J25: =SUMIF(コンシューマー!$B:$B,全体!$G25,コンシューマー!D:D) -> 0 | K25: =SUMIF(コンシューマー!$B:$B,全体!$G25,コンシューマー!E:E) -> 0 | L25: =SUMIF(コンシューマー!$B:$B,全体!$G25,コンシューマー!F:F) -> 0 | M25: =SUMIF(コンシューマー!$B:$B,全体!$G25,コンシューマー!G:G) -> 0 | N25: =SUMIF(コンシューマー!$B:$B,全体!$G25,コンシューマー!H:H) -> 0 | O25: =SUMIF(コンシューマー!$B:$B,全体!$G25,コンシューマー!I:I) -> 0 | P25: =SUMIF(コンシューマー!$B:$B,全体!$G25,コンシューマー!J:J) -> 0 | Q25: =SUMIF(コンシューマー!$B:$B,全体!$G25,コンシューマー!K:K) -> 0 | R25: =SUMIF(コンシューマー!$B:$B,全体!$G25,コンシューマー!L:L) -> 0 | S25: =SUMIF(コンシューマー!$B:$B,全体!$G25,コンシューマー!M:M) -> 0 | T25: =SUMIF(コンシューマー!$B:$B,全体!$G25,コンシューマー!N:N) -> 0 | U25: =SUMIF(コンシューマー!$B:$B,全体!$G25,コンシューマー!O:O) -> 0 | V25: =SUMIF(コンシューマー!$B:$B,全体!$G25,コンシューマー!P:P) -> 0 | W25: =SUMIF(コンシューマー!$B:$B,全体!$G25,コンシューマー!Q:Q) -> 0 | X25: =SUMIF(コンシューマー!$B:$B,全体!$G25,コンシューマー!R:R) -> 0 | Y25: =SUMIF(コンシューマー!$B:$B,全体!$G25,コンシューマー!S:S) -> 0 | Z25: =SUMIF(コンシューマー!$B:$B,全体!$G25,コンシューマー!T:T) -> 0 | AA25: =SUMIF(コンシューマー!$B:$B,全体!$G25,コンシューマー!U:U) -> 0 | AB25: =SUMIF(コンシューマー!$B:$B,全体!$G25,コンシューマー!V:V) -> 0 | AC25: =SUMIF(コンシューマー!$B:$B,全体!$G25,コンシューマー!W:W) -> 0 | AD25: =SUMIF(コンシューマー!$B:$B,全体!$G25,コンシューマー!X:X) -> 0 | AE25: =SUMIF(コンシューマー!$B:$B,全体!$G25,コンシューマー!Y:Y) -> 0 | AF25: =SUMIF(コンシューマー!$B:$B,全体!$G25,コンシューマー!Z:Z) -> 0 | AG25: =SUMIF(コンシューマー!$B:$B,全体!$G25,コンシューマー!AA:AA) -> 0 | AI25: 0 | AK25: 135 | AL25: 94.83871 | AM25: 13.743333 | AN25: 18 | AO25: 81 | AP25: 80 | AQ25: 51 | AR25: =SUMIF(結果貼付!$A:$A,G25,結果貼付!$D:$D) -> 17 | AS25: =(AR25/AS$2)*AS$1 -> 36.428571 | AT25: =SUM(SUMIF(コンシューマー!$B:$B,全体!$G25,コンシューマー!AO:AO),SUMIF(コマーシャル!$B:$B,全体!$G25,コマーシャル!AK:AK)) -> 69.207811 | AU25: =SUM(SUMIF(コンシューマー!$B:$B,全体!$G25,コンシューマー!AP:AP),SUMIF(コマーシャル!$B:$B,全体!$G25,コマーシャル!AL:AL)) -> 83.049373 | AV25: =SUM(SUMIF(コンシューマー!$B:$B,全体!$G25,コンシューマー!AQ:AQ),SUMIF(コマーシャル!$B:$B,全体!$G25,コマーシャル!AM:AM)) -> 70.380573 | AW25: =SUM(SUMIF(コンシューマー!$B:$B,全体!$G25,コンシューマー!AR:AR),SUMIF(コマーシャル!$B:$B,全体!$G25,コマーシャル!AN:AN)) -> 68.98986 | AX25: =SUM(SUMIF(コンシューマー!$B:$B,全体!$G25,コンシューマー!AS:AS),SUMIF(コマーシャル!$B:$B,全体!$G25,コマーシャル!AO:AO)) -> 59.765318 | AY25: =SUM(SUMIF(コンシューマー!$B:$B,全体!$G25,コンシューマー!AT:AT),SUMIF(コマーシャル!$B:$B,全体!$G25,コマーシャル!AP:AP)) -> 59.226998
A26: =SUMIFS(SAP貼付!K:K,SAP貼付!C:C,全体!G26) -> 0 | B26: =SUMIFS(VGAMBFCST貼付!D:D,VGAMBFCST貼付!B:B,G26,VGAMBFCST貼付!C:C,全体!$B$20) -> 0 | C26: =SUMIFS(VGAMBFCST貼付!D:D,VGAMBFCST貼付!B:B,G26,VGAMBFCST貼付!C:C,全体!$C$20) -> 0 | D26: =SUM(A26:C26) -> 0 | E26: =IFERROR(D26-SUM(AT26:AV26)," ") -> -1429.7205 | G26: RTX5060Ti 16GB | H26: =IFERROR(IF(MATCH($G26,コンシューマー!B:B,0),"Y"),"-") -> Y | I26: =IFERROR(IF(MATCH($G26,コマーシャル!B:B,0),"Y"),"-") -> Y | J26: =SUMIF(コンシューマー!$B:$B,全体!$G26,コンシューマー!D:D) -> 0 | K26: =SUMIF(コンシューマー!$B:$B,全体!$G26,コンシューマー!E:E) -> 0 | L26: =SUMIF(コンシューマー!$B:$B,全体!$G26,コンシューマー!F:F) -> 0 | M26: =SUMIF(コンシューマー!$B:$B,全体!$G26,コンシューマー!G:G) -> 0 | N26: =SUMIF(コンシューマー!$B:$B,全体!$G26,コンシューマー!H:H) -> 0 | O26: =SUMIF(コンシューマー!$B:$B,全体!$G26,コンシューマー!I:I) -> 0 | P26: =SUMIF(コンシューマー!$B:$B,全体!$G26,コンシューマー!J:J) -> 0 | Q26: =SUMIF(コンシューマー!$B:$B,全体!$G26,コンシューマー!K:K) -> 0 | R26: =SUMIF(コンシューマー!$B:$B,全体!$G26,コンシューマー!L:L) -> 0 | S26: =SUMIF(コンシューマー!$B:$B,全体!$G26,コンシューマー!M:M) -> 0 | T26: =SUMIF(コンシューマー!$B:$B,全体!$G26,コンシューマー!N:N) -> 0 | U26: =SUMIF(コンシューマー!$B:$B,全体!$G26,コンシューマー!O:O) -> 0 | V26: =SUMIF(コンシューマー!$B:$B,全体!$G26,コンシューマー!P:P) -> 0 | W26: =SUMIF(コンシューマー!$B:$B,全体!$G26,コンシューマー!Q:Q) -> 0 | X26: =SUMIF(コンシューマー!$B:$B,全体!$G26,コンシューマー!R:R) -> 0 | Y26: =SUMIF(コンシューマー!$B:$B,全体!$G26,コンシューマー!S:S) -> 0 | Z26: =SUMIF(コンシューマー!$B:$B,全体!$G26,コンシューマー!T:T) -> 0 | AA26: =SUMIF(コンシューマー!$B:$B,全体!$G26,コンシューマー!U:U) -> 0 | AB26: =SUMIF(コンシューマー!$B:$B,全体!$G26,コンシューマー!V:V) -> -1 | AC26: =SUMIF(コンシューマー!$B:$B,全体!$G26,コンシューマー!W:W) -> 0 | AD26: =SUMIF(コンシューマー!$B:$B,全体!$G26,コンシューマー!X:X) -> 250 | AE26: =SUMIF(コンシューマー!$B:$B,全体!$G26,コンシューマー!Y:Y) -> 639 | AF26: =SUMIF(コンシューマー!$B:$B,全体!$G26,コンシューマー!Z:Z) -> 1248 | AG26: =SUMIF(コンシューマー!$B:$B,全体!$G26,コンシューマー!AA:AA) -> 1907 | AI26: 1352 | AK26: 1624 | AL26: 3109.3548 | AM26: 1673.41 | AN26: 765 | AO26: 589 | AP26: 462 | AQ26: 302 | AR26: =SUMIF(結果貼付!$A:$A,G26,結果貼付!$D:$D) -> 156 | AS26: =(AR26/AS$2)*AS$1 -> 334.28571 | AT26: =SUM(SUMIF(コンシューマー!$B:$B,全体!$G26,コンシューマー!AO:AO),SUMIF(コマーシャル!$B:$B,全体!$G26,コマーシャル!AK:AK)) -> 452 | AU26: =SUM(SUMIF(コンシューマー!$B:$B,全体!$G26,コンシューマー!AP:AP),SUMIF(コマーシャル!$B:$B,全体!$G26,コマーシャル!AL:AL)) -> 528.4 | AV26: =SUM(SUMIF(コンシューマー!$B:$B,全体!$G26,コンシューマー!AQ:AQ),SUMIF(コマーシャル!$B:$B,全体!$G26,コマーシャル!AM:AM)) -> 449.32046 | AW26: =SUM(SUMIF(コンシューマー!$B:$B,全体!$G26,コンシューマー!AR:AR),SUMIF(コマーシャル!$B:$B,全体!$G26,コマーシャル!AN:AN)) -> 540.63954 | AX26: =SUM(SUMIF(コンシューマー!$B:$B,全体!$G26,コンシューマー!AS:AS),SUMIF(コマーシャル!$B:$B,全体!$G26,コマーシャル!AO:AO)) -> 383.0593 | AY26: =SUM(SUMIF(コンシューマー!$B:$B,全体!$G26,コンシューマー!AT:AT),SUMIF(コマーシャル!$B:$B,全体!$G26,コマーシャル!AP:AP)) -> 379.69907
E27: =IFERROR(D27-SUM(AT27:AV27)," ") -> -8.7308924 | G27: RTX5060Ti 16GB WH | H27: =IFERROR(IF(MATCH($G27,コンシューマー!B:B,0),"Y"),"-") -> Y | I27: =IFERROR(IF(MATCH($G27,コマーシャル!B:B,0),"Y"),"-") -> - | J27: =SUMIF(コンシューマー!$B:$B,全体!$G27,コンシューマー!D:D) -> 0 | K27: =SUMIF(コンシューマー!$B:$B,全体!$G27,コンシューマー!E:E) -> 0 | L27: =SUMIF(コンシューマー!$B:$B,全体!$G27,コンシューマー!F:F) -> 0 | M27: =SUMIF(コンシューマー!$B:$B,全体!$G27,コンシューマー!G:G) -> 0 | N27: =SUMIF(コンシューマー!$B:$B,全体!$G27,コンシューマー!H:H) -> 0 | O27: =SUMIF(コンシューマー!$B:$B,全体!$G27,コンシューマー!I:I) -> 0 | P27: =SUMIF(コンシューマー!$B:$B,全体!$G27,コンシューマー!J:J) -> 0 | Q27: =SUMIF(コンシューマー!$B:$B,全体!$G27,コンシューマー!K:K) -> 0 | R27: =SUMIF(コンシューマー!$B:$B,全体!$G27,コンシューマー!L:L) -> 0 | S27: =SUMIF(コンシューマー!$B:$B,全体!$G27,コンシューマー!M:M) -> 0 | T27: =SUMIF(コンシューマー!$B:$B,全体!$G27,コンシューマー!N:N) -> 0 | U27: =SUMIF(コンシューマー!$B:$B,全体!$G27,コンシューマー!O:O) -> 0 | V27: =SUMIF(コンシューマー!$B:$B,全体!$G27,コンシューマー!P:P) -> 0 | W27: =SUMIF(コンシューマー!$B:$B,全体!$G27,コンシューマー!Q:Q) -> 0 | X27: =SUMIF(コンシューマー!$B:$B,全体!$G27,コンシューマー!R:R) -> 0 | Y27: =SUMIF(コンシューマー!$B:$B,全体!$G27,コンシューマー!S:S) -> 0 | Z27: =SUMIF(コンシューマー!$B:$B,全体!$G27,コンシューマー!T:T) -> 0 | AA27: =SUMIF(コンシューマー!$B:$B,全体!$G27,コンシューマー!U:U) -> 0 | AB27: =SUMIF(コンシューマー!$B:$B,全体!$G27,コンシューマー!V:V) -> 0 | AC27: =SUMIF(コンシューマー!$B:$B,全体!$G27,コンシューマー!W:W) -> 0 | AD27: =SUMIF(コンシューマー!$B:$B,全体!$G27,コンシューマー!X:X) -> 0 | AE27: =SUMIF(コンシューマー!$B:$B,全体!$G27,コンシューマー!Y:Y) -> 0 | AF27: =SUMIF(コンシューマー!$B:$B,全体!$G27,コンシューマー!Z:Z) -> 0 | AG27: =SUMIF(コンシューマー!$B:$B,全体!$G27,コンシューマー!AA:AA) -> 0 | AI27: 1 | AK27: 33 | AL27: 116.12903 | AM27: 49.083333 | AN27: 38 | AO27: 13 | AP27: 15 | AQ27: 2 | AR27: =SUMIF(結果貼付!$A:$A,G27,結果貼付!$D:$D) -> 1 | AS27: =(AR27/AS$2)*AS$1 -> 2.1428571 | AT27: =SUM(SUMIF(コンシューマー!$B:$B,全体!$G27,コンシューマー!AO:AO),SUMIF(コマーシャル!$B:$B,全体!$G27,コマーシャル!AK:AK)) -> 2.7140318 | AU27: =SUM(SUMIF(コンシューマー!$B:$B,全体!$G27,コンシューマー!AP:AP),SUMIF(コマーシャル!$B:$B,全体!$G27,コマーシャル!AL:AL)) -> 3.2568382 | AV27: =SUM(SUMIF(コンシューマー!$B:$B,全体!$G27,コンシューマー!AQ:AQ),SUMIF(コマーシャル!$B:$B,全体!$G27,コマーシャル!AM:AM)) -> 2.7600225 | AW27: =SUM(SUMIF(コンシューマー!$B:$B,全体!$G27,コンシューマー!AR:AR),SUMIF(コマーシャル!$B:$B,全体!$G27,コマーシャル!AN:AN)) -> 2.7054847 | AX27: =SUM(SUMIF(コンシューマー!$B:$B,全体!$G27,コンシューマー!AS:AS),SUMIF(コマーシャル!$B:$B,全体!$G27,コマーシャル!AO:AO)) -> 2.343738 | AY27: =SUM(SUMIF(コンシューマー!$B:$B,全体!$G27,コンシューマー!AT:AT),SUMIF(コマーシャル!$B:$B,全体!$G27,コマーシャル!AP:AP)) -> 2.3226274
A28: =SUMIFS(SAP貼付!K:K,SAP貼付!C:C,全体!G28) -> 0 | B28: =SUMIFS(VGAMBFCST貼付!D:D,VGAMBFCST貼付!B:B,G28,VGAMBFCST貼付!C:C,全体!$B$20) -> 0 | C28: =SUMIFS(VGAMBFCST貼付!D:D,VGAMBFCST貼付!B:B,G28,VGAMBFCST貼付!C:C,全体!$C$20) -> 0 | D28: =SUM(A28:C28) -> 0 | E28: =IFERROR(D28-SUM(AT28:AV28)," ") -> -6455 | G28: RTX5060Ti 8GB | H28: =IFERROR(IF(MATCH($G28,コンシューマー!B:B,0),"Y"),"-") -> Y | I28: =IFERROR(IF(MATCH($G28,コマーシャル!B:B,0),"Y"),"-") -> Y | J28: =SUMIF(コンシューマー!$B:$B,全体!$G28,コンシューマー!D:D) -> 0 | K28: =SUMIF(コンシューマー!$B:$B,全体!$G28,コンシューマー!E:E) -> 0 | L28: =SUMIF(コンシューマー!$B:$B,全体!$G28,コンシューマー!F:F) -> 0 | M28: =SUMIF(コンシューマー!$B:$B,全体!$G28,コンシューマー!G:G) -> 0 | N28: =SUMIF(コンシューマー!$B:$B,全体!$G28,コンシューマー!H:H) -> 0 | O28: =SUMIF(コンシューマー!$B:$B,全体!$G28,コンシューマー!I:I) -> 0 | P28: =SUMIF(コンシューマー!$B:$B,全体!$G28,コンシューマー!J:J) -> 0 | Q28: =SUMIF(コンシューマー!$B:$B,全体!$G28,コンシューマー!K:K) -> 0 | R28: =SUMIF(コンシューマー!$B:$B,全体!$G28,コンシューマー!L:L) -> 0 | S28: =SUMIF(コンシューマー!$B:$B,全体!$G28,コンシューマー!M:M) -> 0 | T28: =SUMIF(コンシューマー!$B:$B,全体!$G28,コンシューマー!N:N) -> 0 | U28: =SUMIF(コンシューマー!$B:$B,全体!$G28,コンシューマー!O:O) -> 0 | V28: =SUMIF(コンシューマー!$B:$B,全体!$G28,コンシューマー!P:P) -> 0 | W28: =SUMIF(コンシューマー!$B:$B,全体!$G28,コンシューマー!Q:Q) -> 0 | X28: =SUMIF(コンシューマー!$B:$B,全体!$G28,コンシューマー!R:R) -> 0 | Y28: =SUMIF(コンシューマー!$B:$B,全体!$G28,コンシューマー!S:S) -> 0 | Z28: =SUMIF(コンシューマー!$B:$B,全体!$G28,コンシューマー!T:T) -> 0 | AA28: =SUMIF(コンシューマー!$B:$B,全体!$G28,コンシューマー!U:U) -> 0 | AB28: =SUMIF(コンシューマー!$B:$B,全体!$G28,コンシューマー!V:V) -> 0 | AC28: =SUMIF(コンシューマー!$B:$B,全体!$G28,コンシューマー!W:W) -> 0 | AD28: =SUMIF(コンシューマー!$B:$B,全体!$G28,コンシューマー!X:X) -> 46 | AE28: =SUMIF(コンシューマー!$B:$B,全体!$G28,コンシューマー!Y:Y) -> 392 | AF28: =SUMIF(コンシューマー!$B:$B,全体!$G28,コンシューマー!Z:Z) -> 489 | AG28: =SUMIF(コンシューマー!$B:$B,全体!$G28,コンシューマー!AA:AA) -> 997 | AI28: 1116 | AK28: 667 | AL28: 1067.4194 | AM28: 807.91167 | AN28: 584 | AO28: 2870 | AP28: 2133 | AQ28: 2381 | AR28: =SUMIF(結果貼付!$A:$A,G28,結果貼付!$D:$D) -> 569 | AS28: =(AR28/AS$2)*AS$1 -> 1219.2857 | AT28: =SUM(SUMIF(コンシューマー!$B:$B,全体!$G28,コンシューマー!AO:AO),SUMIF(コマーシャル!$B:$B,全体!$G28,コマーシャル!AK:AK)) -> 1842 | AU28: =SUM(SUMIF(コンシューマー!$B:$B,全体!$G28,コンシューマー!AP:AP),SUMIF(コマーシャル!$B:$B,全体!$G28,コマーシャル!AL:AL)) -> 2841 | AV28: =SUM(SUMIF(コンシューマー!$B:$B,全体!$G28,コンシューマー!AQ:AQ),SUMIF(コマーシャル!$B:$B,全体!$G28,コマーシャル!AM:AM)) -> 1772 | AW28: =SUM(SUMIF(コンシューマー!$B:$B,全体!$G28,コンシューマー!AR:AR),SUMIF(コマーシャル!$B:$B,全体!$G28,コマーシャル!AN:AN)) -> 1737.9735 | AX28: =SUM(SUMIF(コンシューマー!$B:$B,全体!$G28,コンシューマー!AS:AS),SUMIF(コマーシャル!$B:$B,全体!$G28,コマーシャル!AO:AO)) -> 1522.2768 | AY28: =SUM(SUMIF(コンシューマー!$B:$B,全体!$G28,コンシューマー!AT:AT),SUMIF(コマーシャル!$B:$B,全体!$G28,コマーシャル!AP:AP)) -> 1509.1057
G29: RTX5060 | H29: =IFERROR(IF(MATCH($G29,コンシューマー!B:B,0),"Y"),"-") -> Y | I29: =IFERROR(IF(MATCH($G29,コマーシャル!B:B,0),"Y"),"-") -> Y | N29: =SUMIF(コンシューマー!$B:$B,全体!$G29,コンシューマー!H:H) -> 0 | O29: =SUMIF(コンシューマー!$B:$B,全体!$G29,コンシューマー!I:I) -> 0 | P29: =SUMIF(コンシューマー!$B:$B,全体!$G29,コンシューマー!J:J) -> 0 | Q29: =SUMIF(コンシューマー!$B:$B,全体!$G29,コンシューマー!K:K) -> 0 | R29: =SUMIF(コンシューマー!$B:$B,全体!$G29,コンシューマー!L:L) -> 0 | S29: =SUMIF(コンシューマー!$B:$B,全体!$G29,コンシューマー!M:M) -> 0 | T29: =SUMIF(コンシューマー!$B:$B,全体!$G29,コンシューマー!N:N) -> 0 | U29: =SUMIF(コンシューマー!$B:$B,全体!$G29,コンシューマー!O:O) -> 0 | V29: =SUMIF(コンシューマー!$B:$B,全体!$G29,コンシューマー!P:P) -> 0 | W29: =SUMIF(コンシューマー!$B:$B,全体!$G29,コンシューマー!Q:Q) -> 0 | X29: =SUMIF(コンシューマー!$B:$B,全体!$G29,コンシューマー!R:R) -> 0 | Y29: =SUMIF(コンシューマー!$B:$B,全体!$G29,コンシューマー!S:S) -> 0 | Z29: =SUMIF(コンシューマー!$B:$B,全体!$G29,コンシューマー!T:T) -> 0 | AA29: =SUMIF(コンシューマー!$B:$B,全体!$G29,コンシューマー!U:U) -> 0 | AB29: =SUMIF(コンシューマー!$B:$B,全体!$G29,コンシューマー!V:V) -> 0 | AC29: =SUMIF(コンシューマー!$B:$B,全体!$G29,コンシューマー!W:W) -> 0 | AD29: =SUMIF(コンシューマー!$B:$B,全体!$G29,コンシューマー!X:X) -> 0 | AE29: =SUMIF(コンシューマー!$B:$B,全体!$G29,コンシューマー!Y:Y) -> 75 | AF29: =SUMIF(コンシューマー!$B:$B,全体!$G29,コンシューマー!Z:Z) -> 477 | AG29: =SUMIF(コンシューマー!$B:$B,全体!$G29,コンシューマー!AA:AA) -> 2556 | AI29: 1877 | AK29: 2497 | AL29: 4282.2581 | AM29: 3787.8933 | AN29: 2661 | AO29: 1623 | AP29: 1178 | AQ29: 984 | AR29: =SUMIF(結果貼付!$A:$A,G29,結果貼付!$D:$D) -> 550 | AS29: =(AR29/AS$2)*AS$1 -> 1178.5714 | AT29: =SUM(SUMIF(コンシューマー!$B:$B,全体!$G29,コンシューマー!AO:AO),SUMIF(コマーシャル!$B:$B,全体!$G29,コマーシャル!AK:AK)) -> 1410 | AU29: =SUM(SUMIF(コンシューマー!$B:$B,全体!$G29,コンシューマー!AP:AP),SUMIF(コマーシャル!$B:$B,全体!$G29,コマーシャル!AL:AL)) -> 1214 | AV29: =SUM(SUMIF(コンシューマー!$B:$B,全体!$G29,コンシューマー!AQ:AQ),SUMIF(コマーシャル!$B:$B,全体!$G29,コマーシャル!AM:AM)) -> 1333 | AW29: =SUM(SUMIF(コンシューマー!$B:$B,全体!$G29,コンシューマー!AR:AR),SUMIF(コマーシャル!$B:$B,全体!$G29,コマーシャル!AN:AN)) -> 1307.6481 | AX29: =SUM(SUMIF(コンシューマー!$B:$B,全体!$G29,コンシューマー!AS:AS),SUMIF(コマーシャル!$B:$B,全体!$G29,コマーシャル!AO:AO)) -> 1149.4896 | AY29: =SUM(SUMIF(コンシューマー!$B:$B,全体!$G29,コンシューマー!AT:AT),SUMIF(コマーシャル!$B:$B,全体!$G29,コマーシャル!AP:AP)) -> 1139.6763
G30: RTX5060 WH | H30: =IFERROR(IF(MATCH($G30,コンシューマー!B:B,0),"Y"),"-") -> Y | I30: =IFERROR(IF(MATCH($G30,コマーシャル!B:B,0),"Y"),"-") -> - | N30: =SUMIF(コンシューマー!$B:$B,全体!$G30,コンシューマー!H:H) -> 0 | O30: =SUMIF(コンシューマー!$B:$B,全体!$G30,コンシューマー!I:I) -> 0 | P30: =SUMIF(コンシューマー!$B:$B,全体!$G30,コンシューマー!J:J) -> 0 | Q30: =SUMIF(コンシューマー!$B:$B,全体!$G30,コンシューマー!K:K) -> 0 | R30: =SUMIF(コンシューマー!$B:$B,全体!$G30,コンシューマー!L:L) -> 0 | S30: =SUMIF(コンシューマー!$B:$B,全体!$G30,コンシューマー!M:M) -> 0 | T30: =SUMIF(コンシューマー!$B:$B,全体!$G30,コンシューマー!N:N) -> 0 | U30: =SUMIF(コンシューマー!$B:$B,全体!$G30,コンシューマー!O:O) -> 0 | V30: =SUMIF(コンシューマー!$B:$B,全体!$G30,コンシューマー!P:P) -> 0 | W30: =SUMIF(コンシューマー!$B:$B,全体!$G30,コンシューマー!Q:Q) -> 0 | X30: =SUMIF(コンシューマー!$B:$B,全体!$G30,コンシューマー!R:R) -> 0 | Y30: =SUMIF(コンシューマー!$B:$B,全体!$G30,コンシューマー!S:S) -> 0 | Z30: =SUMIF(コンシューマー!$B:$B,全体!$G30,コンシューマー!T:T) -> 0 | AA30: =SUMIF(コンシューマー!$B:$B,全体!$G30,コンシューマー!U:U) -> 0 | AB30: =SUMIF(コンシューマー!$B:$B,全体!$G30,コンシューマー!V:V) -> 0 | AC30: =SUMIF(コンシューマー!$B:$B,全体!$G30,コンシューマー!W:W) -> 0 | AD30: =SUMIF(コンシューマー!$B:$B,全体!$G30,コンシューマー!X:X) -> 0 | AE30: =SUMIF(コンシューマー!$B:$B,全体!$G30,コンシューマー!Y:Y) -> 0 | AF30: =SUMIF(コンシューマー!$B:$B,全体!$G30,コンシューマー!Z:Z) -> 0 | AG30: =SUMIF(コンシューマー!$B:$B,全体!$G30,コンシューマー!AA:AA) -> 0 | AI30: 0 | AK30: 26 | AL30: 37.741935 | AM30: 15.706667 | AN30: 10 | AO30: 2 | AP30: 12 | AQ30: 11 | AR30: =SUMIF(結果貼付!$A:$A,G30,結果貼付!$D:$D) -> 4 | AS30: =(AR30/AS$2)*AS$1 -> 8.5714286 | AT30: =SUM(SUMIF(コンシューマー!$B:$B,全体!$G30,コンシューマー!AO:AO),SUMIF(コマーシャル!$B:$B,全体!$G30,コマーシャル!AK:AK)) -> 14.927175 | AU30: =SUM(SUMIF(コンシューマー!$B:$B,全体!$G30,コンシューマー!AP:AP),SUMIF(コマーシャル!$B:$B,全体!$G30,コマーシャル!AL:AL)) -> 17.91261 | AV30: =SUM(SUMIF(コンシューマー!$B:$B,全体!$G30,コンシューマー!AQ:AQ),SUMIF(コマーシャル!$B:$B,全体!$G30,コマーシャル!AM:AM)) -> 15.180124 | AW30: =SUM(SUMIF(コンシューマー!$B:$B,全体!$G30,コンシューマー!AR:AR),SUMIF(コマーシャル!$B:$B,全体!$G30,コマーシャル!AN:AN)) -> 14.880166 | AX30: =SUM(SUMIF(コンシューマー!$B:$B,全体!$G30,コンシューマー!AS:AS),SUMIF(コマーシャル!$B:$B,全体!$G30,コマーシャル!AO:AO)) -> 12.890559 | AY30: =SUM(SUMIF(コンシューマー!$B:$B,全体!$G30,コンシューマー!AT:AT),SUMIF(コマーシャル!$B:$B,全体!$G30,コマーシャル!AP:AP)) -> 12.774451
G31: RTX5050 | H31: =IFERROR(IF(MATCH($G31,コンシューマー!B:B,0),"Y"),"-") -> Y | I31: =IFERROR(IF(MATCH($G31,コマーシャル!B:B,0),"Y"),"-") -> Y | N31: =SUMIF(コンシューマー!$B:$B,全体!$G31,コンシューマー!H:H) -> 0 | O31: =SUMIF(コンシューマー!$B:$B,全体!$G31,コンシューマー!I:I) -> 0 | P31: =SUMIF(コンシューマー!$B:$B,全体!$G31,コンシューマー!J:J) -> 0 | Q31: =SUMIF(コンシューマー!$B:$B,全体!$G31,コンシューマー!K:K) -> 0 | R31: =SUMIF(コンシューマー!$B:$B,全体!$G31,コンシューマー!L:L) -> 0 | S31: =SUMIF(コンシューマー!$B:$B,全体!$G31,コンシューマー!M:M) -> 0 | T31: =SUMIF(コンシューマー!$B:$B,全体!$G31,コンシューマー!N:N) -> 0 | U31: =SUMIF(コンシューマー!$B:$B,全体!$G31,コンシューマー!O:O) -> 0 | V31: =SUMIF(コンシューマー!$B:$B,全体!$G31,コンシューマー!P:P) -> 0 | W31: =SUMIF(コンシューマー!$B:$B,全体!$G31,コンシューマー!Q:Q) -> 0 | X31: =SUMIF(コンシューマー!$B:$B,全体!$G31,コンシューマー!R:R) -> 0 | Y31: =SUMIF(コンシューマー!$B:$B,全体!$G31,コンシューマー!S:S) -> 0 | Z31: =SUMIF(コンシューマー!$B:$B,全体!$G31,コンシューマー!T:T) -> 0 | AA31: =SUMIF(コンシューマー!$B:$B,全体!$G31,コンシューマー!U:U) -> 0 | AB31: =SUMIF(コンシューマー!$B:$B,全体!$G31,コンシューマー!V:V) -> 0 | AC31: =SUMIF(コンシューマー!$B:$B,全体!$G31,コンシューマー!W:W) -> 0 | AD31: =SUMIF(コンシューマー!$B:$B,全体!$G31,コンシューマー!X:X) -> 0 | AE31: =SUMIF(コンシューマー!$B:$B,全体!$G31,コンシューマー!Y:Y) -> 0 | AF31: =SUMIF(コンシューマー!$B:$B,全体!$G31,コンシューマー!Z:Z) -> 0 | AG31: =SUMIF(コンシューマー!$B:$B,全体!$G31,コンシューマー!AA:AA) -> 10 | AI31: 34 | AK31: 76 | AL31: 193.54839 | AM31: 5.89 | AN31: 90 | AO31: 118 | AP31: 139 | AQ31: 87 | AR31: =SUMIF(結果貼付!$A:$A,G31,結果貼付!$D:$D) -> 96 | AS31: =(AR31/AS$2)*AS$1 -> 205.71429 | AT31: =SUM(SUMIF(コンシューマー!$B:$B,全体!$G31,コンシューマー!AO:AO),SUMIF(コマーシャル!$B:$B,全体!$G31,コマーシャル!AK:AK)) -> 260 | AU31: =SUM(SUMIF(コンシューマー!$B:$B,全体!$G31,コンシューマー!AP:AP),SUMIF(コマーシャル!$B:$B,全体!$G31,コマーシャル!AL:AL)) -> 310 | AV31: =SUM(SUMIF(コンシューマー!$B:$B,全体!$G31,コンシューマー!AQ:AQ),SUMIF(コマーシャル!$B:$B,全体!$G31,コマーシャル!AM:AM)) -> 264.23638 | AW31: =SUM(SUMIF(コンシューマー!$B:$B,全体!$G31,コンシューマー!AR:AR),SUMIF(コマーシャル!$B:$B,全体!$G31,コマーシャル!AN:AN)) -> 259.2127 | AX31: =SUM(SUMIF(コンシューマー!$B:$B,全体!$G31,コンシューマー!AS:AS),SUMIF(コマーシャル!$B:$B,全体!$G31,コマーシャル!AO:AO)) -> 225.8908 | AY31: =SUM(SUMIF(コンシューマー!$B:$B,全体!$G31,コンシューマー!AT:AT),SUMIF(コマーシャル!$B:$B,全体!$G31,コマーシャル!AP:AP)) -> 223.94622
A32: =SUMIFS(SAP貼付!K:K,SAP貼付!C:C,全体!G32) -> 6859 | B32: =SUMIFS(VGAMBFCST貼付!D:D,VGAMBFCST貼付!B:B,G32,VGAMBFCST貼付!C:C,全体!$B$20) -> 7035 | C32: =SUMIFS(VGAMBFCST貼付!D:D,VGAMBFCST貼付!B:B,G32,VGAMBFCST貼付!C:C,全体!$C$20) -> 0 | D32: =SUM(A32:C32) -> 13894 | E32: =IFERROR(D32-SUM(#REF!)," ") | G32: RTX4060Ti | H32: =IFERROR(IF(MATCH($G32,コンシューマー!B:B,0),"Y"),"-") -> Y | I32: =IFERROR(IF(MATCH($G32,コマーシャル!B:B,0),"Y"),"-") -> - | J32: =SUMIF(コンシューマー!$B:$B,全体!$G32,コンシューマー!D:D) -> 5947 | K32: =SUMIF(コンシューマー!$B:$B,全体!$G32,コンシューマー!E:E) -> 5107 | L32: =SUMIF(コンシューマー!$B:$B,全体!$G32,コンシューマー!F:F) -> 3821 | M32: =SUMIF(コンシューマー!$B:$B,全体!$G32,コンシューマー!G:G) -> 4902 | N32: =SUMIF(コンシューマー!$B:$B,全体!$G32,コンシューマー!H:H) -> 6782 | O32: =SUMIF(コンシューマー!$B:$B,全体!$G32,コンシューマー!I:I) -> 6634 | P32: =SUMIF(コンシューマー!$B:$B,全体!$G32,コンシューマー!J:J) -> 4651 | Q32: =SUMIF(コンシューマー!$B:$B,全体!$G32,コンシューマー!K:K) -> 5233 | R32: =SUMIF(コンシューマー!$B:$B,全体!$G32,コンシューマー!L:L) -> 4041 | S32: =SUMIF(コンシューマー!$B:$B,全体!$G32,コンシューマー!M:M) -> 3442 | T32: =SUMIF(コンシューマー!$B:$B,全体!$G32,コンシューマー!N:N) -> 3586 | U32: =SUMIF(コンシューマー!$B:$B,全体!$G32,コンシューマー!O:O) -> 4650 | V32: =SUMIF(コンシューマー!$B:$B,全体!$G32,コンシューマー!P:P) -> 2681 | W32: =SUMIF(コンシューマー!$B:$B,全体!$G32,コンシューマー!Q:Q) -> 3179 | X32: =SUMIF(コンシューマー!$B:$B,全体!$G32,コンシューマー!R:R) -> 3887 | Y32: =SUMIF(コンシューマー!$B:$B,全体!$G32,コンシューマー!S:S) -> 2269 | Z32: =SUMIF(コンシューマー!$B:$B,全体!$G32,コンシューマー!T:T) -> 4072 | AA32: =SUMIF(コンシューマー!$B:$B,全体!$G32,コンシューマー!U:U) -> 3080 | AB32: =SUMIF(コンシューマー!$B:$B,全体!$G32,コンシューマー!V:V) -> 7614 | AC32: =SUMIF(コンシューマー!$B:$B,全体!$G32,コンシューマー!W:W) -> 7504 | AD32: =SUMIF(コンシューマー!$B:$B,全体!$G32,コンシューマー!X:X) -> 3452 | AE32: =SUMIF(コンシューマー!$B:$B,全体!$G32,コンシューマー!Y:Y) -> 1306 | AF32: =SUMIF(コンシューマー!$B:$B,全体!$G32,コンシューマー!Z:Z) -> 1454 | AG32: =SUMIF(コンシューマー!$B:$B,全体!$G32,コンシューマー!AA:AA) -> 284 | AI32: 311 | AK32: 33 | AL32: 5.8064516 | AM32: 0 | AN32: 0 | AO32: -2 | AP32: 0 | AQ32: 0 | AR32: =SUMIF(結果貼付!$A:$A,G32,結果貼付!$D:$D) -> -1 | AS32: =(AR32/AS$2)*AS$1 -> -2.1428571 | AT32: =SUM(SUMIF(コンシューマー!$B:$B,全体!$G32,コンシューマー!AO:AO),SUMIF(コマーシャル!$B:$B,全体!$G32,コマーシャル!AK:AK)) -> 0 | AU32: =SUM(SUMIF(コンシューマー!$B:$B,全体!$G32,コンシューマー!AP:AP),SUMIF(コマーシャル!$B:$B,全体!$G32,コマーシャル!AL:AL)) -> 0 | AV32: =SUM(SUMIF(コンシューマー!$B:$B,全体!$G32,コンシューマー!AQ:AQ),SUMIF(コマーシャル!$B:$B,全体!$G32,コマーシャル!AM:AM)) -> 0 | AW32: =SUM(SUMIF(コンシューマー!$B:$B,全体!$G32,コンシューマー!AR:AR),SUMIF(コマーシャル!$B:$B,全体!$G32,コマーシャル!AN:AN)) -> 0 | AX32: =SUM(SUMIF(コンシューマー!$B:$B,全体!$G32,コンシューマー!AS:AS),SUMIF(コマーシャル!$B:$B,全体!$G32,コマーシャル!AO:AO)) -> 0 | AY32: =SUM(SUMIF(コンシューマー!$B:$B,全体!$G32,コンシューマー!AT:AT),SUMIF(コマーシャル!$B:$B,全体!$G32,コマーシャル!AP:AP)) -> 0
A33: =SUMIFS(SAP貼付!K:K,SAP貼付!C:C,全体!G33) -> 14779 | B33: =SUMIFS(VGAMBFCST貼付!D:D,VGAMBFCST貼付!B:B,G33,VGAMBFCST貼付!C:C,全体!$B$20) -> 798 | C33: =SUMIFS(VGAMBFCST貼付!D:D,VGAMBFCST貼付!B:B,G33,VGAMBFCST貼付!C:C,全体!$C$20) -> 0 | D33: =SUM(A33:C33) -> 15577 | E33: =IFERROR(D33-SUM(#REF!)," ") | G33: RTX4060 | H33: =IFERROR(IF(MATCH($G33,コンシューマー!B:B,0),"Y"),"-") -> Y | I33: =IFERROR(IF(MATCH($G33,コマーシャル!B:B,0),"Y"),"-") -> - | J33: =SUMIF(コンシューマー!$B:$B,全体!$G33,コンシューマー!D:D) -> 1389 | K33: =SUMIF(コンシューマー!$B:$B,全体!$G33,コンシューマー!E:E) -> 1578 | L33: =SUMIF(コンシューマー!$B:$B,全体!$G33,コンシューマー!F:F) -> 1454 | M33: =SUMIF(コンシューマー!$B:$B,全体!$G33,コンシューマー!G:G) -> 1777 | N33: =SUMIF(コンシューマー!$B:$B,全体!$G33,コンシューマー!H:H) -> 2661 | O33: =SUMIF(コンシューマー!$B:$B,全体!$G33,コンシューマー!I:I) -> 2951 | P33: =SUMIF(コンシューマー!$B:$B,全体!$G33,コンシューマー!J:J) -> 2018 | Q33: =SUMIF(コンシューマー!$B:$B,全体!$G33,コンシューマー!K:K) -> 2292 | R33: =SUMIF(コンシューマー!$B:$B,全体!$G33,コンシューマー!L:L) -> 2401 | S33: =SUMIF(コンシューマー!$B:$B,全体!$G33,コンシューマー!M:M) -> 1944 | T33: =SUMIF(コンシューマー!$B:$B,全体!$G33,コンシューマー!N:N) -> 2259 | U33: =SUMIF(コンシューマー!$B:$B,全体!$G33,コンシューマー!O:O) -> 3579 | V33: =SUMIF(コンシューマー!$B:$B,全体!$G33,コンシューマー!P:P) -> 2639 | W33: =SUMIF(コンシューマー!$B:$B,全体!$G33,コンシューマー!Q:Q) -> 2412 | X33: =SUMIF(コンシューマー!$B:$B,全体!$G33,コンシューマー!R:R) -> 2315 | Y33: =SUMIF(コンシューマー!$B:$B,全体!$G33,コンシューマー!S:S) -> 1664 | Z33: =SUMIF(コンシューマー!$B:$B,全体!$G33,コンシューマー!T:T) -> 3117 | AA33: =SUMIF(コンシューマー!$B:$B,全体!$G33,コンシューマー!U:U) -> 2469 | AB33: =SUMIF(コンシューマー!$B:$B,全体!$G33,コンシューマー!V:V) -> 3675 | AC33: =SUMIF(コンシューマー!$B:$B,全体!$G33,コンシューマー!W:W) -> 7581 | AD33: =SUMIF(コンシューマー!$B:$B,全体!$G33,コンシューマー!X:X) -> 3789 | AE33: =SUMIF(コンシューマー!$B:$B,全体!$G33,コンシューマー!Y:Y) -> 2482 | AF33: =SUMIF(コンシューマー!$B:$B,全体!$G33,コンシューマー!Z:Z) -> 2589 | AG33: =SUMIF(コンシューマー!$B:$B,全体!$G33,コンシューマー!AA:AA) -> 1271 | AI33: 223 | AK33: 19 | AL33: -0.96774194 | AM33: 21.596667 | AN33: 0 | AO33: 51 | AP33: 0 | AQ33: -1 | AR33: =SUMIF(結果貼付!$A:$A,G33,結果貼付!$D:$D) -> 0 | AS33: =(AR33/AS$2)*AS$1 -> 0 | AT33: =SUM(SUMIF(コンシューマー!$B:$B,全体!$G33,コンシューマー!AO:AO),SUMIF(コマーシャル!$B:$B,全体!$G33,コマーシャル!AK:AK)) -> 0 | AU33: =SUM(SUMIF(コンシューマー!$B:$B,全体!$G33,コンシューマー!AP:AP),SUMIF(コマーシャル!$B:$B,全体!$G33,コマーシャル!AL:AL)) -> 0 | AV33: =SUM(SUMIF(コンシューマー!$B:$B,全体!$G33,コンシューマー!AQ:AQ),SUMIF(コマーシャル!$B:$B,全体!$G33,コマーシャル!AM:AM)) -> 0 | AW33: =SUM(SUMIF(コンシューマー!$B:$B,全体!$G33,コンシューマー!AR:AR),SUMIF(コマーシャル!$B:$B,全体!$G33,コマーシャル!AN:AN)) -> 0 | AX33: =SUM(SUMIF(コンシューマー!$B:$B,全体!$G33,コンシューマー!AS:AS),SUMIF(コマーシャル!$B:$B,全体!$G33,コマーシャル!AO:AO)) -> 0 | AY33: =SUM(SUMIF(コンシューマー!$B:$B,全体!$G33,コンシューマー!AT:AT),SUMIF(コマーシャル!$B:$B,全体!$G33,コマーシャル!AP:AP)) -> 0
A34: =SUMIFS(SAP貼付!K:K,SAP貼付!C:C,全体!G34) -> 3835 | B34: =SUMIFS(VGAMBFCST貼付!D:D,VGAMBFCST貼付!B:B,G34,VGAMBFCST貼付!C:C,全体!$B$20) -> 216 | C34: =SUMIFS(VGAMBFCST貼付!D:D,VGAMBFCST貼付!B:B,G34,VGAMBFCST貼付!C:C,全体!$C$20) -> 0 | D34: =SUM(A34:C34) -> 4051 | E34: =IFERROR(D34-SUM(#REF!)," ") | G34: RTX3050 6G | H34: =IFERROR(IF(MATCH($G34,コンシューマー!B:B,0),"Y"),"-") -> Y | I34: =IFERROR(IF(MATCH($G34,コマーシャル!B:B,0),"Y"),"-") -> Y | J34: =SUMIF(コンシューマー!$B:$B,全体!$G34,コンシューマー!D:D) -> 0 | K34: =SUMIF(コンシューマー!$B:$B,全体!$G34,コンシューマー!E:E) -> 0 | L34: =SUMIF(コンシューマー!$B:$B,全体!$G34,コンシューマー!F:F) -> 0 | M34: =SUMIF(コンシューマー!$B:$B,全体!$G34,コンシューマー!G:G) -> 0 | N34: =SUMIF(コンシューマー!$B:$B,全体!$G34,コンシューマー!H:H) -> 0 | O34: =SUMIF(コンシューマー!$B:$B,全体!$G34,コンシューマー!I:I) -> 0 | P34: =SUMIF(コンシューマー!$B:$B,全体!$G34,コンシューマー!J:J) -> 0 | Q34: =SUMIF(コンシューマー!$B:$B,全体!$G34,コンシューマー!K:K) -> 0 | R34: =SUMIF(コンシューマー!$B:$B,全体!$G34,コンシューマー!L:L) -> 0 | S34: =SUMIF(コンシューマー!$B:$B,全体!$G34,コンシューマー!M:M) -> 183 | T34: =SUMIF(コンシューマー!$B:$B,全体!$G34,コンシューマー!N:N) -> 564 | U34: =SUMIF(コンシューマー!$B:$B,全体!$G34,コンシューマー!O:O) -> 705 | V34: =SUMIF(コンシューマー!$B:$B,全体!$G34,コンシューマー!P:P) -> 489 | W34: =SUMIF(コンシューマー!$B:$B,全体!$G34,コンシューマー!Q:Q) -> 564 | X34: =SUMIF(コンシューマー!$B:$B,全体!$G34,コンシューマー!R:R) -> 708 | Y34: =SUMIF(コンシューマー!$B:$B,全体!$G34,コンシューマー!S:S) -> 634 | Z34: =SUMIF(コンシューマー!$B:$B,全体!$G34,コンシューマー!T:T) -> 770 | AA34: =SUMIF(コンシューマー!$B:$B,全体!$G34,コンシューマー!U:U) -> 859 | AB34: =SUMIF(コンシューマー!$B:$B,全体!$G34,コンシューマー!V:V) -> 627 | AC34: =SUMIF(コンシューマー!$B:$B,全体!$G34,コンシューマー!W:W) -> 1031 | AD34: =SUMIF(コンシューマー!$B:$B,全体!$G34,コンシューマー!X:X) -> 574 | AE34: =SUMIF(コンシューマー!$B:$B,全体!$G34,コンシューマー!Y:Y) -> 520 | AF34: =SUMIF(コンシューマー!$B:$B,全体!$G34,コンシューマー!Z:Z) -> 529 | AG34: =SUMIF(コンシューマー!$B:$B,全体!$G34,コンシューマー!AA:AA) -> 816 | AI34: 1198 | AK34: 844 | AL34: 1163.2258 | AM34: 1083.4892 | AN34: 423 | AO34: 526 | AP34: 276 | AQ34: 340 | AR34: =SUMIF(結果貼付!$A:$A,G34,結果貼付!$D:$D) -> 179 | AS34: =(AR34/AS$2)*AS$1 -> 383.57143 | AT34: =SUM(SUMIF(コンシューマー!$B:$B,全体!$G34,コンシューマー!AO:AO),SUMIF(コマーシャル!$B:$B,全体!$G34,コマーシャル!AK:AK)) -> 450 | AU34: =SUM(SUMIF(コンシューマー!$B:$B,全体!$G34,コンシューマー!AP:AP),SUMIF(コマーシャル!$B:$B,全体!$G34,コマーシャル!AL:AL)) -> 561 | AV34: =SUM(SUMIF(コンシューマー!$B:$B,全体!$G34,コンシューマー!AQ:AQ),SUMIF(コマーシャル!$B:$B,全体!$G34,コマーシャル!AM:AM)) -> 456.7782 | AW34: =SUM(SUMIF(コンシューマー!$B:$B,全体!$G34,コンシューマー!AR:AR),SUMIF(コマーシャル!$B:$B,全体!$G34,コマーシャル!AN:AN)) -> 448.74031 | AX34: =SUM(SUMIF(コンシューマー!$B:$B,全体!$G34,コンシューマー!AS:AS),SUMIF(コマーシャル!$B:$B,全体!$G34,コマーシャル!AO:AO)) -> 405.42528 | AY34: =SUM(SUMIF(コンシューマー!$B:$B,全体!$G34,コンシューマー!AT:AT),SUMIF(コマーシャル!$B:$B,全体!$G34,コマーシャル!AP:AP)) -> 402.31395
A35: =SUMIFS(SAP貼付!K:K,SAP貼付!C:C,全体!G35) -> 270 | B35: =SUMIFS(VGAMBFCST貼付!D:D,VGAMBFCST貼付!B:B,G35,VGAMBFCST貼付!C:C,全体!$B$20) -> 16 | C35: =SUMIFS(VGAMBFCST貼付!D:D,VGAMBFCST貼付!B:B,G35,VGAMBFCST貼付!C:C,全体!$C$20) -> 0 | D35: =SUM(A35:C35) -> 286 | E35: =IFERROR(D35-SUM(#REF!)," ") | G35: RTX3050 6G LP | H35: =IFERROR(IF(MATCH($G35,コンシューマー!B:B,0),"Y"),"-") -> Y | I35: =IFERROR(IF(MATCH($G35,コマーシャル!B:B,0),"Y"),"-") -> Y | J35: =SUMIF(コンシューマー!$B:$B,全体!$G35,コンシューマー!D:D) -> 0 | K35: =SUMIF(コンシューマー!$B:$B,全体!$G35,コンシューマー!E:E) -> 0 | L35: =SUMIF(コンシューマー!$B:$B,全体!$G35,コンシューマー!F:F) -> 0 | M35: =SUMIF(コンシューマー!$B:$B,全体!$G35,コンシューマー!G:G) -> 0 | N35: =SUMIF(コンシューマー!$B:$B,全体!$G35,コンシューマー!H:H) -> 0 | O35: =SUMIF(コンシューマー!$B:$B,全体!$G35,コンシューマー!I:I) -> 0 | P35: =SUMIF(コンシューマー!$B:$B,全体!$G35,コンシューマー!J:J) -> 0 | Q35: =SUMIF(コンシューマー!$B:$B,全体!$G35,コンシューマー!K:K) -> 0 | R35: =SUMIF(コンシューマー!$B:$B,全体!$G35,コンシューマー!L:L) -> 0 | S35: =SUMIF(コンシューマー!$B:$B,全体!$G35,コンシューマー!M:M) -> 0 | T35: =SUMIF(コンシューマー!$B:$B,全体!$G35,コンシューマー!N:N) -> 0 | U35: =SUMIF(コンシューマー!$B:$B,全体!$G35,コンシューマー!O:O) -> 0 | V35: =SUMIF(コンシューマー!$B:$B,全体!$G35,コンシューマー!P:P) -> 0 | W35: =SUMIF(コンシューマー!$B:$B,全体!$G35,コンシューマー!Q:Q) -> 0 | X35: =SUMIF(コンシューマー!$B:$B,全体!$G35,コンシューマー!R:R) -> 0 | Y35: =SUMIF(コンシューマー!$B:$B,全体!$G35,コンシューマー!S:S) -> 9 | Z35: =SUMIF(コンシューマー!$B:$B,全体!$G35,コンシューマー!T:T) -> 17 | AA35: =SUMIF(コンシューマー!$B:$B,全体!$G35,コンシューマー!U:U) -> 17 | AB35: =SUMIF(コンシューマー!$B:$B,全体!$G35,コンシューマー!V:V) -> 45 | AC35: =SUMIF(コンシューマー!$B:$B,全体!$G35,コンシューマー!W:W) -> 55 | AD35: =SUMIF(コンシューマー!$B:$B,全体!$G35,コンシューマー!X:X) -> 36 | AE35: =SUMIF(コンシューマー!$B:$B,全体!$G35,コンシューマー!Y:Y) -> 61 | AF35: =SUMIF(コンシューマー!$B:$B,全体!$G35,コンシューマー!Z:Z) -> 53 | AG35: =SUMIF(コンシューマー!$B:$B,全体!$G35,コンシューマー!AA:AA) -> 53 | AI35: 81 | AK35: 54 | AL35: 54.193548 | AM35: 49.574167 | AN35: 85 | AO35: 99 | AP35: 22 | AQ35: 75 | AR35: =SUMIF(結果貼付!$A:$A,G35,結果貼付!$D:$D) -> 3 | AS35: =(AR35/AS$2)*AS$1 -> 6.4285714 | AT35: =SUM(SUMIF(コンシューマー!$B:$B,全体!$G35,コンシューマー!AO:AO),SUMIF(コマーシャル!$B:$B,全体!$G35,コマーシャル!AK:AK)) -> 7.20576 | AU35: =SUM(SUMIF(コンシューマー!$B:$B,全体!$G35,コンシューマー!AP:AP),SUMIF(コマーシャル!$B:$B,全体!$G35,コマーシャル!AL:AL)) -> 0 | AV35: =SUM(SUMIF(コンシューマー!$B:$B,全体!$G35,コンシューマー!AQ:AQ),SUMIF(コマーシャル!$B:$B,全体!$G35,コマーシャル!AM:AM)) -> 0 | AW35: =SUM(SUMIF(コンシューマー!$B:$B,全体!$G35,コンシューマー!AR:AR),SUMIF(コマーシャル!$B:$B,全体!$G35,コマーシャル!AN:AN)) -> 0 | AX35: =SUM(SUMIF(コンシューマー!$B:$B,全体!$G35,コンシューマー!AS:AS),SUMIF(コマーシャル!$B:$B,全体!$G35,コマーシャル!AO:AO)) -> 0 | AY35: =SUM(SUMIF(コンシューマー!$B:$B,全体!$G35,コンシューマー!AT:AT),SUMIF(コマーシャル!$B:$B,全体!$G35,コマーシャル!AP:AP)) -> 0
A36: =SUMIFS(SAP貼付!K:K,SAP貼付!C:C,全体!G36) -> 53 | B36: =SUMIFS(VGAMBFCST貼付!D:D,VGAMBFCST貼付!B:B,G36,VGAMBFCST貼付!C:C,全体!$B$20) -> 0 | C36: =SUMIFS(VGAMBFCST貼付!D:D,VGAMBFCST貼付!B:B,G36,VGAMBFCST貼付!C:C,全体!$C$20) -> 0 | D36: =SUM(A36:C36) -> 53 | E36: =IFERROR(D36-SUM(#REF!)," ") | G36: GT1030 | H36: =IFERROR(IF(MATCH($G36,コンシューマー!B:B,0),"Y"),"-") -> - | I36: =IFERROR(IF(MATCH($G36,コマーシャル!B:B,0),"Y"),"-") -> Y | J36: =SUMIF(コンシューマー!$B:$B,全体!$G36,コンシューマー!D:D) -> 0 | K36: =SUMIF(コンシューマー!$B:$B,全体!$G36,コンシューマー!E:E) -> 0 | L36: =SUMIF(コンシューマー!$B:$B,全体!$G36,コンシューマー!F:F) -> 0 | M36: =SUMIF(コンシューマー!$B:$B,全体!$G36,コンシューマー!G:G) -> 0 | N36: =SUMIF(コンシューマー!$B:$B,全体!$G36,コンシューマー!H:H) -> 0 | O36: =SUMIF(コンシューマー!$B:$B,全体!$G36,コンシューマー!I:I) -> 0 | P36: =SUMIF(コンシューマー!$B:$B,全体!$G36,コンシューマー!J:J) -> 0 | Q36: =SUMIF(コンシューマー!$B:$B,全体!$G36,コンシューマー!K:K) -> 0 | R36: =SUMIF(コンシューマー!$B:$B,全体!$G36,コンシューマー!L:L) -> 0 | S36: =SUMIF(コンシューマー!$B:$B,全体!$G36,コンシューマー!M:M) -> 0 | T36: =SUMIF(コンシューマー!$B:$B,全体!$G36,コンシューマー!N:N) -> 0 | U36: =SUMIF(コンシューマー!$B:$B,全体!$G36,コンシューマー!O:O) -> 0 | V36: =SUMIF(コンシューマー!$B:$B,全体!$G36,コンシューマー!P:P) -> 0 | W36: =SUMIF(コンシューマー!$B:$B,全体!$G36,コンシューマー!Q:Q) -> 0 | X36: =SUMIF(コンシューマー!$B:$B,全体!$G36,コンシューマー!R:R) -> 0 | Y36: =SUMIF(コンシューマー!$B:$B,全体!$G36,コンシューマー!S:S) -> 0 | Z36: =SUMIF(コンシューマー!$B:$B,全体!$G36,コンシューマー!T:T) -> 0 | AA36: =SUMIF(コンシューマー!$B:$B,全体!$G36,コンシューマー!U:U) -> 0 | AB36: =SUMIF(コンシューマー!$B:$B,全体!$G36,コンシューマー!V:V) -> 0 | AC36: =SUMIF(コンシューマー!$B:$B,全体!$G36,コンシューマー!W:W) -> 0 | AD36: =SUMIF(コンシューマー!$B:$B,全体!$G36,コンシューマー!X:X) -> 0 | AE36: =SUMIF(コンシューマー!$B:$B,全体!$G36,コンシューマー!Y:Y) -> 0 | AF36: =SUMIF(コンシューマー!$B:$B,全体!$G36,コンシューマー!Z:Z) -> 0 | AG36: =SUMIF(コンシューマー!$B:$B,全体!$G36,コンシューマー!AA:AA) -> 0 | AI36: 0 | AK36: 0 | AL36: 0 | AM36: 0 | AN36: 0 | AO36: 0 | AP36: 0 | AQ36: 0 | AR36: =SUMIF(結果貼付!$A:$A,G36,結果貼付!$D:$D) -> 0 | AS36: =(AR36/AS$2)*AS$1 -> 0 | AT36: =SUM(SUMIF(コンシューマー!$B:$B,全体!$G36,コンシューマー!AO:AO),SUMIF(コマーシャル!$B:$B,全体!$G36,コマーシャル!AK:AK)) -> 0 | AU36: =SUM(SUMIF(コンシューマー!$B:$B,全体!$G36,コンシューマー!AP:AP),SUMIF(コマーシャル!$B:$B,全体!$G36,コマーシャル!AL:AL)) -> 0 | AV36: =SUM(SUMIF(コンシューマー!$B:$B,全体!$G36,コンシューマー!AQ:AQ),SUMIF(コマーシャル!$B:$B,全体!$G36,コマーシャル!AM:AM)) -> 0 | AW36: =SUM(SUMIF(コンシューマー!$B:$B,全体!$G36,コンシューマー!AR:AR),SUMIF(コマーシャル!$B:$B,全体!$G36,コマーシャル!AN:AN)) -> 0 | AX36: =SUM(SUMIF(コンシューマー!$B:$B,全体!$G36,コンシューマー!AS:AS),SUMIF(コマーシャル!$B:$B,全体!$G36,コマーシャル!AO:AO)) -> 0 | AY36: =SUM(SUMIF(コンシューマー!$B:$B,全体!$G36,コンシューマー!AT:AT),SUMIF(コマーシャル!$B:$B,全体!$G36,コマーシャル!AP:AP)) -> 0
G37: A310 LP | H37: =IFERROR(IF(MATCH($G37,コンシューマー!B:B,0),"Y"),"-") -> Y | I37: =IFERROR(IF(MATCH($G37,コマーシャル!B:B,0),"Y"),"-") -> - | J37: =SUMIF(コンシューマー!$B:$B,全体!$G37,コンシューマー!D:D) -> 0 | K37: =SUMIF(コンシューマー!$B:$B,全体!$G37,コンシューマー!E:E) -> 0 | L37: =SUMIF(コンシューマー!$B:$B,全体!$G37,コンシューマー!F:F) -> 0 | M37: =SUMIF(コンシューマー!$B:$B,全体!$G37,コンシューマー!G:G) -> 0 | N37: =SUMIF(コンシューマー!$B:$B,全体!$G37,コンシューマー!H:H) -> 0 | O37: =SUMIF(コンシューマー!$B:$B,全体!$G37,コンシューマー!I:I) -> 0 | P37: =SUMIF(コンシューマー!$B:$B,全体!$G37,コンシューマー!J:J) -> 0 | Q37: =SUMIF(コンシューマー!$B:$B,全体!$G37,コンシューマー!K:K) -> 0 | R37: =SUMIF(コンシューマー!$B:$B,全体!$G37,コンシューマー!L:L) -> 0 | S37: =SUMIF(コンシューマー!$B:$B,全体!$G37,コンシューマー!M:M) -> 0 | T37: =SUMIF(コンシューマー!$B:$B,全体!$G37,コンシューマー!N:N) -> 0 | U37: =SUMIF(コンシューマー!$B:$B,全体!$G37,コンシューマー!O:O) -> 0 | V37: =SUMIF(コンシューマー!$B:$B,全体!$G37,コンシューマー!P:P) -> 0 | W37: =SUMIF(コンシューマー!$B:$B,全体!$G37,コンシューマー!Q:Q) -> 0 | X37: =SUMIF(コンシューマー!$B:$B,全体!$G37,コンシューマー!R:R) -> 0 | Y37: =SUMIF(コンシューマー!$B:$B,全体!$G37,コンシューマー!S:S) -> 0 | Z37: =SUMIF(コンシューマー!$B:$B,全体!$G37,コンシューマー!T:T) -> 0 | AA37: =SUMIF(コンシューマー!$B:$B,全体!$G37,コンシューマー!U:U) -> 0 | AB37: =SUMIF(コンシューマー!$B:$B,全体!$G37,コンシューマー!V:V) -> 0 | AC37: =SUMIF(コンシューマー!$B:$B,全体!$G37,コンシューマー!W:W) -> 0 | AD37: =SUMIF(コンシューマー!$B:$B,全体!$G37,コンシューマー!X:X) -> 0 | AE37: =SUMIF(コンシューマー!$B:$B,全体!$G37,コンシューマー!Y:Y) -> 0 | AF37: =SUMIF(コンシューマー!$B:$B,全体!$G37,コンシューマー!Z:Z) -> 0 | AG37: =SUMIF(コンシューマー!$B:$B,全体!$G37,コンシューマー!AA:AA) -> 0 | AI37: 0 | AK37: 0 | AL37: 0 | AM37: 0 | AN37: 0 | AO37: 0 | AP37: 0 | AQ37: 0 | AR37: =SUMIF(結果貼付!$A:$A,G37,結果貼付!$D:$D) -> 0 | AS37: =(AR37/AS$2)*AS$1 -> 0 | AT37: =SUM(SUMIF(コンシューマー!$B:$B,全体!$G37,コンシューマー!AO:AO),SUMIF(コマーシャル!$B:$B,全体!$G37,コマーシャル!AK:AK)) -> 7.2 | AU37: =SUM(SUMIF(コンシューマー!$B:$B,全体!$G37,コンシューマー!AP:AP),SUMIF(コマーシャル!$B:$B,全体!$G37,コマーシャル!AL:AL)) -> 5 | AV37: =SUM(SUMIF(コンシューマー!$B:$B,全体!$G37,コンシューマー!AQ:AQ),SUMIF(コマーシャル!$B:$B,全体!$G37,コマーシャル!AM:AM)) -> 5 | AW37: =SUM(SUMIF(コンシューマー!$B:$B,全体!$G37,コンシューマー!AR:AR),SUMIF(コマーシャル!$B:$B,全体!$G37,コマーシャル!AN:AN)) -> 5 | AX37: =SUM(SUMIF(コンシューマー!$B:$B,全体!$G37,コンシューマー!AS:AS),SUMIF(コマーシャル!$B:$B,全体!$G37,コマーシャル!AO:AO)) -> 5 | AY37: =SUM(SUMIF(コンシューマー!$B:$B,全体!$G37,コンシューマー!AT:AT),SUMIF(コマーシャル!$B:$B,全体!$G37,コマーシャル!AP:AP)) -> 4.9549638 | AZ37: 初回発注のみ、追加不要
A38: =SUMIFS(SAP貼付!K:K,SAP貼付!C:C,全体!G38) -> 13 | B38: =SUMIFS(VGAMBFCST貼付!D:D,VGAMBFCST貼付!B:B,G38,VGAMBFCST貼付!C:C,全体!$B$20) -> 0 | C38: =SUMIFS(VGAMBFCST貼付!D:D,VGAMBFCST貼付!B:B,G38,VGAMBFCST貼付!C:C,全体!$C$20) -> 0 | D38: =SUM(A38:C38) -> 13 | E38: =IFERROR(D38-SUM(#REF!)," ") | G38: A380 | H38: =IFERROR(IF(MATCH($G38,コンシューマー!B:B,0),"Y"),"-") -> - | I38: =IFERROR(IF(MATCH($G38,コマーシャル!B:B,0),"Y"),"-") -> - | J38: =SUMIF(コンシューマー!$B:$B,全体!$G38,コンシューマー!D:D) -> 0 | K38: =SUMIF(コンシューマー!$B:$B,全体!$G38,コンシューマー!E:E) -> 0 | L38: =SUMIF(コンシューマー!$B:$B,全体!$G38,コンシューマー!F:F) -> 0 | M38: =SUMIF(コンシューマー!$B:$B,全体!$G38,コンシューマー!G:G) -> 0 | N38: =SUMIF(コンシューマー!$B:$B,全体!$G38,コンシューマー!H:H) -> 0 | O38: =SUMIF(コンシューマー!$B:$B,全体!$G38,コンシューマー!I:I) -> 0 | P38: =SUMIF(コンシューマー!$B:$B,全体!$G38,コンシューマー!J:J) -> 0 | Q38: =SUMIF(コンシューマー!$B:$B,全体!$G38,コンシューマー!K:K) -> 0 | R38: =SUMIF(コンシューマー!$B:$B,全体!$G38,コンシューマー!L:L) -> 0 | S38: =SUMIF(コンシューマー!$B:$B,全体!$G38,コンシューマー!M:M) -> 0 | T38: =SUMIF(コンシューマー!$B:$B,全体!$G38,コンシューマー!N:N) -> 0 | U38: =SUMIF(コンシューマー!$B:$B,全体!$G38,コンシューマー!O:O) -> 0 | V38: =SUMIF(コンシューマー!$B:$B,全体!$G38,コンシューマー!P:P) -> 0 | W38: =SUMIF(コンシューマー!$B:$B,全体!$G38,コンシューマー!Q:Q) -> 0 | X38: =SUMIF(コンシューマー!$B:$B,全体!$G38,コンシューマー!R:R) -> 0 | Y38: =SUMIF(コンシューマー!$B:$B,全体!$G38,コンシューマー!S:S) -> 0 | Z38: =SUMIF(コンシューマー!$B:$B,全体!$G38,コンシューマー!T:T) -> 0 | AA38: =SUMIF(コンシューマー!$B:$B,全体!$G38,コンシューマー!U:U) -> 0 | AB38: =SUMIF(コンシューマー!$B:$B,全体!$G38,コンシューマー!V:V) -> 0 | AC38: =SUMIF(コンシューマー!$B:$B,全体!$G38,コンシューマー!W:W) -> 0 | AD38: =SUMIF(コンシューマー!$B:$B,全体!$G38,コンシューマー!X:X) -> 0 | AE38: =SUMIF(コンシューマー!$B:$B,全体!$G38,コンシューマー!Y:Y) -> 0 | AF38: =SUMIF(コンシューマー!$B:$B,全体!$G38,コンシューマー!Z:Z) -> 0 | AG38: =SUMIF(コンシューマー!$B:$B,全体!$G38,コンシューマー!AA:AA) -> 0 | AI38: 0 | AK38: 0 | AL38: 0 | AM38: 0 | AN38: 0 | AO38: 0 | AP38: 0 | AQ38: 0 | AR38: =SUMIF(結果貼付!$A:$A,G38,結果貼付!$D:$D) -> 0 | AS38: =(AR38/AS$2)*AS$1 -> 0 | AT38: =SUM(SUMIF(コンシューマー!$B:$B,全体!$G38,コンシューマー!AO:AO),SUMIF(コマーシャル!$B:$B,全体!$G38,コマーシャル!AK:AK)) -> 0 | AU38: =SUM(SUMIF(コンシューマー!$B:$B,全体!$G38,コンシューマー!AP:AP),SUMIF(コマーシャル!$B:$B,全体!$G38,コマーシャル!AL:AL)) -> 0 | AV38: =SUM(SUMIF(コンシューマー!$B:$B,全体!$G38,コンシューマー!AQ:AQ),SUMIF(コマーシャル!$B:$B,全体!$G38,コマーシャル!AM:AM)) -> 0 | AW38: =SUM(SUMIF(コンシューマー!$B:$B,全体!$G38,コンシューマー!AR:AR),SUMIF(コマーシャル!$B:$B,全体!$G38,コマーシャル!AN:AN)) -> 0 | AX38: =SUM(SUMIF(コンシューマー!$B:$B,全体!$G38,コンシューマー!AS:AS),SUMIF(コマーシャル!$B:$B,全体!$G38,コマーシャル!AO:AO)) -> 0 | AY38: =SUM(SUMIF(コンシューマー!$B:$B,全体!$G38,コンシューマー!AT:AT),SUMIF(コマーシャル!$B:$B,全体!$G38,コマーシャル!AP:AP)) -> 0
A39: =SUMIFS(SAP貼付!K:K,SAP貼付!C:C,全体!G39) -> 0 | B39: =SUMIFS(VGAMBFCST貼付!D:D,VGAMBFCST貼付!B:B,G39,VGAMBFCST貼付!C:C,全体!$B$20) -> 0 | C39: =SUMIFS(VGAMBFCST貼付!D:D,VGAMBFCST貼付!B:B,G39,VGAMBFCST貼付!C:C,全体!$C$20) -> 0 | D39: =SUM(A39:C39) -> 0 | G39: RX9070XT | H39: =IFERROR(IF(MATCH($G39,コンシューマー!B:B,0),"Y"),"-") -> Y | I39: =IFERROR(IF(MATCH($G39,コマーシャル!B:B,0),"Y"),"-") -> Y | J39: =SUMIF(コンシューマー!$B:$B,全体!$G39,コンシューマー!D:D) -> 0 | K39: =SUMIF(コンシューマー!$B:$B,全体!$G39,コンシューマー!E:E) -> 0 | L39: =SUMIF(コンシューマー!$B:$B,全体!$G39,コンシューマー!F:F) -> 0 | M39: =SUMIF(コンシューマー!$B:$B,全体!$G39,コンシューマー!G:G) -> 0 | N39: =SUMIF(コンシューマー!$B:$B,全体!$G39,コンシューマー!H:H) -> 0 | O39: =SUMIF(コンシューマー!$B:$B,全体!$G39,コンシューマー!I:I) -> 0 | P39: =SUMIF(コンシューマー!$B:$B,全体!$G39,コンシューマー!J:J) -> 0 | Q39: =SUMIF(コンシューマー!$B:$B,全体!$G39,コンシューマー!K:K) -> 0 | R39: =SUMIF(コンシューマー!$B:$B,全体!$G39,コンシューマー!L:L) -> 0 | S39: =SUMIF(コンシューマー!$B:$B,全体!$G39,コンシューマー!M:M) -> 0 | T39: =SUMIF(コンシューマー!$B:$B,全体!$G39,コンシューマー!N:N) -> 0 | U39: =SUMIF(コンシューマー!$B:$B,全体!$G39,コンシューマー!O:O) -> 0 | V39: =SUMIF(コンシューマー!$B:$B,全体!$G39,コンシューマー!P:P) -> 0 | W39: =SUMIF(コンシューマー!$B:$B,全体!$G39,コンシューマー!Q:Q) -> 0 | X39: =SUMIF(コンシューマー!$B:$B,全体!$G39,コンシューマー!R:R) -> 0 | Y39: =SUMIF(コンシューマー!$B:$B,全体!$G39,コンシューマー!S:S) -> 0 | Z39: =SUMIF(コンシューマー!$B:$B,全体!$G39,コンシューマー!T:T) -> 0 | AA39: =SUMIF(コンシューマー!$B:$B,全体!$G39,コンシューマー!U:U) -> 0 | AB39: =SUMIF(コンシューマー!$B:$B,全体!$G39,コンシューマー!V:V) -> 0 | AC39: =SUMIF(コンシューマー!$B:$B,全体!$G39,コンシューマー!W:W) -> 182 | AD39: =SUMIF(コンシューマー!$B:$B,全体!$G39,コンシューマー!X:X) -> 777 | AE39: =SUMIF(コンシューマー!$B:$B,全体!$G39,コンシューマー!Y:Y) -> 379 | AF39: =SUMIF(コンシューマー!$B:$B,全体!$G39,コンシューマー!Z:Z) -> 342 | AG39: =SUMIF(コンシューマー!$B:$B,全体!$G39,コンシューマー!AA:AA) -> 391 | AI39: 201 | AK39: 148 | AL39: 239.03226 | AM39: 137.43333 | AN39: 36 | AO39: 178 | AP39: 578 | AQ39: 25 | AR39: =SUMIF(結果貼付!$A:$A,G39,結果貼付!$D:$D) -> 12 | AS39: =(AR39/AS$2)*AS$1 -> 25.714286 | AT39: =SUM(SUMIF(コンシューマー!$B:$B,全体!$G39,コンシューマー!AO:AO),SUMIF(コマーシャル!$B:$B,全体!$G39,コマーシャル!AK:AK)) -> 36.925397 | AU39: =SUM(SUMIF(コンシューマー!$B:$B,全体!$G39,コンシューマー!AP:AP),SUMIF(コマーシャル!$B:$B,全体!$G39,コマーシャル!AL:AL)) -> 43.710477 | AV39: =SUM(SUMIF(コンシューマー!$B:$B,全体!$G39,コンシューマー!AQ:AQ),SUMIF(コマーシャル!$B:$B,全体!$G39,コマーシャル!AM:AM)) -> 37.500281 | AW39: =SUM(SUMIF(コンシューマー!$B:$B,全体!$G39,コンシューマー!AR:AR),SUMIF(コマーシャル!$B:$B,全体!$G39,コマーシャル!AN:AN)) -> 36.818559 | AX39: =SUM(SUMIF(コンシューマー!$B:$B,全体!$G39,コンシューマー!AS:AS),SUMIF(コマーシャル!$B:$B,全体!$G39,コマーシャル!AO:AO)) -> 32.296725 | AY39: =SUM(SUMIF(コンシューマー!$B:$B,全体!$G39,コンシューマー!AT:AT),SUMIF(コマーシャル!$B:$B,全体!$G39,コマーシャル!AP:AP)) -> 32.032842 | AZ39: 12月ALGSレンタル分130pcs
A40: =SUMIFS(SAP貼付!K:K,SAP貼付!C:C,全体!G40) -> 0 | B40: =SUMIFS(VGAMBFCST貼付!D:D,VGAMBFCST貼付!B:B,G40,VGAMBFCST貼付!C:C,全体!$B$20) -> 0 | C40: =SUMIFS(VGAMBFCST貼付!D:D,VGAMBFCST貼付!B:B,G40,VGAMBFCST貼付!C:C,全体!$C$20) -> 0 | D40: =SUM(A40:C40) -> 0 | G40: RX9070 | H40: =IFERROR(IF(MATCH($G40,コンシューマー!B:B,0),"Y"),"-") -> Y | I40: =IFERROR(IF(MATCH($G40,コマーシャル!B:B,0),"Y"),"-") -> Y | J40: =SUMIF(コンシューマー!$B:$B,全体!$G40,コンシューマー!D:D) -> 0 | K40: =SUMIF(コンシューマー!$B:$B,全体!$G40,コンシューマー!E:E) -> 0 | L40: =SUMIF(コンシューマー!$B:$B,全体!$G40,コンシューマー!F:F) -> 0 | M40: =SUMIF(コンシューマー!$B:$B,全体!$G40,コンシューマー!G:G) -> 0 | N40: =SUMIF(コンシューマー!$B:$B,全体!$G40,コンシューマー!H:H) -> 0 | O40: =SUMIF(コンシューマー!$B:$B,全体!$G40,コンシューマー!I:I) -> 0 | P40: =SUMIF(コンシューマー!$B:$B,全体!$G40,コンシューマー!J:J) -> 0 | Q40: =SUMIF(コンシューマー!$B:$B,全体!$G40,コンシューマー!K:K) -> 0 | R40: =SUMIF(コンシューマー!$B:$B,全体!$G40,コンシューマー!L:L) -> 0 | S40: =SUMIF(コンシューマー!$B:$B,全体!$G40,コンシューマー!M:M) -> 0 | T40: =SUMIF(コンシューマー!$B:$B,全体!$G40,コンシューマー!N:N) -> 0 | U40: =SUMIF(コンシューマー!$B:$B,全体!$G40,コンシューマー!O:O) -> 0 | V40: =SUMIF(コンシューマー!$B:$B,全体!$G40,コンシューマー!P:P) -> 0 | W40: =SUMIF(コンシューマー!$B:$B,全体!$G40,コンシューマー!Q:Q) -> 0 | X40: =SUMIF(コンシューマー!$B:$B,全体!$G40,コンシューマー!R:R) -> 0 | Y40: =SUMIF(コンシューマー!$B:$B,全体!$G40,コンシューマー!S:S) -> 0 | Z40: =SUMIF(コンシューマー!$B:$B,全体!$G40,コンシューマー!T:T) -> 0 | AA40: =SUMIF(コンシューマー!$B:$B,全体!$G40,コンシューマー!U:U) -> 0 | AB40: =SUMIF(コンシューマー!$B:$B,全体!$G40,コンシューマー!V:V) -> 0 | AC40: =SUMIF(コンシューマー!$B:$B,全体!$G40,コンシューマー!W:W) -> 57 | AD40: =SUMIF(コンシューマー!$B:$B,全体!$G40,コンシューマー!X:X) -> 21 | AE40: =SUMIF(コンシューマー!$B:$B,全体!$G40,コンシューマー!Y:Y) -> 8 | AF40: =SUMIF(コンシューマー!$B:$B,全体!$G40,コンシューマー!Z:Z) -> 9 | AG40: =SUMIF(コンシューマー!$B:$B,全体!$G40,コンシューマー!AA:AA) -> 53 | AI40: 30 | AK40: 23 | AL40: 37.741935 | AM40: 17.67 | AN40: 7 | AO40: 3 | AP40: 2 | AQ40: 1 | AR40: =SUMIF(結果貼付!$A:$A,G40,結果貼付!$D:$D) -> 2 | AS40: =(AR40/AS$2)*AS$1 -> 4.2857143 | AT40: =SUM(SUMIF(コンシューマー!$B:$B,全体!$G40,コンシューマー!AO:AO),SUMIF(コマーシャル!$B:$B,全体!$G40,コマーシャル!AK:AK)) -> 4.3570159 | AU40: =SUM(SUMIF(コンシューマー!$B:$B,全体!$G40,コンシューマー!AP:AP),SUMIF(コマーシャル!$B:$B,全体!$G40,コマーシャル!AL:AL)) -> 4.6284191 | AV40: =SUM(SUMIF(コンシューマー!$B:$B,全体!$G40,コンシューマー!AQ:AQ),SUMIF(コマーシャル!$B:$B,全体!$G40,コマーシャル!AM:AM)) -> 4.3800112 | AW40: =SUM(SUMIF(コンシューマー!$B:$B,全体!$G40,コンシューマー!AR:AR),SUMIF(コマーシャル!$B:$B,全体!$G40,コマーシャル!AN:AN)) -> 4.3527424 | AX40: =SUM(SUMIF(コンシューマー!$B:$B,全体!$G40,コンシューマー!AS:AS),SUMIF(コマーシャル!$B:$B,全体!$G40,コマーシャル!AO:AO)) -> 4.171869 | AY40: =SUM(SUMIF(コンシューマー!$B:$B,全体!$G40,コンシューマー!AT:AT),SUMIF(コマーシャル!$B:$B,全体!$G40,コマーシャル!AP:AP)) -> 4.1613137
...

Sheet コラボ販売予測
A1: 印刷面 | B1: 金具 | E1: 45901 | F1: 45931 | G1: 45962 | H1: 45992 | I1: 46023 | J1: 46054 | K1: 46082 | L1: 46113 | M1: 46143 | N1: 46174 | O1: 46204 | P1: 46235 | Q1: 46266 | R1: 46296 | S1: 46327 | T1: 46357 | U1: 46388 | V1: 46419 | W1: 46447 | X1: 46478 | Y1: 46508 | Z1: 46539 | AA1: 46569 | AB1: 46600 | AC1: 46631 | AD1: 46661 | AE1: 46692 | AF1: 46722 | AG1: 46753
A2: 表 | B2: あり | C2: SF 黒 コラボ 表 | D2: SF黒コラボ 渋ハル | E2: 100 | F2: 50 | G2: 30 | H2: 30 | I2: 20 | J2: 20 | K2: 20 | L2: 20 | M2: 20 | N2: 20 | O2: 10 | P2: 10 | Q2: 10 | R2: 10 | S2: 10 | T2: 10 | U2: 10 | V2: 10 | W2: 10 | X2: 10 | Y2: 10 | Z2: 10 | AA2: 10
A3: 表 | B3: あり | C3: SF 黒 コラボ 表 | D3: SF黒コラボ 葛葉 | F3: 1300 | G3: 500 | H3: 500 | I3: 400 | J3: 200 | K3: 200 | L3: 200 | M3: 200 | N3: 80 | O3: 80 | P3: 80 | Q3: 80 | R3: 80 | S3: 80 | T3: 80 | U3: 80 | V3: 80 | W3: 80 | X3: 80 | Y3: 80 | Z3: 80 | AA3: 80 | AB3: 80 | AC3: 80 | AD3: 80
A4: 表 | B4: あり | C4: SF 白 コラボ | D4: SF白コラボ Nachoneko | G4: 200 | H4: 100 | I4: 60 | J4: 100 | K4: 100 | L4: 100 | M4: 100 | N4: 50 | O4: 50 | P4: 50 | Q4: 50 | R4: 50 | S4: 50 | T4: 50 | U4: 50 | V4: 50 | W4: 50 | X4: 50 | Y4: 50 | Z4: 50 | AA4: 50 | AB4: 50 | AC4: 50 | AD4: 50
A5: 表 | B5: あり | C5: SF 黒 コラボ 表 | D5: SF黒コラボ REJECT | H5: 50 | I5: 50 | J5: 10 | K5: 10 | L5: 10 | M5: 10 | N5: 10 | O5: 10 | P5: 10 | Q5: 10 | R5: 10 | S5: 10 | T5: 10 | U5: 10 | V5: 10 | W5: 10 | X5: 10 | Y5: 10 | Z5: 10 | AA5: 10 | AB5: 10 | AC5: 10 | AD5: 10 | AE5: 10
A6: 裏 | B6: 無 | C6: SF 白 コラボ | D6: SF白コラボ 猫麦とろろ | L6: 400 | M6: 200 | N6: 30 | O6: 30 | P6: 30 | Q6: 30 | R6: 30 | S6: 30 | T6: 30 | U6: 30 | V6: 30 | W6: 30 | X6: 30 | Y6: 30 | Z6: 30 | AA6: 30 | AB6: 30 | AC6: 30 | AD6: 30
A7: 裏 | B7: 無 | C7: SF 黒 コラボ | D7: SF黒コラボ 藤ちょこ | L7: 500 | M7: 250 | N7: 30 | O7: 30 | P7: 30 | Q7: 30 | R7: 30 | S7: 30 | T7: 30 | U7: 30 | V7: 30 | W7: 30
A8: 裏 | B8: 無 | C8: SF 白 コラボ | D8: SF白コラボ シャニマス | L8: 300 | M8: 180 | N8: 20 | O8: 20 | P8: 20 | Q8: 20 | R8: 20 | S8: 20 | T8: 20 | U8: 20 | V8: 20
A9: 表 | B9: あり | C9: SF 黒 コラボ 表 | D9: SF黒コラボ MHWs | J9: 100 | K9: 50 | L9: 50 | M9: 50 | N9: 10 | O9: 10 | P9: 10 | Q9: 10 | R9: 10 | S9: 10 | T9: 10 | U9: 10
A10: 裏 | B10: 無 | C10: SF 白 コラボ | D10: SF白コラボ カグラナナ | O10: 80 | P10: 30 | Q10: 20 | R10: 20 | S10: 20 | T10: 20 | U10: 20 | V10: 20 | W10: 20 | X10: 20 | Y10: 20 | Z10: 20
A11: 裏 | B11: 無 | C11: SF 白 コラボ | D11: 寺田てら | P11: 60 | Q11: 30 | R11: 30 | S11: 30 | T11: 30 | U11: 20 | V11: 20 | W11: 20 | X11: 20 | Y11: 20 | Z11: 20 | AA11: 20
