Workbook

Sheet 表の見方と入力について
A5: ↓インチ+ブランド | G5: ↓当月月初の在庫（SAP貼り付けから計算） | K5: ↓各月の計画
B6: ↓購買の名称 | C6: ↓販売モデル名＝定格銘板 | D6: ↓搭載CPU | E6: 搭載GPU | F6: メモリ種別 | H6: ↓今月～翌々月（向う4か月の販売計画 在庫＜販売計画の場合赤文字）
B7: GALLERIA | C7: model名 | D7: CPU | E7: GPU | F7: メモリ | G7: 在庫残 | H7: 4か月計画 | I7: 45292 | J7: 45323 | K7: 45352 | L7: 45383 | M7: 45413 | N7: 45444 | O7: 45474 | P7: 45505 | Q7: 45536 | R7: 45566 | S7: 45597 | T7: 45627 | U7: 45658 | V7: 45689 | W7: 45717 | X7: 45748 | Y7: 45778
A8: 17"-G | B8: CLE-X370-13900HX-4090-L6 | C8: UL9C-R49 | D8: RPL-i9-13900HX | E8: 4090 | F8: DDR5 | G8: 101 | H8: 98 | I8: 48 | J8: 41 | K8: 49 | M8: 49 | N8: 49
H9: 0
A10: 16”-G | B10: ID-B 14900HX-4090-creator-L6 | C10: UL9C-R49-6 | D10: RPL-R i9-14900HX | E10: 4090 | F10: DDR5 | G10: 166 | H10: 128.46447 | M10: 41.56267 | N10: 42.967437 | O10: 43.934367 | P10: 37.162537 | Q10: 34.416967 | R10: 30.705081 | S10: 32.475825 | T10: 51.467864 | U10: 34.913113 | V10: 29.879111 | W10: 43.758397 | X10: 37.756631
B11: ID-B 14900HX-4070-L6 | C11: ZL9C-R47-6B | D11: RPL-R i9-14900HX | E11: 4070 | F11: DDR5 | G11: 300 | H11: 194.02279 | N11: 97 | O11: 97.02279 | P11: 87.43885 | Q11: 77.32581 | R11: 69.003718 | S11: 73.784727 | T11: 102.20604
B12: ID-U-155H-4070-gaming | C12: ZL7C-R47-6 | D12: MTL-UL9-185H | E12: 4070 | F12: DDR5 | G12: 0 | H12: 10 | O12: 10 | P12: 10 | Q12: 102.45938 | R12: 84.967783 | S12: 91.165387 | T12: 154.13753 | U12: 122.1959 | V12: 104.57689 | W12: 153.15439 | X12: 132.14821
B13: ID-B 14900HX-4060-L6 | C13: ZL9C-R46-6 | D13: RPL-R i9-14900HX | E13: 4060 | F13: DDR5 | G13: 200 | H13: 132.2034 | N13: 43.960924 | O13: 88.24248 | P13: 75.390089 | Q13: 66.40072 | R13: 58.892194 | S13: 63.14198 | T13: 44.960924
B14: CLE-V56-155H-4060-L6 | C14: XL7C-R46-6 | D14: MTL-UL7-155H | E14: 4060 | F14: DDR5 | H14: 0 | P14: 668.57582 | Q14: 591.17326 | R14: 526.51178 | S14: 565.46815 | T14: 966.29302 | U14: 768.08848 | V14: 657.34044 | W14: 962.68474 | X14: 830.64588
B15: UNW-6H2-13700H-4060-L6 | C15: XL7C-R46H(L6) | D15: RPL-i7-13700H | E15: 4060 | F15: DDR5 | G15: 657 | H15: 404 | I15: 95 | J15: 85 | K15: 130 | L15: 108 | M15: 128 | N15: 123 | O15: 153 | P15: 153 | Q15: 133
B16: CLE-V56-155H-4050-L6 | C16: XL7C-R45-6 | D16: MTL-UL7-155H | E16: 4050 | H16: 0 | P16: 403.14549 | Q16: 353.70396 | R16: 317.90707 | S16: 341.28089 | T16: 580.77581 | U16: 460.85309 | V16: 394.40426 | W16: 577.61085 | X16: 498.38753
B17: UNW-6H2-13700H-4050-L9 | C17: XL7C-R45H(L9) | D17: RPL-i7-13700H | E17: 4050 | G17: 17 | H17: 6 | I17: 28 | J17: 85 | K17: 74 | L17: 22 | M17: 2 | N17: 2 | O17: 2
B18: CLE-NV45-13700H-4050-L6 | C18: RM7C-R45 | D18: RPL-i7-13700H | E18: 4050 | F18: DDR5 | G18: 1 | H18: 25 | I18: 105 | J18: 105 | K18: 205 | L18: 155 | M18: 25
H19: 0
B20: GALLERIA 合計 | K20: 3046 | L20: 1820 | M20: 2143.0703 | N20: 2586.7887 | O20: 3011.9025 | P20: 3117.4016 | Q20: 2611.0739 | R20: 2239.6654 | S20: 2475.9708 | T20: 3779.2164 | U20: 2608.0095 | V20: 1559.6896 | W20: 2284.1883 | X20: 1970.8961 | Y20: 0
B21: GALLERIA 予算 | G21: 0 | H21: 0 | P21: 2919.1792 | Q21: 2806.0207 | R21: 2719.4459 | S21: 2912.4681 | T21: 4805.0359 | U21: 4440.2634
Q22: ↑台数計画合計＜予算の場合赤文字
B27: EOL製品
B28: 計画製品（未発注もしくは未確定）
B29: ブランド別の合計
B31: 変更必須（在庫不足） | C31: ←納期変更や、販売過剰などによる在庫不足（販売不可）
B32: 前回（最新日付のシート）から変更 | C32: ←ONE未反映の状態。最新シートが作成された時点で白地に変更します
B44: ■ノート担当用
B45: 販売計画の更新について
B47: 計画更新が発生したら、
B48: ツールバーから 数式→再計算実行を選択（一般 + 法人 の計算実行）
A49: 1 | B49: 一般 + 法人 = 全体 になっていることを確認
B50: ① 新規に更新されたモデルを確認
B51: ② 他 3点ほどランダムでモデルピックアップをして確認
B52: 問題ある場合、計算式を確認、またモデル追加がある場合はモデルを追加
B53: （一般、法人双方に同じモデルがないと集計されない可能性あり）
A54: 2 | B54: 在庫使用計画（ノート全体試算）をコピー、コピーしたシート名を在庫使用計画（当日日付）に変更
A55: 3 | B55: 2.でコピーしたシート全体をCtrl+A、Crtl +C で全体コピーして、数字で貼り付け
B56: （計算式を残さないで数字としてデータ化）
A57: 4 | B57: 3.でコピーした結果が、全体試算のシートと変わらないか確認
A58: 5 | B58: \\172.25.20.11\サードウェーブグループ\41上期\サードウェーブ\購買本部\【通常業務】\ONE
B59: ↑ONEファイルから、『NoteONE計画』のファイルを開く
A60: 6 | B60: 販売計画_yymmdd（一番新しい日付のもの）を全体コピーして、yymmdd（ひとつ前）のシートに貼り付け
B61: ひとつ前のシート名を更新
...

Sheet マスタ
A1: 在庫使用計画にあるか | B1: EOL連絡 | C1: ブランド | D1: 製品型番 | E1: 商品コード | F1: ベア名称 | G1: ID通称 | H1: 綽名 | I1: 画面サイズ | J1: Copilot OS | K1: CPU | L1: GPU | M1: 在庫 | N1: 在庫+注残 | O1: MP出荷 | P1: 販売開始 | Q1: 終息予定 | R1: 備考 | S1: 移動数 | T1: 完了日 | U1: 備考2 | V1: 計画 | W1: 総発注数 | X1: 販売数 | Y1: 最終入荷 | Z1: 代替製品CD | AA1: 名称 | AB1: 代替品CD 2 | AC1: 列3 | AD1: 移動累計 | AE1: リペア比率 | AF1: 販売比率 | AG1: 在庫4 | AH1: その他 | AI1: 代替提案CD | AJ1: 代替提案ベア | AK1: 対応マニュアル | AL1: 納品日 | AM1: 納品数 | AN1: AC容量 | AO1: V | AP1: A | AQ1: AC形状 | AR1: AC商品CD | AS1: ケーブル | AT1: ケーブルCD | AU1: USB-PD対応 | AV1: 備考3 | AW1: ONE計画との整合 | AX1: SAPとの整合 | AY1: TGP | AZ1: Aカバー | BA1: Aカバー7 | BB1: Bカバー | BC1: C | BD1: D | BE1: サイズ | BF1: 重量(kg) | BG1: ACアダプタ | BH1: 箱サイズ | BI1: 重量(kg)2 | BJ1: 後継・代替 | BK1: 直近30日販売台数 | BL1: 列1 | BM1: 全体 | BN1: 一般 | BO1: 法人 | BP1: 全体実績+予測 | BQ1: 計画 予測 | BR1: 在庫確認 | BS1: 部品予測
A2: {=_xlfn.XLOOKUP(マスタ_EOLリスト[製品型番],'在庫使用計画 (ノート全体試算)'!C:C,'在庫使用計画 (ノート全体試算)'!C:C)} -> 0 | B2: 4EOL(完全終息) | E2: 161647 | F2: 組TVS 8023D法(8 WXGA Z8350 4+64 3165 DC PD | M2: 0 | N2: 0 | AX2: 在庫無し | BM2: =IF(COUNTIFS('在庫使用計画 (ノート全体試算)'!C:C,マスタ_EOLリスト[[#This Row],[製品型番]])=0,"記載なし","") -> 記載なし | BN2: =IF(COUNTIFS('在庫使用計画 (一般)'!C:C,マスタ_EOLリスト[[#This Row],[製品型番]])=0,"記載なし","") -> 記載なし | BO2: =IF(COUNTIFS('在庫使用計画 (法人)'!C:C,マスタ_EOLリスト[[#This Row],[製品型番]])=0,"記載なし","") -> 記載なし | BP2: =IF(COUNTIFS('在庫使用計画 (全体実績+予測）0701'!C:C,マスタ_EOLリスト[[#This Row],[製品型番]])=0,"記載なし","") -> 記載なし | BQ2: =IF(COUNTIFS('在庫使用計画 (計画 予測)'!C:C,マスタ_EOLリスト[[#This Row],[製品型番]])=0,"記載なし","") -> 記載なし | BR2: =IF(COUNTIFS(在庫確認!B:B,マスタ_EOLリスト[[#This Row],[製品型番]])=0,"記載なし","") -> 記載なし | BS2: =COUNTIF(#REF!,マスタ_EOLリスト[[#This Row],[製品型番]]) -> #REF!
A3: 0 | B3: 4EOL(完全終息) | E3: 168654 | F3: 組TVS TVE8016E-A法(8inch WXGA N4120 8G128G 9461) | M3: 0 | N3: 0 | AX3: 在庫無し | BM3: =IF(COUNTIFS('在庫使用計画 (ノート全体試算)'!C:C,マスタ_EOLリスト[[#This Row],[製品型番]])=0,"記載なし","") -> 記載なし | BN3: =IF(COUNTIFS('在庫使用計画 (一般)'!C:C,マスタ_EOLリスト[[#This Row],[製品型番]])=0,"記載なし","") -> 記載なし | BO3: =IF(COUNTIFS('在庫使用計画 (法人)'!C:C,マスタ_EOLリスト[[#This Row],[製品型番]])=0,"記載なし","") -> 記載なし | BP3: =IF(COUNTIFS('在庫使用計画 (全体実績+予測）0701'!C:C,マスタ_EOLリスト[[#This Row],[製品型番]])=0,"記載なし","") -> 記載なし | BQ3: =IF(COUNTIFS('在庫使用計画 (計画 予測)'!C:C,マスタ_EOLリスト[[#This Row],[製品型番]])=0,"記載なし","") -> 記載なし | BR3: =IF(COUNTIFS(在庫確認!B:B,マスタ_EOLリスト[[#This Row],[製品型番]])=0,"記載なし","") -> 記載なし | BS3: =COUNTIF(#REF!,マスタ_EOLリスト[[#This Row],[製品型番]]) -> #REF!
A4: 0 | B4: 4EOL(完全終息) | E4: 174103 | F4: 組TVS 8016E-A(法R1 8 WXGA N4120 8G128G 9461 | M4: 0 | N4: 0 | AX4: 在庫無し | BM4: =IF(COUNTIFS('在庫使用計画 (ノート全体試算)'!C:C,マスタ_EOLリスト[[#This Row],[製品型番]])=0,"記載なし","") -> 記載なし | BN4: =IF(COUNTIFS('在庫使用計画 (一般)'!C:C,マスタ_EOLリスト[[#This Row],[製品型番]])=0,"記載なし","") -> 記載なし | BO4: =IF(COUNTIFS('在庫使用計画 (法人)'!C:C,マスタ_EOLリスト[[#This Row],[製品型番]])=0,"記載なし","") -> 記載なし | BP4: =IF(COUNTIFS('在庫使用計画 (全体実績+予測）0701'!C:C,マスタ_EOLリスト[[#This Row],[製品型番]])=0,"記載なし","") -> 記載なし | BQ4: =IF(COUNTIFS('在庫使用計画 (計画 予測)'!C:C,マスタ_EOLリスト[[#This Row],[製品型番]])=0,"記載なし","") -> 記載なし | BR4: =IF(COUNTIFS(在庫確認!B:B,マスタ_EOLリスト[[#This Row],[製品型番]])=0,"記載なし","") -> 記載なし | BS4: =COUNTIF(#REF!,マスタ_EOLリスト[[#This Row],[製品型番]]) -> #REF!
A5: UL9C-R59-8A | B5: 2発売中 | C5: 1GALLERIA-G | D5: UL9C-R59-8A | E5: 212347 | F5: 組CLE X58WNT-G(GG 18QHD+ 275HX 5090 330W L6) | G5: X58 | H5: CLE-X58-275HX-5090-L6 | I5: 18 | K5: u9-275HX | L5: 5090 | M5: 66 | N5: 66 | O5: 45717 | P5: 45747 | Q5: 2026年4月頃 | V5: 600 | W5: 476 | AN5: 330W | AO5: 20 | AP5: 16.5 | AQ5: 5525+ | AU5: 100W | AV5: 100W以上 | AW5: TRUE | AX5: 組CLE X58WNT-G(GG 18QHD+ 275HX 5090 330W | AY5: 175 | BA5: S60 鐵灰 | BB5: S60 鐵灰 | BC5: S60 鐵灰 | BD5: S60 鐵灰 | BJ5: NMC9L-R59-G8 | BM5: =IF(COUNTIFS('在庫使用計画 (ノート全体試算)'!C:C,マスタ_EOLリスト[[#This Row],[製品型番]])=0,"記載なし","") | BN5: =IF(COUNTIFS('在庫使用計画 (一般)'!C:C,マスタ_EOLリスト[[#This Row],[製品型番]])=0,"記載なし","") | BO5: =IF(COUNTIFS('在庫使用計画 (法人)'!C:C,マスタ_EOLリスト[[#This Row],[製品型番]])=0,"記載なし","") | BP5: =IF(COUNTIFS('在庫使用計画 (全体実績+予測）0701'!C:C,マスタ_EOLリスト[[#This Row],[製品型番]])=0,"記載なし","") | BQ5: =IF(COUNTIFS('在庫使用計画 (計画 予測)'!C:C,マスタ_EOLリスト[[#This Row],[製品型番]])=0,"記載なし","") | BR5: =IF(COUNTIFS(在庫確認!B:B,マスタ_EOLリスト[[#This Row],[製品型番]])=0,"記載なし","") | BS5: =COUNTIF(#REF!,マスタ_EOLリスト[[#This Row],[製品型番]]) -> #REF!
A6: UL9C-R49-6 | B6: 4EOL(完全終息) | C6: 1GALLERIA-G | D6: UL9C-R49-6 | E6: 193182 | F6: 組UNW GM6IX9B(GG 16WQXGA 14900HX 4090 280W L6) | G6: ID-B | H6: ID-B 14900HX-4090-gaming-L6 | K6: i9-14900HX | L6: 4090 | M6: 0 | N6: 0 | O6: 45414 | P6: 45414 | Q6: 終息 | U6: Copilot keyモデルにスライド | V6: 150 | W6: 216 | Z6: 199017 | AB6: 212347 | AC6: 5090 価格差あり | AK6: 194883 | AL6: 45481 | AM6: 35 | AN6: 280W | AX6: 在庫無し | BA6: Light Gray | BB6: Black | BC6: Light Gray | BD6: Light Gray | BM6: =IF(COUNTIFS('在庫使用計画 (ノート全体試算)'!C:C,マスタ_EOLリスト[[#This Row],[製品型番]])=0,"記載なし","") | BN6: =IF(COUNTIFS('在庫使用計画 (一般)'!C:C,マスタ_EOLリスト[[#This Row],[製品型番]])=0,"記載なし","") | BO6: =IF(COUNTIFS('在庫使用計画 (法人)'!C:C,マスタ_EOLリスト[[#This Row],[製品型番]])=0,"記載なし","") | BP6: =IF(COUNTIFS('在庫使用計画 (全体実績+予測）0701'!C:C,マスタ_EOLリスト[[#This Row],[製品型番]])=0,"記載なし","") | BQ6: =IF(COUNTIFS('在庫使用計画 (計画 予測)'!C:C,マスタ_EOLリスト[[#This Row],[製品型番]])=0,"記載なし","") -> 記載なし | BR6: =IF(COUNTIFS(在庫確認!B:B,マスタ_EOLリスト[[#This Row],[製品型番]])=0,"記載なし","") | BS6: =COUNTIF(#REF!,マスタ_EOLリスト[[#This Row],[製品型番]]) -> #REF!
A7: UL9C-R49-6 | B7: 4EOL(完全終息) | C7: 1GALLERIA-G | D7: UL9C-R49-6 | E7: 199017 | F7: 組UNW GM6IX9B(R1 GG 16WQXGA 14900HX 4090 280W L6) | G7: ID-B | H7: ID-B 14900HX-4090-gaming-L6 | K7: i9-14900HX | L7: 4090 | M7: 0 | N7: 0 | Q7: 2025年3月頃 | R7: Copilot key対応版 | W7: 235 | AB7: 212347 | AC7: 5090 価格差あり | AK7: 207653 | AL7: 45483 | AM7: 125 | AN7: 280W | AX7: 在庫無し | BA7: Aurora Black | BB7: Black | BC7: Aurora Black | BD7: Black | BM7: =IF(COUNTIFS('在庫使用計画 (ノート全体試算)'!C:C,マスタ_EOLリスト[[#This Row],[製品型番]])=0,"記載なし","") | BN7: =IF(COUNTIFS('在庫使用計画 (一般)'!C:C,マスタ_EOLリスト[[#This Row],[製品型番]])=0,"記載なし","") | BO7: =IF(COUNTIFS('在庫使用計画 (法人)'!C:C,マスタ_EOLリスト[[#This Row],[製品型番]])=0,"記載なし","") | BP7: =IF(COUNTIFS('在庫使用計画 (全体実績+予測）0701'!C:C,マスタ_EOLリスト[[#This Row],[製品型番]])=0,"記載なし","") | BQ7: =IF(COUNTIFS('在庫使用計画 (計画 予測)'!C:C,マスタ_EOLリスト[[#This Row],[製品型番]])=0,"記載なし","") -> 記載なし | BR7: =IF(COUNTIFS(在庫確認!B:B,マスタ_EOLリスト[[#This Row],[製品型番]])=0,"記載なし","") | BS7: =COUNTIF(#REF!,マスタ_EOLリスト[[#This Row],[製品型番]]) -> #REF!
A8: UL9C-R49 | B8: 4EOL(完全終息) | C8: 1GALLERIA-G | D8: UL9C-R49 | E8: 184056 | F8: 組CLE X370SNW-G(17.3QHD 13900HX 4090 330W L6) | G8: X370 | H8: CLE-X370-13900HX-4090-L6 | K8: i9-13900HX | L8: 4090 | M8: 0 | N8: 0 | P8: 45197 | Q8: 2024年5月頃 | R8: 代替候補はID別 | V8: 300 | W8: 400 | Z8: 193182 | AC8: 2024/6頃 RPL-Rに変更 | AH8: 後継IDは変更 →ID-B | AI8: 193182 | AJ8: 組UNW GM6IX9B(GG 16WQXGA 14900HX 4090 280W L6) | AL8: 45471 | AM8: 80 | AQ8: 特殊 | AX8: 在庫無し | BM8: =IF(COUNTIFS('在庫使用計画 (ノート全体試算)'!C:C,マスタ_EOLリスト[[#This Row],[製品型番]])=0,"記載なし","") | BN8: =IF(COUNTIFS('在庫使用計画 (一般)'!C:C,マスタ_EOLリスト[[#This Row],[製品型番]])=0,"記載なし","") -> 記載なし | BO8: =IF(COUNTIFS('在庫使用計画 (法人)'!C:C,マスタ_EOLリスト[[#This Row],[製品型番]])=0,"記載なし","") | BP8: =IF(COUNTIFS('在庫使用計画 (全体実績+予測）0701'!C:C,マスタ_EOLリスト[[#This Row],[製品型番]])=0,"記載なし","") | BQ8: =IF(COUNTIFS('在庫使用計画 (計画 予測)'!C:C,マスタ_EOLリスト[[#This Row],[製品型番]])=0,"記載なし","") -> 記載なし | BR8: =IF(COUNTIFS(在庫確認!B:B,マスタ_EOLリスト[[#This Row],[製品型番]])=0,"記載なし","") | BS8: =COUNTIF(#REF!,マスタ_EOLリスト[[#This Row],[製品型番]]) -> #REF!
A9: NMC9L-R59-G8 | B9: 2発売中 | C9: 1GALLERIA-G | D9: NMC9L-R59-G8 | E9: 318440 | F9: 組CLE X58WNT-G(GG 18QHD+290HXP5090 330W L6) | G9: X58 | H9: CLE-X58-290HXP-5090-L6-GG | I9: 18 | K9: u9-290HX Plus | L9: 5090 | M9: 107 | N9: 107 | AW9: TRUE | AX9: 組CLE X58WNT-G(GG 18QHD+290HXP5090 330W L | BJ9: x | BM9: =IF(COUNTIFS('在庫使用計画 (ノート全体試算)'!C:C,マスタ_EOLリスト[[#This Row],[製品型番]])=0,"記載なし","") | BN9: =IF(COUNTIFS('在庫使用計画 (一般)'!C:C,マスタ_EOLリスト[[#This Row],[製品型番]])=0,"記載なし","") | BO9: =IF(COUNTIFS('在庫使用計画 (法人)'!C:C,マスタ_EOLリスト[[#This Row],[製品型番]])=0,"記載なし","") | BP9: =IF(COUNTIFS('在庫使用計画 (全体実績+予測）0701'!C:C,マスタ_EOLリスト[[#This Row],[製品型番]])=0,"記載なし","") | BQ9: =IF(COUNTIFS('在庫使用計画 (計画 予測)'!C:C,マスタ_EOLリスト[[#This Row],[製品型番]])=0,"記載なし","") | BR9: =IF(COUNTIFS(在庫確認!B:B,マスタ_EOLリスト[[#This Row],[製品型番]])=0,"記載なし","") -> 記載なし | BS9: =COUNTIF(#REF!,マスタ_EOLリスト[[#This Row],[製品型番]]) -> #REF!
A10: NMC9L-R59-G8 | B10: 2発売中 | C10: 1GALLERIA-G | D10: NMC9L-R59-G8 | E10: 366294 | F10: 組CLE X58WNT-G(R1GG 18QHD+290HXP5090 330WL6) | G10: X58 | H10: CLE-X58-290HXP-5090-L6-GG | I10: 18 | K10: u9-290HX Plus | L10: 5090 | M10: 0 | N10: 30 | AW10: TRUE | AX10: 在庫無し | BJ10: x | BM10: =IF(COUNTIFS('在庫使用計画 (ノート全体試算)'!C:C,マスタ_EOLリスト[[#This Row],[製品型番]])=0,"記載なし","") | BN10: =IF(COUNTIFS('在庫使用計画 (一般)'!C:C,マスタ_EOLリスト[[#This Row],[製品型番]])=0,"記載なし","") | BO10: =IF(COUNTIFS('在庫使用計画 (法人)'!C:C,マスタ_EOLリスト[[#This Row],[製品型番]])=0,"記載なし","") | BP10: =IF(COUNTIFS('在庫使用計画 (全体実績+予測）0701'!C:C,マスタ_EOLリスト[[#This Row],[製品型番]])=0,"記載なし","") | BQ10: =IF(COUNTIFS('在庫使用計画 (計画 予測)'!C:C,マスタ_EOLリスト[[#This Row],[製品型番]])=0,"記載なし","") | BR10: =IF(COUNTIFS(在庫確認!B:B,マスタ_EOLリスト[[#This Row],[製品型番]])=0,"記載なし","") -> 記載なし | BS10: =COUNTIF(#REF!,マスタ_EOLリスト[[#This Row],[製品型番]]) -> #REF!
A11: NMC9L-R58-H6 | B11: 2発売中 | C11: 1GALLERIA-G | D11: NMC9L-R58-H6 | E11: 326941 | F11: 組UNW X6AF558Y(GC 16WQXGA 290HXP 5080 330W L6) | G11: ID-Y | H11: UNW-Y-290HXP-5080-L6-GC | I11: 16 | K11: u9-290HX Plus | L11: 5080 | M11: 269 | N11: 341 | AW11: TRUE | AX11: 組UNW X6AF558Y(GC 16WQXGA 290HXP 5080 330 | BM11: =IF(COUNTIFS('在庫使用計画 (ノート全体試算)'!C:C,マスタ_EOLリスト[[#This Row],[製品型番]])=0,"記載なし","") | BN11: =IF(COUNTIFS('在庫使用計画 (一般)'!C:C,マスタ_EOLリスト[[#This Row],[製品型番]])=0,"記載なし","") | BO11: =IF(COUNTIFS('在庫使用計画 (法人)'!C:C,マスタ_EOLリスト[[#This Row],[製品型番]])=0,"記載なし","") | BP11: =IF(COUNTIFS('在庫使用計画 (全体実績+予測）0701'!C:C,マスタ_EOLリスト[[#This Row],[製品型番]])=0,"記載なし","") | BQ11: =IF(COUNTIFS('在庫使用計画 (計画 予測)'!C:C,マスタ_EOLリスト[[#This Row],[製品型番]])=0,"記載なし","") | BR11: =IF(COUNTIFS(在庫確認!B:B,マスタ_EOLリスト[[#This Row],[製品型番]])=0,"記載なし","") -> 記載なし | BS11: =COUNTIF(#REF!,マスタ_EOLリスト[[#This Row],[製品型番]]) -> #REF!
A12: ZL9R-R57T-6 | B12: 3EOL(在庫あり) | C12: 1GALLERIA-G | D12: ZL9R-R57T-6 | E12: 212476 | F12: 組UNW X6FR57TK(GG 16WQXGA 9955HX 5070Ti 240W L6) | G12: ID-K | H12: UNW-K-9955HX-5070Ti-L6 | I12: 16 | K12: R9-9955X | L12: 5070Ti | M12: 11 | N12: 11 | O12: 45717 | P12: 45793 | Q12: 2026年4月頃 | R12: 在庫+注残限り | V12: 240 | W12: 1306 | AN12: 240W | AO12: 20 | AP12: 12 | AQ12: 5525+ | AR12: 199685 | AS12: C5-C6 | AT12: 171480 | AU12: 100W/140W | AV12: 140W未検証 | AW12: TRUE | AX12: 組UNW X6FR57TK(GG 16WQXGA 9955HX 5070Ti 2 | AY12: 115 | BA12: Ink Stone Black | BB12: Ink Stone Black | BC12: Ink Stone Black | BD12: Ink Stone Black | BJ12: ZL9C-R57T-6A | BM12: =IF(COUNTIFS('在庫使用計画 (ノート全体試算)'!C:C,マスタ_EOLリスト[[#This Row],[製品型番]])=0,"記載なし","") | BN12: =IF(COUNTIFS('在庫使用計画 (一般)'!C:C,マスタ_EOLリスト[[#This Row],[製品型番]])=0,"記載なし","") | BO12: =IF(COUNTIFS('在庫使用計画 (法人)'!C:C,マスタ_EOLリスト[[#This Row],[製品型番]])=0,"記載なし","") | BP12: =IF(COUNTIFS('在庫使用計画 (全体実績+予測）0701'!C:C,マスタ_EOLリスト[[#This Row],[製品型番]])=0,"記載なし","") | BQ12: =IF(COUNTIFS('在庫使用計画 (計画 予測)'!C:C,マスタ_EOLリスト[[#This Row],[製品型番]])=0,"記載なし","") | BR12: =IF(COUNTIFS(在庫確認!B:B,マスタ_EOLリスト[[#This Row],[製品型番]])=0,"記載なし","") | BS12: =COUNTIF(#REF!,マスタ_EOLリスト[[#This Row],[製品型番]]) -> #REF!
A13: ZL9C-R57T-6A | B13: 2発売中 | C13: 1GALLERIA-G | D13: ZL9C-R57T-6A | E13: 220801 | F13: 組UNW X6AR57TK(GG 16WQXGA 275HX 5070Ti 240W L6) | G13: ID-K | H13: UNW-K-275HX-5070Ti-L6 | I13: 16 | K13: u9-275HX | L13: 5070Ti | M13: 74 | N13: 74 | O13: 45848 | P13: 45876 | Q13: 2026年4月頃 | R13: 在庫+注残限り | V13: 580 | W13: 696 | AN13: 240W | AO13: 20 | AP13: 12 | AQ13: 5525+ | AR13: 199685 | AS13: C5-C6 | AT13: 171480 | AU13: 100W/140W | AV13: 140W未検証 | AW13: TRUE | AX13: 組UNW X6AR57TK(GG 16WQXGA 275HX 5070Ti 24 | AY13: 115 | BA13: Light Gray | BB13: Black | BC13: Light Gray | BD13: Light Gray | BJ13: x | BM13: =IF(COUNTIFS('在庫使用計画 (ノート全体試算)'!C:C,マスタ_EOLリスト[[#This Row],[製品型番]])=0,"記載なし","") | BN13: =IF(COUNTIFS('在庫使用計画 (一般)'!C:C,マスタ_EOLリスト[[#This Row],[製品型番]])=0,"記載なし","") | BO13: =IF(COUNTIFS('在庫使用計画 (法人)'!C:C,マスタ_EOLリスト[[#This Row],[製品型番]])=0,"記載なし","") | BP13: =IF(COUNTIFS('在庫使用計画 (全体実績+予測）0701'!C:C,マスタ_EOLリスト[[#This Row],[製品型番]])=0,"記載なし","") | BQ13: =IF(COUNTIFS('在庫使用計画 (計画 予測)'!C:C,マスタ_EOLリスト[[#This Row],[製品型番]])=0,"記載なし","") | BR13: =IF(COUNTIFS(在庫確認!B:B,マスタ_EOLリスト[[#This Row],[製品型番]])=0,"記載なし","") | BS13: =COUNTIF(#REF!,マスタ_EOLリスト[[#This Row],[製品型番]]) -> #REF!
A14: ZL9C-R57T-6A | B14: 2発売中 | C14: 1GALLERIA-G | D14: ZL9C-R57T-6A | E14: 349140 | F14: 組UNW X6AR57TK(R1 GG 16WQXGA 275HX 5070Ti 240W L6) | G14: ID-K | H14: UNW-K-275HX-5070Ti-L6 | I14: 16 | K14: u9-275HX | L14: 5070Ti | M14: 119 | N14: 479 | O14: 45848 | P14: 45876 | Q14: 2026年4月頃 | R14: 在庫+注残限り。箱変更 | V14: 580 | W14: 0 | AN14: 240W | AO14: 20 | AP14: 12 | AQ14: 5525+ | AR14: 199685 | AS14: C5-C6 | AT14: 171480 | AU14: 100W/140W | AV14: 140W未検証 | AW14: TRUE | AX14: 組UNW X6AR57TK(R1 GG 16WQXGA 275HX 5070Ti | AY14: 115 | BA14: Light Gray | BB14: Black | BC14: Light Gray | BD14: Light Gray | BJ14: x | BM14: =IF(COUNTIFS('在庫使用計画 (ノート全体試算)'!C:C,マスタ_EOLリスト[[#This Row],[製品型番]])=0,"記載なし","") | BN14: =IF(COUNTIFS('在庫使用計画 (一般)'!C:C,マスタ_EOLリスト[[#This Row],[製品型番]])=0,"記載なし","") | BO14: =IF(COUNTIFS('在庫使用計画 (法人)'!C:C,マスタ_EOLリスト[[#This Row],[製品型番]])=0,"記載なし","") | BP14: =IF(COUNTIFS('在庫使用計画 (全体実績+予測）0701'!C:C,マスタ_EOLリスト[[#This Row],[製品型番]])=0,"記載なし","") | BQ14: =IF(COUNTIFS('在庫使用計画 (計画 予測)'!C:C,マスタ_EOLリスト[[#This Row],[製品型番]])=0,"記載なし","") | BR14: =IF(COUNTIFS(在庫確認!B:B,マスタ_EOLリスト[[#This Row],[製品型番]])=0,"記載なし","") | BS14: =COUNTIF(#REF!,マスタ_EOLリスト[[#This Row],[製品型番]]) -> #REF!
A15: ZL7C-R57-6A | B15: 2発売中 | C15: 1GALLERIA-G | D15: ZL7C-R57-6A | E15: 220803 | F15: 組UNW X6AR557K(GG 16WQXGA 255HX 5070 240W L6) | G15: ID-K | H15: UNW-K-255HX-5070-L6 | I15: 16 | K15: u7-255HX | L15: 5070 | M15: 128 | N15: 128 | O15: 45856 | P15: 45876 | Q15: 2026年4月頃 | R15: 在庫+注残限り | V15: 1180 | W15: 926 | AN15: 240W | AO15: 20 | AP15: 12 | AQ15: 5525+ | AR15: 199685 | AS15: C5-C6 | AT15: 171480 | AU15: 100W/140W | AV15: 140W未検証 | AW15: TRUE | AX15: 組UNW X6AR557K(GG 16WQXGA 255HX 5070 240W | AY15: 115 | BA15: Light Gray | BB15: Black | BC15: Light Gray | BD15: Light Gray | BJ15: ID-7? | BM15: =IF(COUNTIFS('在庫使用計画 (ノート全体試算)'!C:C,マスタ_EOLリスト[[#This Row],[製品型番]])=0,"記載なし","") | BN15: =IF(COUNTIFS('在庫使用計画 (一般)'!C:C,マスタ_EOLリスト[[#This Row],[製品型番]])=0,"記載なし","") | BO15: =IF(COUNTIFS('在庫使用計画 (法人)'!C:C,マスタ_EOLリスト[[#This Row],[製品型番]])=0,"記載なし","") | BP15: =IF(COUNTIFS('在庫使用計画 (全体実績+予測）0701'!C:C,マスタ_EOLリスト[[#This Row],[製品型番]])=0,"記載なし","") | BQ15: =IF(COUNTIFS('在庫使用計画 (計画 予測)'!C:C,マスタ_EOLリスト[[#This Row],[製品型番]])=0,"記載なし","") | BR15: =IF(COUNTIFS(在庫確認!B:B,マスタ_EOLリスト[[#This Row],[製品型番]])=0,"記載なし","") | BS15: =COUNTIF(#REF!,マスタ_EOLリスト[[#This Row],[製品型番]]) -> #REF!
A16: ZL7C-R57-6A | B16: 2発売中 | C16: 1GALLERIA-G | D16: ZL7C-R57-6A | E16: 366295 | F16: 組UNW X6AR557K(R1GG 16WQXGA 255HX 5070 240W L6) | G16: ID-K | H16: UNW-K-255HX-5070-L6 | I16: 16 | K16: u7-255HX | L16: 5070 | M16: 0 | N16: 140 | O16: 45856 | P16: 45876 | Q16: 2026年4月頃 | R16: 在庫+注残限り | V16: 1180 | W16: 0 | AN16: 240W | AO16: 20 | AP16: 12 | AQ16: 5525+ | AR16: 199685 | AS16: C5-C6 | AT16: 171480 | AU16: 100W/140W | AV16: 140W未検証 | AW16: TRUE | AX16: 在庫無し | AY16: 115 | BA16: Light Gray | BB16: Black | BC16: Light Gray | BD16: Light Gray | BJ16: ID-7? | BM16: =IF(COUNTIFS('在庫使用計画 (ノート全体試算)'!C:C,マスタ_EOLリスト[[#This Row],[製品型番]])=0,"記載なし","") | BN16: =IF(COUNTIFS('在庫使用計画 (一般)'!C:C,マスタ_EOLリスト[[#This Row],[製品型番]])=0,"記載なし","") | BO16: =IF(COUNTIFS('在庫使用計画 (法人)'!C:C,マスタ_EOLリスト[[#This Row],[製品型番]])=0,"記載なし","") | BP16: =IF(COUNTIFS('在庫使用計画 (全体実績+予測）0701'!C:C,マスタ_EOLリスト[[#This Row],[製品型番]])=0,"記載なし","") | BQ16: =IF(COUNTIFS('在庫使用計画 (計画 予測)'!C:C,マスタ_EOLリスト[[#This Row],[製品型番]])=0,"記載なし","") | BR16: =IF(COUNTIFS(在庫確認!B:B,マスタ_EOLリスト[[#This Row],[製品型番]])=0,"記載なし","") | BS16: =COUNTIF(#REF!,マスタ_EOLリスト[[#This Row],[製品型番]]) -> #REF!
A17: ZL9C-R47-6B | B17: 4EOL(完全終息) | C17: 1GALLERIA-G | D17: ZL9C-R47-6B | E17: 196068 | F17: 組UNW_GM6IX7B(GG 16WQXGA 14900HX 4070 240W L6) | G17: ID-B | H17: ID-B 14900HX-4070-L6 | K17: i9-14900HX | L17: 4070 | M17: 0 | N17: 0 | O17: 45423 | P17: 45449 | U17: Copilot keyモデルにスライド | V17: 500 | W17: 400 | Z17: 199019 | AK17: 199325 | AL17: 45525 | AM17: 70 | AN17: 240W | AX17: 在庫無し | BA17: Thunder Black | BB17: Black | BC17: Thunder Black | BD17: Stellar Black | BM17: =IF(COUNTIFS('在庫使用計画 (ノート全体試算)'!C:C,マスタ_EOLリスト[[#This Row],[製品型番]])=0,"記載なし","") | BN17: =IF(COUNTIFS('在庫使用計画 (一般)'!C:C,マスタ_EOLリスト[[#This Row],[製品型番]])=0,"記載なし","") | BO17: =IF(COUNTIFS('在庫使用計画 (法人)'!C:C,マスタ_EOLリスト[[#This Row],[製品型番]])=0,"記載なし","") | BP17: =IF(COUNTIFS('在庫使用計画 (全体実績+予測）0701'!C:C,マスタ_EOLリスト[[#This Row],[製品型番]])=0,"記載なし","") | BQ17: =IF(COUNTIFS('在庫使用計画 (計画 予測)'!C:C,マスタ_EOLリスト[[#This Row],[製品型番]])=0,"記載なし","") -> 記載なし | BR17: =IF(COUNTIFS(在庫確認!B:B,マスタ_EOLリスト[[#This Row],[製品型番]])=0,"記載なし","") | BS17: =COUNTIF(#REF!,マスタ_EOLリスト[[#This Row],[製品型番]]) -> #REF!
A18: ZL9C-R47-6B | B18: 4EOL(完全終息) | C18: 1GALLERIA-G | D18: ZL9C-R47-6B | E18: 199019 | F18: 組UNW GM6IX7B(R1 GG 16WQXGA 14900HX 4070 240W L6) | G18: ID-B | H18: ID-B 14900HX-4070-L6 | K18: i9-14900HX | L18: 4070 | M18: 0 | N18: 0 | Q18: 2025年3月頃 | R18: Copilot key対応版 | W18: 890 | Z18: 212476,212347 | AB18: 212476 | AK18: 207654 | AL18: 45483 | AM18: 125 | AN18: 240W | AX18: 在庫無し | BA18: S17S 暮石灰 | BB18: S72 暮石灰 | BC18: S72 暮石灰 | BD18: S72 暮石灰 | BM18: =IF(COUNTIFS('在庫使用計画 (ノート全体試算)'!C:C,マスタ_EOLリスト[[#This Row],[製品型番]])=0,"記載なし","") | BN18: =IF(COUNTIFS('在庫使用計画 (一般)'!C:C,マスタ_EOLリスト[[#This Row],[製品型番]])=0,"記載なし","") | BO18: =IF(COUNTIFS('在庫使用計画 (法人)'!C:C,マスタ_EOLリスト[[#This Row],[製品型番]])=0,"記載なし","") | BP18: =IF(COUNTIFS('在庫使用計画 (全体実績+予測）0701'!C:C,マスタ_EOLリスト[[#This Row],[製品型番]])=0,"記載なし","") | BQ18: =IF(COUNTIFS('在庫使用計画 (計画 予測)'!C:C,マスタ_EOLリスト[[#This Row],[製品型番]])=0,"記載なし","") -> 記載なし | BR18: =IF(COUNTIFS(在庫確認!B:B,マスタ_EOLリスト[[#This Row],[製品型番]])=0,"記載なし","") | BS18: =COUNTIF(#REF!,マスタ_EOLリスト[[#This Row],[製品型番]]) -> #REF!
A19: ZL9C-R46-6 | B19: 4EOL(完全終息) | C19: 1GALLERIA-G | D19: ZL9C-R46-6 | E19: 196066 | F19: 組UNW GM6IX0B(16WQXGA 14900HX 4060 240W L6) | G19: ID-B | H19: ID-B 14900HX-4060-L6 | K19: i9-14900HX | L19: 4060 | M19: 0 | N19: 0 | P19: 45449 | U19: 在庫限りで終息予定 | V19: 500 | W19: 380 | Z19: 199020 | AC19: ZL9C-R47-6B | AL19: 45481 | AM19: 10 | AX19: 在庫無し | BA19: B11S 瀾夜黑 | BB19: B77 瀾夜黑 | BC19: B77 瀾夜黑 | BD19: B77 瀾夜黑 | BM19: =IF(COUNTIFS('在庫使用計画 (ノート全体試算)'!C:C,マスタ_EOLリスト[[#This Row],[製品型番]])=0,"記載なし","") | BN19: =IF(COUNTIFS('在庫使用計画 (一般)'!C:C,マスタ_EOLリスト[[#This Row],[製品型番]])=0,"記載なし","") | BO19: =IF(COUNTIFS('在庫使用計画 (法人)'!C:C,マスタ_EOLリスト[[#This Row],[製品型番]])=0,"記載なし","") | BP19: =IF(COUNTIFS('在庫使用計画 (全体実績+予測）0701'!C:C,マスタ_EOLリスト[[#This Row],[製品型番]])=0,"記載なし","") | BQ19: =IF(COUNTIFS('在庫使用計画 (計画 予測)'!C:C,マスタ_EOLリスト[[#This Row],[製品型番]])=0,"記載なし","") -> 記載なし | BR19: =IF(COUNTIFS(在庫確認!B:B,マスタ_EOLリスト[[#This Row],[製品型番]])=0,"記載なし","") | BS19: =COUNTIF(#REF!,マスタ_EOLリスト[[#This Row],[製品型番]]) -> #REF!
A20: ZL9C-R46-6 | B20: 4EOL(完全終息) | C20: 1GALLERIA-G | D20: ZL9C-R46-6 | E20: 199020 | F20: 組UNW GM6IX0B(R1 GG 16WQXGA 14900HX 4060 240W L6) | G20: ID-B | H20: ID-B 14900HX-4060-L6 | K20: i9-14900HX | L20: 4060 | M20: 0 | N20: 0 | R20: Copilot key対応版 | W20: 0 | Z20: なし | AL20: 45483 | AM20: 125 | AX20: 在庫無し | BA20: B11S 瀾夜黑 | BB20: B77 瀾夜黑 | BC20: B77 瀾夜黑 | BD20: B77 瀾夜黑 | BM20: =IF(COUNTIFS('在庫使用計画 (ノート全体試算)'!C:C,マスタ_EOLリスト[[#This Row],[製品型番]])=0,"記載なし","") | BN20: =IF(COUNTIFS('在庫使用計画 (一般)'!C:C,マスタ_EOLリスト[[#This Row],[製品型番]])=0,"記載なし","") | BO20: =IF(COUNTIFS('在庫使用計画 (法人)'!C:C,マスタ_EOLリスト[[#This Row],[製品型番]])=0,"記載なし","") | BP20: =IF(COUNTIFS('在庫使用計画 (全体実績+予測）0701'!C:C,マスタ_EOLリスト[[#This Row],[製品型番]])=0,"記載なし","") | BQ20: =IF(COUNTIFS('在庫使用計画 (計画 予測)'!C:C,マスタ_EOLリスト[[#This Row],[製品型番]])=0,"記載なし","") -> 記載なし | BR20: =IF(COUNTIFS(在庫確認!B:B,マスタ_EOLリスト[[#This Row],[製品型番]])=0,"記載なし","") | BS20: =COUNTIF(#REF!,マスタ_EOLリスト[[#This Row],[製品型番]]) -> #REF!
A21: ZL7C-R47 | B21: 4EOL(完全終息) | C21: 1GALLERIA-G | D21: ZL7C-R47 | E21: 184057 | F21: 組CLE PD51SNE-GTD(15.6FHD 13700HX 4070 280W L6) | G21: PD51 | H21: CLE-PD51-13700HX-4070-L6 | K21: i7-13700HX | L21: 4070 | M21: 0 | N21: 0 | P21: 45197 | Q21: 2024年6月頃 | R21: 代替候補はID別 | V21: 1200 | W21: 1250 | Z21: 196068 | AC21: ラインとしての後継 | AH21: 後継IDは変更 | AI21: 196068 | AJ21: 組UNW_GM6IX7B(GG 16WQXGA 14900HX 4070 240W L6) | AL21: 45413 | AM21: 40 | AX21: 在庫無し | BA21: Light Gray | BB21: Black | BC21: Light Gray | BD21: Light Gray | BM21: =IF(COUNTIFS('在庫使用計画 (ノート全体試算)'!C:C,マスタ_EOLリスト[[#This Row],[製品型番]])=0,"記載なし","") | BN21: =IF(COUNTIFS('在庫使用計画 (一般)'!C:C,マスタ_EOLリスト[[#This Row],[製品型番]])=0,"記載なし","") -> 記載なし | BO21: =IF(COUNTIFS('在庫使用計画 (法人)'!C:C,マスタ_EOLリスト[[#This Row],[製品型番]])=0,"記載なし","") | BP21: =IF(COUNTIFS('在庫使用計画 (全体実績+予測）0701'!C:C,マスタ_EOLリスト[[#This Row],[製品型番]])=0,"記載なし","") | BQ21: =IF(COUNTIFS('在庫使用計画 (計画 予測)'!C:C,マスタ_EOLリスト[[#This Row],[製品型番]])=0,"記載なし","") -> 記載なし | BR21: =IF(COUNTIFS(在庫確認!B:B,マスタ_EOLリスト[[#This Row],[製品型番]])=0,"記載なし","") | BS21: =COUNTIF(#REF!,マスタ_EOLリスト[[#This Row],[製品型番]]) -> #REF!
A22: XL7R-R56-6A | B22: 4EOL(完全終息) | C22: 1GALLERIA-G | D22: XL7R-R56-6A | E22: 212469 | F22: 組CLE V561KNN-TD(GG 16QHD+ 350 5060 180W L6) | G22: V56 | H22: CLE-V56-350-5060-L6 | I22: 16 | J22: 必須 | K22: R AI 7 350 | L22: 5060 | M22: 0 | N22: 0 | O22: 2025年4月末 | P22: 45793 | Q22: 2026年4月頃 | V22: 1050 | W22: 506 | Z22: 251110 | AN22: 180W | AO22: 20 | AP22: 9 | AQ22: 5525+ | AR22: 188009 | AS22: C5-C6 | AT22: 188010 | AU22: 45-100W | AX22: 在庫無し | AY22: 115 | BA22: S60 鐵灰 | BB22: S60 鐵灰 | BC22: S60 鐵灰 | BD22: S60 鐵灰 | BJ22: x | BM22: =IF(COUNTIFS('在庫使用計画 (ノート全体試算)'!C:C,マスタ_EOLリスト[[#This Row],[製品型番]])=0,"記載なし","") | BN22: =IF(COUNTIFS('在庫使用計画 (一般)'!C:C,マスタ_EOLリスト[[#This Row],[製品型番]])=0,"記載なし","") | BO22: =IF(COUNTIFS('在庫使用計画 (法人)'!C:C,マスタ_EOLリスト[[#This Row],[製品型番]])=0,"記載なし","") | BP22: =IF(COUNTIFS('在庫使用計画 (全体実績+予測）0701'!C:C,マスタ_EOLリスト[[#This Row],[製品型番]])=0,"記載なし","") | BQ22: =IF(COUNTIFS('在庫使用計画 (計画 予測)'!C:C,マスタ_EOLリスト[[#This Row],[製品型番]])=0,"記載なし","") | BR22: =IF(COUNTIFS(在庫確認!B:B,マスタ_EOLリスト[[#This Row],[製品型番]])=0,"記載なし","") | BS22: =COUNTIF(#REF!,マスタ_EOLリスト[[#This Row],[製品型番]]) -> #REF!
A23: XL7R-R56-6A | B23: 4EOL(完全終息) | C23: 1GALLERIA-G | D23: XL7R-R56-6A | E23: 251110 | F23: 組CLE V561KNN-TD(R1 GG 16QHD+300Hz 350 5060 180WL6 | G23: V56 | H23: CLE-V56-350-5060-L6 | I23: 16 | J23: 必須 | K23: R AI 7 350 | L23: 5060 | M23: 0 | N23: 0 | P23: 45793 | Q23: 2026年4月頃 | R23: 液晶変更版 2nd sorce | W23: 384 | AB23: 295634 | AN23: 180W | AO23: 20 | AP23: 9 | AQ23: 5525+ | AR23: 188009 | AS23: C5-C6 | AT23: 188010 | AU23: 45-100W | AX23: 在庫無し | AY23: 115 | BA23: Light Gray | BB23: Black | BC23: Light Gray | BD23: Light Gray | BJ23: NDC7L-R57-G6 | BM23: =IF(COUNTIFS('在庫使用計画 (ノート全体試算)'!C:C,マスタ_EOLリスト[[#This Row],[製品型番]])=0,"記載なし","") | BN23: =IF(COUNTIFS('在庫使用計画 (一般)'!C:C,マスタ_EOLリスト[[#This Row],[製品型番]])=0,"記載なし","") | BO23: =IF(COUNTIFS('在庫使用計画 (法人)'!C:C,マスタ_EOLリスト[[#This Row],[製品型番]])=0,"記載なし","") | BP23: =IF(COUNTIFS('在庫使用計画 (全体実績+予測）0701'!C:C,マスタ_EOLリスト[[#This Row],[製品型番]])=0,"記載なし","") | BQ23: =IF(COUNTIFS('在庫使用計画 (計画 予測)'!C:C,マスタ_EOLリスト[[#This Row],[製品型番]])=0,"記載なし","") | BR23: =IF(COUNTIFS(在庫確認!B:B,マスタ_EOLリスト[[#This Row],[製品型番]])=0,"記載なし","") | BS23: =COUNTIF(#REF!,マスタ_EOLリスト[[#This Row],[製品型番]]) -> #REF!
A24: XL7C-R56-6A | B24: 3EOL(在庫あり) | C24: 1GALLERIA-G | D24: XL7C-R56-6A | E24: 214073 | F24: 組UNW X6AR556U(GG 16WQXGA 255HX 5060 240W L6) | G24: ID-U | H24: UNW-U-255HX-5060-L6 | I24: 16 | K24: u7-255HX | L24: 5060 | M24: 5 | N24: 5 | P24: 45925 | Q24: 2026年5月頃？ | V24: 1950 | W24: 786 | AN24: 240W | AO24: 20 | AP24: 12 | AQ24: 5525+ | AR24: 199685 | AS24: C5-C6 | AT24: 171480 | AW24: TRUE | AX24: 組UNW X6AR556U(GG 16WQXGA 255HX 5060 240W | AY24: 115 | BA24: S17S 暮石灰 | BB24: S17S 暮石灰 | BC24: S17S 暮石灰 | BD24: S17S 暮石灰 | BJ24: x | BM24: =IF(COUNTIFS('在庫使用計画 (ノート全体試算)'!C:C,マスタ_EOLリスト[[#This Row],[製品型番]])=0,"記載なし","") | BN24: =IF(COUNTIFS('在庫使用計画 (一般)'!C:C,マスタ_EOLリスト[[#This Row],[製品型番]])=0,"記載なし","") | BO24: =IF(COUNTIFS('在庫使用計画 (法人)'!C:C,マスタ_EOLリスト[[#This Row],[製品型番]])=0,"記載なし","") | BP24: =IF(COUNTIFS('在庫使用計画 (全体実績+予測）0701'!C:C,マスタ_EOLリスト[[#This Row],[製品型番]])=0,"記載なし","") | BQ24: =IF(COUNTIFS('在庫使用計画 (計画 予測)'!C:C,マスタ_EOLリスト[[#This Row],[製品型番]])=0,"記載なし","") | BR24: =IF(COUNTIFS(在庫確認!B:B,マスタ_EOLリスト[[#This Row],[製品型番]])=0,"記載なし","") | BS24: =COUNTIF(#REF!,マスタ_EOLリスト[[#This Row],[製品型番]]) -> #REF!
A25: #N/A | B25: 4EOL(完全終息) | C25: 1GALLERIA-G | D25: XL7C-R46H | E25: 186236 | F25: 組UNW PH6PG02(16WUXGA 13700H 4060 150W L6) | G25: 6H2 | M25: 0 | N25: 0 | Q25: 2024年6月頃 | R25: 代替候補はID別 | W25: 1248 | AC25: 2024/7頃 | AI25: 199408 | AL25: 45422 | AM25: 250 | AN25: 150W | AO25: 19 | AP25: 7.89 | AQ25: 5525+ | AX25: 在庫無し | BM25: =IF(COUNTIFS('在庫使用計画 (ノート全体試算)'!C:C,マスタ_EOLリスト[[#This Row],[製品型番]])=0,"記載なし","") -> 記載なし | BN25: =IF(COUNTIFS('在庫使用計画 (一般)'!C:C,マスタ_EOLリスト[[#This Row],[製品型番]])=0,"記載なし","") -> 記載なし | BO25: =IF(COUNTIFS('在庫使用計画 (法人)'!C:C,マスタ_EOLリスト[[#This Row],[製品型番]])=0,"記載なし","") -> 記載なし | BP25: =IF(COUNTIFS('在庫使用計画 (全体実績+予測）0701'!C:C,マスタ_EOLリスト[[#This Row],[製品型番]])=0,"記載なし","") -> 記載なし | BQ25: =IF(COUNTIFS('在庫使用計画 (計画 予測)'!C:C,マスタ_EOLリスト[[#This Row],[製品型番]])=0,"記載なし","") -> 記載なし | BR25: =IF(COUNTIFS(在庫確認!B:B,マスタ_EOLリスト[[#This Row],[製品型番]])=0,"記載なし","") -> 記載なし | BS25: =COUNTIF(#REF!,マスタ_EOLリスト[[#This Row],[製品型番]]) -> #REF!
A26: XL7C-R46-6 | B26: 4EOL(完全終息) | C26: 1GALLERIA-G | D26: XL7C-R46-6 | E26: 199408 | F26: 組CLE V561TND-TD(GG 16QHD+240Hz 155H 4060 180W L6) | G26: V56 | H26: CLE-V56-155H-4060-L6 | K26: u7-155H | L26: 4060 | M26: 0 | N26: 0 | P26: 45526 | Q26: 2025年4-5月 | U26: 2000で終了見込み | V26: 5010 | W26: 2000 | Z26: 212347 | AB26: 212469,214073 | AC26: intel/AMD +5060 | AL26: 45510 | AM26: 300 | AN26: 180W | AX26: 在庫無し | BA26: S17S 暮石灰 | BB26: S17S 暮石灰 | BC26: S17S 暮石灰 | BD26: S17S 暮石灰 | BM26: =IF(COUNTIFS('在庫使用計画 (ノート全体試算)'!C:C,マスタ_EOLリスト[[#This Row],[製品型番]])=0,"記載なし","") | BN26: =IF(COUNTIFS('在庫使用計画 (一般)'!C:C,マスタ_EOLリスト[[#This Row],[製品型番]])=0,"記載なし","") | BO26: =IF(COUNTIFS('在庫使用計画 (法人)'!C:C,マスタ_EOLリスト[[#This Row],[製品型番]])=0,"記載なし","") | BP26: =IF(COUNTIFS('在庫使用計画 (全体実績+予測）0701'!C:C,マスタ_EOLリスト[[#This Row],[製品型番]])=0,"記載なし","") | BQ26: =IF(COUNTIFS('在庫使用計画 (計画 予測)'!C:C,マスタ_EOLリスト[[#This Row],[製品型番]])=0,"記載なし","") -> 記載なし | BR26: =IF(COUNTIFS(在庫確認!B:B,マスタ_EOLリスト[[#This Row],[製品型番]])=0,"記載なし","") | BS26: =COUNTIF(#REF!,マスタ_EOLリスト[[#This Row],[製品型番]]) -> #REF!
A27: #N/A | B27: 4EOL(完全終息) | C27: 1GALLERIA-G | D27: XL7C-R46 | E27: 186232 | F27: 組TFH GM5PG0O(15FHD 13700H 4060 230W L6) | G27: ID-O3 | M27: 0 | N27: 0 | P27: 10月予定 | Q27: 2024年6月頃 | R27: 代替候補はID別 | W27: 3240 | Z27: 201898 | AC27: 2024/7頃 | AI27: 201898,199408 | AJ27: 201898は廉価、199408は16”MTL | AX27: 在庫無し | BA27: Galaxy Black | BB27: Black | BC27: Galaxy Black | BD27: Black | BM27: =IF(COUNTIFS('在庫使用計画 (ノート全体試算)'!C:C,マスタ_EOLリスト[[#This Row],[製品型番]])=0,"記載なし","") -> 記載なし | BN27: =IF(COUNTIFS('在庫使用計画 (一般)'!C:C,マスタ_EOLリスト[[#This Row],[製品型番]])=0,"記載なし","") -> 記載なし | BO27: =IF(COUNTIFS('在庫使用計画 (法人)'!C:C,マスタ_EOLリスト[[#This Row],[製品型番]])=0,"記載なし","") -> 記載なし | BP27: =IF(COUNTIFS('在庫使用計画 (全体実績+予測）0701'!C:C,マスタ_EOLリスト[[#This Row],[製品型番]])=0,"記載なし","") -> 記載なし | BQ27: =IF(COUNTIFS('在庫使用計画 (計画 予測)'!C:C,マスタ_EOLリスト[[#This Row],[製品型番]])=0,"記載なし","") -> 記載なし | BR27: =IF(COUNTIFS(在庫確認!B:B,マスタ_EOLリスト[[#This Row],[製品型番]])=0,"記載なし","") -> 記載なし | BS27: =COUNTIF(#REF!,マスタ_EOLリスト[[#This Row],[製品型番]]) -> #REF!
A28: #N/A | B28: 4EOL(完全終息) | C28: 1GALLERIA-G | D28: XL7C-R45H | E28: 181640 | F28: 組UNW PH6PG52(16WUXGA 13700H 4050 150W L9) | G28: 6H2 | M28: 0 | N28: 0 | P28: 45106 | R28: 代替候補はID別 | V28: 2000 | W28: 700 | X28: 71 | AC28: ↓L6に移行 | AN28: 150W | AO28: 19 | AP28: 7.89 | AQ28: 5525+ | AX28: 在庫無し | BA28: Galaxy Black | BB28: Black | BC28: Galaxy Black | BD28: Black | BM28: =IF(COUNTIFS('在庫使用計画 (ノート全体試算)'!C:C,マスタ_EOLリスト[[#This Row],[製品型番]])=0,"記載なし","") -> 記載なし | BN28: =IF(COUNTIFS('在庫使用計画 (一般)'!C:C,マスタ_EOLリスト[[#This Row],[製品型番]])=0,"記載なし","") -> 記載なし | BO28: =IF(COUNTIFS('在庫使用計画 (法人)'!C:C,マスタ_EOLリスト[[#This Row],[製品型番]])=0,"記載なし","") -> 記載なし | BP28: =IF(COUNTIFS('在庫使用計画 (全体実績+予測）0701'!C:C,マスタ_EOLリスト[[#This Row],[製品型番]])=0,"記載なし","") -> 記載なし | BQ28: =IF(COUNTIFS('在庫使用計画 (計画 予測)'!C:C,マスタ_EOLリスト[[#This Row],[製品型番]])=0,"記載なし","") -> 記載なし | BR28: =IF(COUNTIFS(在庫確認!B:B,マスタ_EOLリスト[[#This Row],[製品型番]])=0,"記載なし","") -> 記載なし | BS28: =COUNTIF(#REF!,マスタ_EOLリスト[[#This Row],[製品型番]]) -> #REF!
A29: XL7C-R45-6 | B29: 4EOL(完全終息) | C29: 1GALLERIA-G | D29: XL7C-R45-6 | E29: 199409 | F29: 組CLE V561TNC-TD(GG 16QHD+240Hz 155H 4050 180W L6) | G29: V56 | H29: CLE-V56-155H-4050-L6 | K29: u7-155H | L29: 4060 | M29: 0 | N29: 0 | P29: 45526 | Q29: 2025年4-5月 | U29: 1500で終了見込み | V29: 3350 | W29: 1500 | Z29: 216515 | AA29: 5050モデル | AB29: 212469,214073 | AC29: intel/AMD +5060 | AL29: 45530 | AM29: 240 | AN29: 180W | AX29: 在庫無し | BA29: S60 鐵灰 | BB29: S60 鐵灰 | BC29: S60 鐵灰 | BD29: S60 鐵灰 | BM29: =IF(COUNTIFS('在庫使用計画 (ノート全体試算)'!C:C,マスタ_EOLリスト[[#This Row],[製品型番]])=0,"記載なし","") | BN29: =IF(COUNTIFS('在庫使用計画 (一般)'!C:C,マスタ_EOLリスト[[#This Row],[製品型番]])=0,"記載なし","") | BO29: =IF(COUNTIFS('在庫使用計画 (法人)'!C:C,マスタ_EOLリスト[[#This Row],[製品型番]])=0,"記載なし","") | BP29: =IF(COUNTIFS('在庫使用計画 (全体実績+予測）0701'!C:C,マスタ_EOLリスト[[#This Row],[製品型番]])=0,"記載なし","") | BQ29: =IF(COUNTIFS('在庫使用計画 (計画 予測)'!C:C,マスタ_EOLリスト[[#This Row],[製品型番]])=0,"記載なし","") -> 記載なし | BR29: =IF(COUNTIFS(在庫確認!B:B,マスタ_EOLリスト[[#This Row],[製品型番]])=0,"記載なし","") | BS29: =COUNTIF(#REF!,マスタ_EOLリスト[[#This Row],[製品型番]]) -> #REF!
A30: #N/A | B30: 4EOL(完全終息) | C30: 1GALLERIA-G | D30: XL7C-R45 | E30: 179160 | F30: 組TFH GM5PG5O(15FHD 13700H 4050 230W L9) | G30: ID-O3 | K30: i7-13700H | L30: 4050 | M30: 0 | N30: 0 | P30: 45056 | R30: 代替候補はID別 | V30: 6780 | W30: 4350 | X30: 2397 | Z30: 201900 | AC30: ↓L6に移行 | AH30: 後継IDは変更 →ID-U | AI30: 201900,199409 | AJ30: 201900は廉価 | AX30: 在庫無し | BA30: S60 鐵灰 | BB30: S60 鐵灰 | BC30: S60 鐵灰 | BD30: S60 鐵灰 | BM30: =IF(COUNTIFS('在庫使用計画 (ノート全体試算)'!C:C,マスタ_EOLリスト[[#This Row],[製品型番]])=0,"記載なし","") -> 記載なし | BN30: =IF(COUNTIFS('在庫使用計画 (一般)'!C:C,マスタ_EOLリスト[[#This Row],[製品型番]])=0,"記載なし","") -> 記載なし | BO30: =IF(COUNTIFS('在庫使用計画 (法人)'!C:C,マスタ_EOLリスト[[#This Row],[製品型番]])=0,"記載なし","") -> 記載なし | BP30: =IF(COUNTIFS('在庫使用計画 (全体実績+予測）0701'!C:C,マスタ_EOLリスト[[#This Row],[製品型番]])=0,"記載なし","") -> 記載なし | BQ30: =IF(COUNTIFS('在庫使用計画 (計画 予測)'!C:C,マスタ_EOLリスト[[#This Row],[製品型番]])=0,"記載なし","") -> 記載なし | BR30: =IF(COUNTIFS(在庫確認!B:B,マスタ_EOLリスト[[#This Row],[製品型番]])=0,"記載なし","") -> 記載なし | BS30: =COUNTIF(#REF!,マスタ_EOLリスト[[#This Row],[製品型番]]) -> #REF!
A31: #N/A | B31: 4EOL(完全終息) | C31: 1GALLERIA-G | D31: XL7C-R45 | E31: 186233 | F31: 組TFH GM5PG5O(15FHD 13700H 4050 230W L6) | G31: ID-O3 | K31: i7-13700H | L31: 4050 | M31: 0 | N31: 0 | Q31: 2024年6月頃 | R31: 代替候補はID別 | W31: 5120 | Z31: 201900 | AC31: 2024/7頃 | AI31: 201900,199409 | AJ31: 201900は廉価 | AL31: 45422 | AM31: 60 | AX31: 在庫無し | BA31: S60 鐵灰 | BB31: S60 鐵灰 | BC31: S60 鐵灰 | BD31: S60 鐵灰 | BM31: =IF(COUNTIFS('在庫使用計画 (ノート全体試算)'!C:C,マスタ_EOLリスト[[#This Row],[製品型番]])=0,"記載なし","") -> 記載なし | BN31: =IF(COUNTIFS('在庫使用計画 (一般)'!C:C,マスタ_EOLリスト[[#This Row],[製品型番]])=0,"記載なし","") -> 記載なし | BO31: =IF(COUNTIFS('在庫使用計画 (法人)'!C:C,マスタ_EOLリスト[[#This Row],[製品型番]])=0,"記載なし","") -> 記載なし | BP31: =IF(COUNTIFS('在庫使用計画 (全体実績+予測）0701'!C:C,マスタ_EOLリスト[[#This Row],[製品型番]])=0,"記載なし","") -> 記載なし | BQ31: =IF(COUNTIFS('在庫使用計画 (計画 予測)'!C:C,マスタ_EOLリスト[[#This Row],[製品型番]])=0,"記載なし","") -> 記載なし | BR31: =IF(COUNTIFS(在庫確認!B:B,マスタ_EOLリスト[[#This Row],[製品型番]])=0,"記載なし","") -> 記載なし | BS31: =COUNTIF(#REF!,マスタ_EOLリスト[[#This Row],[製品型番]]) -> #REF!
A32: #N/A | B32: 5開発中止 | C32: 1GALLERIA-G | D32: NDC9L-R57T-G6 | G32: ID-K | H32: UNW-K-290HXP-5070Ti-L6 | I32: 16 | K32: ARL-HX R U9-290HX Plus | L32: 5070Ti | M32: 0 | N32: 0 | AX32: 在庫無し | BM32: =IF(COUNTIFS('在庫使用計画 (ノート全体試算)'!C:C,マスタ_EOLリスト[[#This Row],[製品型番]])=0,"記載なし","") -> 記載なし | BN32: =IF(COUNTIFS('在庫使用計画 (一般)'!C:C,マスタ_EOLリスト[[#This Row],[製品型番]])=0,"記載なし","") -> 記載なし | BO32: =IF(COUNTIFS('在庫使用計画 (法人)'!C:C,マスタ_EOLリスト[[#This Row],[製品型番]])=0,"記載なし","") -> 記載なし | BP32: =IF(COUNTIFS('在庫使用計画 (全体実績+予測）0701'!C:C,マスタ_EOLリスト[[#This Row],[製品型番]])=0,"記載なし","") -> 記載なし | BQ32: =IF(COUNTIFS('在庫使用計画 (計画 予測)'!C:C,マスタ_EOLリスト[[#This Row],[製品型番]])=0,"記載なし","") -> 記載なし | BR32: =IF(COUNTIFS(在庫確認!B:B,マスタ_EOLリスト[[#This Row],[製品型番]])=0,"記載なし","") -> 記載なし | BS32: =COUNTIF(#REF!,マスタ_EOLリスト[[#This Row],[製品型番]]) -> #REF!
A33: #N/A | B33: 5開発中止 | C33: 1GALLERIA-G | D33: NDC7L-R57-G6 | G33: ID-K | H33: UNW-K-270HXP-5070-L6 | I33: 16 | K33: ARL-HX U7-270HX Plus(仮) | L33: 5070 | M33: 0 | N33: 0 | AX33: 在庫無し | BM33: =IF(COUNTIFS('在庫使用計画 (ノート全体試算)'!C:C,マスタ_EOLリスト[[#This Row],[製品型番]])=0,"記載なし","") -> 記載なし | BN33: =IF(COUNTIFS('在庫使用計画 (一般)'!C:C,マスタ_EOLリスト[[#This Row],[製品型番]])=0,"記載なし","") -> 記載なし | BO33: =IF(COUNTIFS('在庫使用計画 (法人)'!C:C,マスタ_EOLリスト[[#This Row],[製品型番]])=0,"記載なし","") -> 記載なし | BP33: =IF(COUNTIFS('在庫使用計画 (全体実績+予測）0701'!C:C,マスタ_EOLリスト[[#This Row],[製品型番]])=0,"記載なし","") -> 記載なし | BQ33: =IF(COUNTIFS('在庫使用計画 (計画 予測)'!C:C,マスタ_EOLリスト[[#This Row],[製品型番]])=0,"記載なし","") -> 記載なし | BR33: =IF(COUNTIFS(在庫確認!B:B,マスタ_EOLリスト[[#This Row],[製品型番]])=0,"記載なし","") -> 記載なし | BS33: =COUNTIF(#REF!,マスタ_EOLリスト[[#This Row],[製品型番]]) -> #REF!
A34: RL7C-R56-5N | B34: 2発売中 | C34: 1GALLERIA-G | D34: RL7C-R56-5N | E34: 222818 | F34: 組CLE V350SNNQ(GG 15.6FHD 14650HX 5060 180W L6) | G34: V35 | H34: CLE-V35-14650HX-5060-L6 | I34: 15 | K34: i7-14650HX | L34: 5060 | M34: 53 | N34: 53 | P34: 45939 | R34: 7-8月にID-2に切替 | W34: 2726 | AU34: 65W-100W | AW34: TRUE | AX34: 組CLE V350SNNQ(GG 15.6FHD 14650HX 5060 18 | AY34: 115 | BA34: S17S 暮石灰 | BB34: S17S 暮石灰 | BC34: S17S 暮石灰 | BD34: S17S 暮石灰 | BJ34: NPC7L-R56-G5 | BM34: =IF(COUNTIFS('在庫使用計画 (ノート全体試算)'!C:C,マスタ_EOLリスト[[#This Row],[製品型番]])=0,"記載なし","") | BN34: =IF(COUNTIFS('在庫使用計画 (一般)'!C:C,マスタ_EOLリスト[[#This Row],[製品型番]])=0,"記載なし","") | BO34: =IF(COUNTIFS('在庫使用計画 (法人)'!C:C,マスタ_EOLリスト[[#This Row],[製品型番]])=0,"記載なし","") | BP34: =IF(COUNTIFS('在庫使用計画 (全体実績+予測）0701'!C:C,マスタ_EOLリスト[[#This Row],[製品型番]])=0,"記載なし","") | BQ34: =IF(COUNTIFS('在庫使用計画 (計画 予測)'!C:C,マスタ_EOLリスト[[#This Row],[製品型番]])=0,"記載なし","") | BR34: =IF(COUNTIFS(在庫確認!B:B,マスタ_EOLリスト[[#This Row],[製品型番]])=0,"記載なし","") | BS34: =COUNTIF(#REF!,マスタ_EOLリスト[[#This Row],[製品型番]]) -> #REF!
A35: RL7C-R56-5N | B35: 2発売中 | C35: 1GALLERIA-G | D35: RL7C-R56-5N | E35: 317460 | F35: 組CLE V350SNNQ(R1 GG 15.6FHD 14650HX 5060 180W L6) | G35: V35 | H35: CLE-V35-14650HX-5060-L6 | I35: 15 | K35: i7-14650HX | L35: 5060 | M35: 99 | N35: 99 | R35: 7-8月にID-2に切替 | AW35: TRUE | AX35: 組CLE V350SNNQ(R1 GG 15.6FHD 14650HX 5060 | BJ35: NPC7L-R56-G5 | BM35: =IF(COUNTIFS('在庫使用計画 (ノート全体試算)'!C:C,マスタ_EOLリスト[[#This Row],[製品型番]])=0,"記載なし","") | BN35: =IF(COUNTIFS('在庫使用計画 (一般)'!C:C,マスタ_EOLリスト[[#This Row],[製品型番]])=0,"記載なし","") | BO35: =IF(COUNTIFS('在庫使用計画 (法人)'!C:C,マスタ_EOLリスト[[#This Row],[製品型番]])=0,"記載なし","") | BP35: =IF(COUNTIFS('在庫使用計画 (全体実績+予測）0701'!C:C,マスタ_EOLリスト[[#This Row],[製品型番]])=0,"記載なし","") | BQ35: =IF(COUNTIFS('在庫使用計画 (計画 予測)'!C:C,マスタ_EOLリスト[[#This Row],[製品型番]])=0,"記載なし","") | BR35: =IF(COUNTIFS(在庫確認!B:B,マスタ_EOLリスト[[#This Row],[製品型番]])=0,"記載なし","") | BS35: =COUNTIF(#REF!,マスタ_EOLリスト[[#This Row],[製品型番]]) -> #REF!
A36: RL7C-R55-5N | B36: 2発売中 | C36: 1GALLERIA-G | D36: RL7C-R55-5N | E36: 216515 | F36: 組CLE V350SNMQ(GG 15.6FHD 14650HX 5050 180W L6) | G36: V35 | H36: CLE-V35-14650HX-5050-L6 | I36: 15 | K36: i7-14650HX | L36: 5050 | M36: 702 | N36: 702 | O36: 2025年5月末 | P36: 45832 | R36: 7-8月にID-2に切替 | V36: 6000 | W36: 3596 | AN36: 180W | AU36: 65W-100W | AW36: TRUE | AX36: 組CLE V350SNMQ(GG 15.6FHD 14650HX 5050 18 | AY36: 115 | BA36: S17S 暮石灰 | BB36: S17S 暮石灰 | BC36: S17S 暮石灰 | BD36: S17S 暮石灰 | BJ36: NPR7L-R55-G5 | BM36: =IF(COUNTIFS('在庫使用計画 (ノート全体試算)'!C:C,マスタ_EOLリスト[[#This Row],[製品型番]])=0,"記載なし","") | BN36: =IF(COUNTIFS('在庫使用計画 (一般)'!C:C,マスタ_EOLリスト[[#This Row],[製品型番]])=0,"記載なし","") | BO36: =IF(COUNTIFS('在庫使用計画 (法人)'!C:C,マスタ_EOLリスト[[#This Row],[製品型番]])=0,"記載なし","") | BP36: =IF(COUNTIFS('在庫使用計画 (全体実績+予測）0701'!C:C,マスタ_EOLリスト[[#This Row],[製品型番]])=0,"記載なし","") | BQ36: =IF(COUNTIFS('在庫使用計画 (計画 予測)'!C:C,マスタ_EOLリスト[[#This Row],[製品型番]])=0,"記載なし","") | BR36: =IF(COUNTIFS(在庫確認!B:B,マスタ_EOLリスト[[#This Row],[製品型番]])=0,"記載なし","") | BS36: =COUNTIF(#REF!,マスタ_EOLリスト[[#This Row],[製品型番]]) -> #REF!
A37: RL7C-R55-5N | B37: 2発売中 | C37: 1GALLERIA-G | D37: RL7C-R55-5N | E37: 317461 | F37: 組CLE V350SNMQ(R1 GG 15.6FHD 14650HX 5050 180W L6) | G37: V35 | H37: CLE-V35-14650HX-5050-L6 | I37: 15 | K37: i7-14650HX | L37: 5050 | M37: 0 | N37: 0 | R37: 7-8月にID-2に切替 | AW37: TRUE | AX37: 在庫無し | BJ37: NPR7L-R55-G5 | BM37: =IF(COUNTIFS('在庫使用計画 (ノート全体試算)'!C:C,マスタ_EOLリスト[[#This Row],[製品型番]])=0,"記載なし","") | BN37: =IF(COUNTIFS('在庫使用計画 (一般)'!C:C,マスタ_EOLリスト[[#This Row],[製品型番]])=0,"記載なし","") | BO37: =IF(COUNTIFS('在庫使用計画 (法人)'!C:C,マスタ_EOLリスト[[#This Row],[製品型番]])=0,"記載なし","") | BP37: =IF(COUNTIFS('在庫使用計画 (全体実績+予測）0701'!C:C,マスタ_EOLリスト[[#This Row],[製品型番]])=0,"記載なし","") | BQ37: =IF(COUNTIFS('在庫使用計画 (計画 予測)'!C:C,マスタ_EOLリスト[[#This Row],[製品型番]])=0,"記載なし","") | BR37: =IF(COUNTIFS(在庫確認!B:B,マスタ_EOLリスト[[#This Row],[製品型番]])=0,"記載なし","") | BS37: =COUNTIF(#REF!,マスタ_EOLリスト[[#This Row],[製品型番]]) -> #REF!
A38: RL7C-R46-5N | B38: 4EOL(完全終息) | C38: 1GALLERIA-G | D38: RL7C-R46-5N | E38: 201898 | F38: 組UNW GM5PD0O(GG 15.6FHD 13620H 4060 230W L6) | G38: ID-O3 | H38: UNW-O3-13620H-4060-L6 | I38: 15 | K38: i7-13620H | L38: 4060 | M38: 0 | N38: 0 | P38: 45561 | Q38: 45839 | U38: XL7C-R46 の後継 | W38: 6728 | Z38: 222818 | AA38: 5060モデル 10月発売 | AB38: 212469,216515 | AC38: V56 AMD + 5060 / ARL-HX + 5060 / V35 14650HX 5050 | AL38: 45537 | AM38: 6 | AN38: 230W | AX38: 在庫無し | BA38: Galaxy Black | BB38: Black | BC38: Galaxy Black | BD38: Black | BM38: =IF(COUNTIFS('在庫使用計画 (ノート全体試算)'!C:C,マスタ_EOLリスト[[#This Row],[製品型番]])=0,"記載なし","") | BN38: =IF(COUNTIFS('在庫使用計画 (一般)'!C:C,マスタ_EOLリスト[[#This Row],[製品型番]])=0,"記載なし","") | BO38: =IF(COUNTIFS('在庫使用計画 (法人)'!C:C,マスタ_EOLリスト[[#This Row],[製品型番]])=0,"記載なし","") | BP38: =IF(COUNTIFS('在庫使用計画 (全体実績+予測）0701'!C:C,マスタ_EOLリスト[[#This Row],[製品型番]])=0,"記載なし","") | BQ38: =IF(COUNTIFS('在庫使用計画 (計画 予測)'!C:C,マスタ_EOLリスト[[#This Row],[製品型番]])=0,"記載なし","") -> 記載なし | BR38: =IF(COUNTIFS(在庫確認!B:B,マスタ_EOLリスト[[#This Row],[製品型番]])=0,"記載なし","") | BS38: =COUNTIF(#REF!,マスタ_EOLリスト[[#This Row],[製品型番]]) -> #REF!
A39: RL7C-R45-5N | B39: 2発売中 | C39: 1GALLERIA-G | D39: RL7C-R45-5N | E39: 201900 | F39: 組UNW GM5PD5E(GG 15.6FHD 13620H 4050 230W L6) | G39: ID-E | H39: UNW-E-13620H-4050-L6 | I39: 15 | K39: i7-13620H | L39: 4050 | M39: 1414 | N39: 1414 | P39: 45561 | U39: XL7C-R45 の後継 | W39: 12078 | AC39: V35 14650HX 5050/5060 | AL39: 45553 | AM39: 35 | AN39: 230W | AO39: 19.5/20 | AP39: 11.8/11.5 | AQ39: 5525+ | AR39: 199688 | AS39: C13-14 | AT39: 171358 | AW39: TRUE | AX39: 組UNW GM5PD5E(GG 15.6FHD 13620H 4050 230W | AY39: 115 | BA39: S17S 暮石灰 | BB39: S17S 暮石灰 | BC39: S17S 暮石灰 | BD39: S17S 暮石灰 | BJ39: NPC5L-R55-G5 | BM39: =IF(COUNTIFS('在庫使用計画 (ノート全体試算)'!C:C,マスタ_EOLリスト[[#This Row],[製品型番]])=0,"記載なし","") | BN39: =IF(COUNTIFS('在庫使用計画 (一般)'!C:C,マスタ_EOLリスト[[#This Row],[製品型番]])=0,"記載なし","") | BO39: =IF(COUNTIFS('在庫使用計画 (法人)'!C:C,マスタ_EOLリスト[[#This Row],[製品型番]])=0,"記載なし","") | BP39: =IF(COUNTIFS('在庫使用計画 (全体実績+予測）0701'!C:C,マスタ_EOLリスト[[#This Row],[製品型番]])=0,"記載なし","") | BQ39: =IF(COUNTIFS('在庫使用計画 (計画 予測)'!C:C,マスタ_EOLリスト[[#This Row],[製品型番]])=0,"記載なし","") | BR39: =IF(COUNTIFS(在庫確認!B:B,マスタ_EOLリスト[[#This Row],[製品型番]])=0,"記載なし","") | BS39: =COUNTIF(#REF!,マスタ_EOLリスト[[#This Row],[製品型番]]) -> #REF!
A40: RL7C-R35-5N | B40: 3EOL(在庫あり) | C40: 1GALLERIA-G | D40: RL7C-R35-5N | E40: 199024 | F40: 組UNW GM5PD3E(R1 GG 15.6FHD 13620H 3050 180W L6) | G40: ID-E | H40: UNW-E-13620H-3050-L6 | I40: 15 | K40: i7-13620H | L40: 3050 | M40: 2039 | N40: 2039 | Q40: 2026年 6月頃 | R40: Copilot key対応版 | W40: 19980 | AK40: 207649 | AL40: 45525 | AM40: 70 | AN40: 180W | AO40: 19.5/20 | AP40: 9.23/8 | AQ40: 5525+ | AR40: 199687 | AS40: C5-C6 | AT40: 171480 | AW40: TRUE | AX40: 組UNW GM5PD3E(R1 GG 15.6FHD 13620H 3050 1 | BJ40: x | BM40: =IF(COUNTIFS('在庫使用計画 (ノート全体試算)'!C:C,マスタ_EOLリスト[[#This Row],[製品型番]])=0,"記載なし","") | BN40: =IF(COUNTIFS('在庫使用計画 (一般)'!C:C,マスタ_EOLリスト[[#This Row],[製品型番]])=0,"記載なし","") | BO40: =IF(COUNTIFS('在庫使用計画 (法人)'!C:C,マスタ_EOLリスト[[#This Row],[製品型番]])=0,"記載なし","") | BP40: =IF(COUNTIFS('在庫使用計画 (全体実績+予測）0701'!C:C,マスタ_EOLリスト[[#This Row],[製品型番]])=0,"記載なし","") | BQ40: =IF(COUNTIFS('在庫使用計画 (計画 予測)'!C:C,マスタ_EOLリスト[[#This Row],[製品型番]])=0,"記載なし","") | BR40: =IF(COUNTIFS(在庫確認!B:B,マスタ_EOLリスト[[#This Row],[製品型番]])=0,"記載なし","") | BS40: =COUNTIF(#REF!,マスタ_EOLリスト[[#This Row],[製品型番]]) -> #REF!
...

Sheet 基準データ
B2: 事業年度 | C2: 43 | D2: 期 | G2: 検索フォルダ名 | H2: ファイル名 | I2: 更新日時 | N2: 期 | O2: 40 | P2: 41 | Q2: 42 | R2: 43
B3: 期間 | C3: =DATE($C$2+1982,8,1) -> 45870 | D3: ～ | E3: =DATE($C$2+1983,7,31) -> 46234 | G3: 43上期 | H3: 【日次】ノート集計【2026年7月】_0702.xlsx | I3: 46206.535 | N3: 販売台数 | O3: 36293 | P3: 41075 | Q3: 41710 | R3: 21838
N4: SKU | O4: 44 | P4: 64 | Q4: 59 | R4: 37
B5: 基準日(最新出荷日) | C5: {=INT(実績ファイル更新日時[更新日時])-1} -> 46205 | E5: =TODAY() -> 46209 | N5: 台/SKU | O5: =O3/O4 -> 824.84091 | P5: =P3/P4 -> 641.79688 | Q5: =Q3/Q4 -> 706.94915 | R5: =R3/R4 -> 590.21622
B6: 月初日 | C6: =EOMONTH($C$5,-1)+1 -> 46204
B7: 月末日 | C7: =EOMONTH($C$5,0) -> 46234 | N7: 台数予算 | Q7: 30000
B8: 当月残日数 | C8: =C7-C5 -> 29 | N8: 必要SKU（800台/SKUとした場合） | Q8: =Q7/800 -> 37.5
B9: 残月割合 | C9: =($C$7-$C$5)/DAY($C$7) -> 0.93548387

Sheet このファイルについて
A2: ■ファイルの目的
B3: 製品の在庫過不足を確認し、購買の追加発注判断をかけるために、各販売計画を集計します。
B4: また、その妥当性（無理のある計画ではないか？）の判断も行います。
A7: ■概要
B8: 法人、一般の製品担当が販売計画を作成、合わせて全体としての計画数を集計します。
B9: 実績・予測値から妥当性を判断し、問題がある（予測と計画の差異が大きい）場合は各担当に確認します。
B10: ➡施策予定があり販売計画が上がる、競合や市場動向から計画が落ち込むなど、乖離が納得できるものならOK
B11: 妥当性判断ができたら集計したファイルを購買の『NoteONE計画』に反映します。
B12: ➡購買はこれを元に在庫手配、追加発注を行います。
B13: \\172.25.20.11\サードウェーブグループ\41上期\サードウェーブ\購買本部\【通常業務】\ONE
A18: ■大まかな流れ
B19: 在庫使用計画（一般）、在庫使用計画（法人）で更新された数値の合計が、在庫使用計画（ノート全体試算）に反映。
B20: 反映されたファイルについて、最新使用計画（mmdd更新）※mmddは日付でコピーを作成、それをもとにONE計画を更新。
B21: 日次集計ファイルは、最新使用計画（mmdd更新）の最新の日付を確認し、新しくなっていれば集計ファイルに反映。
B22: その際に、法人 一般もあわせて更新する。
B24: 企画： | C24: 『在庫使用計画（一般）』を更新。
B25: 法人： | C25: 『在庫使用計画（法人）』を更新。
B26: ノート担当： | C26: 週一回、ファイル更新を確認し、NoteONE計画のファイルを更新します。（月～火の午前中）
C27: 『在庫使用計画（全体）』をコピー、名称を『在庫使用計画（mmdd）』（mmddは更新日）に変更。
C28: 在庫使用計画 (計画 予測)のシートを確認し、計画を検証。（実績との乖離や在庫数が適正か確認）
C29: ↑の更新ファイルをもとに、購買がOne計画を更新
C30: 市村さんに連絡し、ノート日次集計のファイルに反映してもらう。
B32: 責任範囲 | Q32: tips
B33: 企画： | C33: 『在庫使用計画（一般）』のシート | Q33: ・Power Query更新時に「外部データのフォーマットが不正」といったエラーが出ることがあるが、
B34: 法人： | C34: 『在庫使用計画（法人）』のシート | Q34: Power Queryのプロセスが残留してしまっていることが原因の場合がある。
B35: ノート担当： | C35: 更新連絡を受けた後の購買への変更依頼（ONEファイルへの反映） | Q35: この場合、Microsoft.Mashup.Container.Loader.exeをタスクマネージャーから落とすことで改善
C36: 販売計画の妥当性確認、異常と見える場合は要素（施策対応、状況など）を確認。
C37: 必要に応じて、各担当者に計画再修正を行ってもらう。
A40: ■ファイルの構成
B41: 【在庫使用計画（全体実績+予測）】：先月までは実績、当月は着地予測を入力、次月以降は過去の係数（ブランドごとの前月比係数）をもとに予測値を試算
C42: 前月までは実績、当月は着地予測、次月以降は「当月予測x係数」による予測
B43: 【在庫使用計画 (ノート全体試算)】：TWとして全体の販売計画数を表示、このファイルをもとに日付ファイルを作成し、NoteONE計画のファイルに反映する
C44: 在庫使用計画 (一般)：製品担当者が一般分（通販・店舗）の販売計画を入力
C45: 在庫使用計画 (法人)：法人担当者が法人（法人営業分）の販売計画を入力
B46: 【在庫確認】：起点時（基本的には月初時点）の在庫と注残を確認。この先4か月、つまりこれから発注するものが入荷するまで販売計画を満たす在庫があるかどうか
C47: SAP貼り付け(901) ※()内は更新日付：SAPデータを貼り付け
C48: Onenote貼り付け(901) ※()内は更新日付：ONEデータを貼り付け
B50: 43期 | C50: 今期の予算と実績
B51: 在庫使用計画（mmdd）：最新の販売計画（過去計画の履歴）
A54: ■週次の作業ながれ
...

Sheet 在庫使用計画 (4ヶ月計)
B1: GALLERIA | C1: model名 | D1: 品目 | E1: CPU | F1: GPU | G1: メモリ | H1: 在庫+注残 | I1: 次回入荷日 | J1: 次回入荷数量 | K1: 922 | L1: 929 | M1: 1003 | N1: 1006 | O1: 1014 | P1: 1016 | Q1: 1020 | R1: 1027 | S1: 1028 | T1: 1105 | U1: 1110 | V1: 1111 | W1: 1112 | X1: 1117 | Y1: 1118 | Z1: 1120 | AA1: 1125 | AB1: 1128 | AC1: 1202 | AD1: 1205 | AE1: 1211 | AF1: 1215 | AG1: 1219 | AH1: 1224 | AI1: 0105 | AJ1: 0115 | AK1: 0119 | AL1: 0120 | AM1: 0121 | AN1: 0128 | AO1: 0129 | AP1: 0202 | AQ1: 0209 | AR1: 0210 | AS1: 0213 | AT1: 0216 | AU1: 0218
A2: 18"-G | B2: {=IF(C2:C27="","",_xlfn.XLOOKUP(C2:C27,マスタ_EOLリスト[製品型番],マスタ_EOLリスト[綽名]))} -> CLE-X58-275HX-5090-L6 | C2: UL9C-R59-8A | D2: {=IF($C2:$C27<>"", _xlfn.MAXIFS(#REF!,マスタ_EOLリスト[製品型番],$C2:$C27), "")} -> #REF! | E2: ARL i9-275HX | F2: 5090 | G2: DDR5 | H2: {=IF($C2:$C27<>"", _xlfn.XLOOKUP($C2:$C27, '在庫使用計画 (ノート全体試算)'!C:C, '在庫使用計画 (ノート全体試算)'!G:G),"")} -> 66 | I2: {=IF(_xlfn.ANCHORARRAY(D2)<>"", _xlfn.XLOOKUP(_xlfn.ANCHORARRAY(D2),購買計画one_note_貼り付け[コード],購買計画one_note_貼り付け[納品日],""), "")} -> #REF! | J2: {=IF(_xlfn.ANCHORARRAY(D2)<>"", _xlfn.XLOOKUP(_xlfn.ANCHORARRAY(D2),購買計画one_note_貼り付け[コード],購買計画one_note_貼り付け[数量],""), "")} -> #REF! | K2: 157.70079 | L2: 186.6368 | M2: 186.6368 | N2: 186.6368 | O2: 165.6368 | P2: 165.6368 | Q2: 165.6368 | R2: 165.6368 | S2: 165.6368 | T2: 190 | U2: 190 | V2: 190 | W2: 190 | X2: 190 | Y2: 190 | Z2: 190 | AA2: 190 | AB2: 227 | AC2: 227 | AD2: 227 | AE2: 181.77703 | AF2: 181.77703 | AG2: 164.09835 | AH2: 164.09835 | AI2: 143.10704 | AJ2: 143.10704 | AK2: 159.41505 | AL2: 160.41505 | AM2: 160.41505 | AN2: 160.41505 | AO2: 160.41505 | AP2: 141.94174 | AQ2: 144.94174 | AR2: 144.94174 | AS2: 144.94174 | AT2: 144.94174 | AU2: 176.94174 | AV2: {=IFERROR(_xlfn.XLOOKUP($C2, INDIRECT("'在庫使用計画 ("&AV$1&")'!D:D"), INDIRECT("'在庫使用計画 ("&AV$1&")'!I:I") ),"")} | AW2: {=IFERROR(_xlfn.XLOOKUP($C2, INDIRECT("'在庫使用計画 ("&AW$1&")'!D:D"), INDIRECT("'在庫使用計画 ("&AW$1&")'!I:I") ),"")} | AX2: {=IFERROR(_xlfn.XLOOKUP($C2, INDIRECT("'在庫使用計画 ("&AX$1&")'!D:D"), INDIRECT("'在庫使用計画 ("&AX$1&")'!I:I") ),"")}
B3: CLE-X58-290HXP-5090-L6-GG | C3: NMC9L-R59-G8 | D3: #REF! | H3: 137 | I3: #REF! | J3: #REF! | AQ3: 26.921683
B4: #N/A | C4: NMC9L-R58-G6 | D4: #REF! | H4: #N/A | I4: #REF! | J4: #REF! | AQ4: 0
AV5: {=IFERROR(_xlfn.XLOOKUP($C5, INDIRECT("'在庫使用計画 ("&AV$1&")'!D:D"), INDIRECT("'在庫使用計画 ("&AV$1&")'!I:I") ),"")} | AW5: {=IFERROR(_xlfn.XLOOKUP($C5, INDIRECT("'在庫使用計画 ("&AW$1&")'!D:D"), INDIRECT("'在庫使用計画 ("&AW$1&")'!I:I") ),"")} | AX5: {=IFERROR(_xlfn.XLOOKUP($C5, INDIRECT("'在庫使用計画 ("&AX$1&")'!D:D"), INDIRECT("'在庫使用計画 ("&AX$1&")'!I:I") ),"")}
A6: 16”-G | B6: UNW-K-9955HX-5070Ti-L6 | C6: ZL9R-R57T-6 | D6: #REF! | E6: FRR 9955HX | F6: 5070Ti | G6: DDR5 | H6: 11 | I6: #REF! | J6: #REF! | K6: 581.02728 | L6: 550.40934 | M6: 508.89653 | N6: 508.89653 | O6: 508.89653 | P6: 508.89653 | Q6: 508.89653 | R6: 508.89653 | S6: 508.89653 | T6: 497.94982 | U6: 497.94982 | V6: 497.94982 | W6: 497.94982 | X6: 497.94982 | Y6: 497.94982 | Z6: 545.94982 | AA6: 545.94982 | AB6: 602.33455 | AC6: 602.33455 | AD6: 602.33455 | AE6: 273.49833 | AF6: 273.49833 | AG6: 281.34424 | AH6: 281.34424 | AI6: 289.37465 | AJ6: 289.37465 | AK6: 324.75962 | AL6: 324.75962 | AM6: 324.75962 | AN6: 324.75962 | AO6: 324.75962 | AP6: 296.82522 | AQ6: 311.82522 | AR6: 311.82522 | AS6: 311.82522 | AT6: 311.82522 | AU6: 311.82522 | AV6: {=IFERROR(_xlfn.XLOOKUP($C6, INDIRECT("'在庫使用計画 ("&AV$1&")'!D:D"), INDIRECT("'在庫使用計画 ("&AV$1&")'!I:I") ),"")} | AW6: {=IFERROR(_xlfn.XLOOKUP($C6, INDIRECT("'在庫使用計画 ("&AW$1&")'!D:D"), INDIRECT("'在庫使用計画 ("&AW$1&")'!I:I") ),"")} | AX6: {=IFERROR(_xlfn.XLOOKUP($C6, INDIRECT("'在庫使用計画 ("&AX$1&")'!D:D"), INDIRECT("'在庫使用計画 ("&AX$1&")'!I:I") ),"")}
B7: #N/A | C7: NDR9L-R57T-G6Z | D7: #REF! | E7: ARL-HX U9-275HX | F7: 5070Ti | G7: DDR5 | H7: #N/A | I7: #REF! | J7: #REF! | K7: 499.77757 | L7: 488.11959 | M7: 302.68606 | N7: 302.68606 | O7: 305.68606 | P7: 305.68606 | Q7: 305.68606 | R7: 305.68606 | S7: 305.68606 | T7: 297.44417 | U7: 297.44417 | V7: 297.44417 | W7: 297.44417 | X7: 297.44417 | Y7: 297.44417 | Z7: 297.44417 | AA7: 297.44417 | AB7: 329.62264 | AC7: 329.62264 | AD7: 329.62264 | AE7: 499.99666 | AF7: 499.99666 | AG7: 496.6393 | AH7: 496.6393 | AI7: 511.69578 | AJ7: 511.69578 | AK7: 459.64838 | AL7: 459.64838 | AM7: 459.64838 | AN7: 459.64838 | AO7: 459.64838 | AP7: 433.11925 | AQ7: 0 | AR7: 0 | AS7: 0 | AT7: 0 | AV7: {=IFERROR(_xlfn.XLOOKUP($C7, INDIRECT("'在庫使用計画 ("&AV$1&")'!D:D"), INDIRECT("'在庫使用計画 ("&AV$1&")'!I:I") ),"")} | AW7: {=IFERROR(_xlfn.XLOOKUP($C7, INDIRECT("'在庫使用計画 ("&AW$1&")'!D:D"), INDIRECT("'在庫使用計画 ("&AW$1&")'!I:I") ),"")} | AX7: {=IFERROR(_xlfn.XLOOKUP($C7, INDIRECT("'在庫使用計画 ("&AX$1&")'!D:D"), INDIRECT("'在庫使用計画 ("&AX$1&")'!I:I") ),"")}
B8: UNW-K-275HX-5070Ti-L6 | C8: ZL9C-R57T-6A | D8: #REF! | E8: ARL-HX U9-275HX | F8: 5070Ti | G8: DDR5 | H8: 553 | I8: #REF! | J8: #REF! | K8: 499.77757 | L8: 488.11959 | M8: 302.68606 | N8: 302.68606 | O8: 305.68606 | P8: 305.68606 | Q8: 305.68606 | R8: 305.68606 | S8: 305.68606 | T8: 297.44417 | U8: 297.44417 | V8: 297.44417 | W8: 297.44417 | X8: 297.44417 | Y8: 297.44417 | Z8: 297.44417 | AA8: 297.44417 | AB8: 329.62264 | AC8: 329.62264 | AD8: 329.62264 | AE8: 499.99666 | AF8: 499.99666 | AG8: 496.6393 | AH8: 496.6393 | AI8: 511.69578 | AJ8: 511.69578 | AK8: 459.64838 | AL8: 459.64838 | AM8: 459.64838 | AN8: 459.64838 | AO8: 459.64838 | AP8: 433.11925 | AQ8: 455.11925 | AR8: 467.11925 | AS8: 467.11925 | AT8: 467.11925 | AU8: 467.11925 | AV8: {=IFERROR(_xlfn.XLOOKUP($C8, INDIRECT("'在庫使用計画 ("&AV$1&")'!D:D"), INDIRECT("'在庫使用計画 ("&AV$1&")'!I:I") ),"")} | AW8: {=IFERROR(_xlfn.XLOOKUP($C8, INDIRECT("'在庫使用計画 ("&AW$1&")'!D:D"), INDIRECT("'在庫使用計画 ("&AW$1&")'!I:I") ),"")} | AX8: {=IFERROR(_xlfn.XLOOKUP($C8, INDIRECT("'在庫使用計画 ("&AX$1&")'!D:D"), INDIRECT("'在庫使用計画 ("&AX$1&")'!I:I") ),"")}
B9: UNW-K-290HXP-5070Ti-L6 | C9: NDC9L-R57T-G6 | D9: #REF! | E9: ARL-HX U7-255HX | F9: 5070 | G9: DDR5 | H9: #N/A | I9: #REF! | J9: #REF! | K9: 433.93619 | L9: 431.12627 | M9: 328.10521 | N9: 328.10521 | O9: 361.10521 | P9: 361.10521 | Q9: 361.10521 | R9: 361.10521 | S9: 361.10521 | T9: 440.89273 | U9: 424.30866 | V9: 424.30866 | W9: 424.30866 | X9: 424.30866 | Y9: 424.30866 | Z9: 424.30866 | AA9: 424.30866 | AB9: 583.01245 | AC9: 583.01245 | AD9: 583.01245 | AE9: 358.27536 | AF9: 358.27536 | AG9: 386.54095 | AH9: 386.54095 | AI9: 379.58873 | AJ9: 379.58873 | AK9: 416.59963 | AL9: 416.59963 | AM9: 416.59963 | AN9: 416.59963 | AO9: 416.59963 | AP9: 384.17888 | AQ9: 0 | AR9: 0 | AS9: 0 | AT9: 0 | AU9: 0 | AV9: {=IFERROR(_xlfn.XLOOKUP($C9, INDIRECT("'在庫使用計画 ("&AV$1&")'!D:D"), INDIRECT("'在庫使用計画 ("&AV$1&")'!I:I") ),"")} | AW9: {=IFERROR(_xlfn.XLOOKUP($C9, INDIRECT("'在庫使用計画 ("&AW$1&")'!D:D"), INDIRECT("'在庫使用計画 ("&AW$1&")'!I:I") ),"")} | AX9: {=IFERROR(_xlfn.XLOOKUP($C9, INDIRECT("'在庫使用計画 ("&AX$1&")'!D:D"), INDIRECT("'在庫使用計画 ("&AX$1&")'!I:I") ),"")}
B10: UNW-K-255HX-5070-L6 | C10: ZL7C-R57-6A | D10: #REF! | E10: ARL-HX U7-255HX | F10: 5070 | G10: DDR5 | H10: 268 | I10: #REF! | J10: #REF! | K10: 433.93619 | L10: 431.12627 | M10: 328.10521 | N10: 328.10521 | O10: 361.10521 | P10: 361.10521 | Q10: 361.10521 | R10: 361.10521 | S10: 361.10521 | T10: 440.89273 | U10: 424.30866 | V10: 424.30866 | W10: 424.30866 | X10: 424.30866 | Y10: 424.30866 | Z10: 424.30866 | AA10: 424.30866 | AB10: 583.01245 | AC10: 583.01245 | AD10: 583.01245 | AE10: 358.27536 | AF10: 358.27536 | AG10: 386.54095 | AH10: 386.54095 | AI10: 379.58873 | AJ10: 379.58873 | AK10: 416.59963 | AL10: 416.59963 | AM10: 416.59963 | AN10: 416.59963 | AO10: 416.59963 | AP10: 384.17888 | AQ10: 371.17888 | AR10: 319.17343 | AS10: 319.17343 | AT10: 319.17343 | AU10: 319.17343 | AV10: {=IFERROR(_xlfn.XLOOKUP($C10, INDIRECT("'在庫使用計画 ("&AV$1&")'!D:D"), INDIRECT("'在庫使用計画 ("&AV$1&")'!I:I") ),"")} | AW10: {=IFERROR(_xlfn.XLOOKUP($C10, INDIRECT("'在庫使用計画 ("&AW$1&")'!D:D"), INDIRECT("'在庫使用計画 ("&AW$1&")'!I:I") ),"")} | AX10: {=IFERROR(_xlfn.XLOOKUP($C10, INDIRECT("'在庫使用計画 ("&AX$1&")'!D:D"), INDIRECT("'在庫使用計画 ("&AX$1&")'!I:I") ),"")}
B11: UNW-K-270HXP-5070-L6 | C11: NDC7L-R57-G6 | D11: #REF! | E11: Ryzen AI 7-350 | F11: 5060 | G11: DDR5 | H11: #N/A | I11: #REF! | J11: #REF! | K11: 317.37121 | L11: 325.36413 | M11: 411.95151 | N11: 411.95151 | O11: 411.95151 | P11: 411.95151 | Q11: 411.95151 | R11: 411.95151 | S11: 411.95151 | T11: 451.95151 | U11: 451.95151 | V11: 451.95151 | W11: 451.95151 | X11: 451.95151 | Y11: 451.95151 | Z11: 451.95151 | AA11: 451.95151 | AB11: 443.39759 | AC11: 443.39759 | AD11: 443.39759 | AE11: 384.66221 | AF11: 384.66221 | AG11: 297.6393 | AH11: 297.6393 | AI11: 279.69578 | AJ11: 279.69578 | AK11: 246.24243 | AL11: 276.24243 | AM11: 276.24243 | AN11: 276.24243 | AO11: 276.24243 | AP11: 262.23714 | AQ11: 0 | AR11: 0 | AS11: 0 | AT11: 0 | AU11: 0 | AV11: {=IFERROR(_xlfn.XLOOKUP($C11, INDIRECT("'在庫使用計画 ("&AV$1&")'!D:D"), INDIRECT("'在庫使用計画 ("&AV$1&")'!I:I") ),"")} | AW11: {=IFERROR(_xlfn.XLOOKUP($C11, INDIRECT("'在庫使用計画 ("&AW$1&")'!D:D"), INDIRECT("'在庫使用計画 ("&AW$1&")'!I:I") ),"")} | AX11: {=IFERROR(_xlfn.XLOOKUP($C11, INDIRECT("'在庫使用計画 ("&AX$1&")'!D:D"), INDIRECT("'在庫使用計画 ("&AX$1&")'!I:I") ),"")}
B12: CLE-V56-350-5060-L6 | C12: XL7R-R56-6A | D12: #REF! | E12: Ryzen AI 7-350 | F12: 5060 | G12: DDR5 | H12: 0 | I12: #REF! | J12: #REF! | K12: 317.37121 | L12: 325.36413 | M12: 411.95151 | N12: 411.95151 | O12: 411.95151 | P12: 411.95151 | Q12: 411.95151 | R12: 411.95151 | S12: 411.95151 | T12: 451.95151 | U12: 451.95151 | V12: 451.95151 | W12: 451.95151 | X12: 451.95151 | Y12: 451.95151 | Z12: 451.95151 | AA12: 451.95151 | AB12: 443.39759 | AC12: 443.39759 | AD12: 443.39759 | AE12: 384.66221 | AF12: 384.66221 | AG12: 297.6393 | AH12: 297.6393 | AI12: 279.69578 | AJ12: 279.69578 | AK12: 246.24243 | AL12: 276.24243 | AM12: 276.24243 | AN12: 276.24243 | AO12: 276.24243 | AP12: 262.23714 | AQ12: 254.23714 | AR12: 254.23714 | AS12: 254.23714 | AT12: 254.23714 | AU12: 254.23714 | AV12: {=IFERROR(_xlfn.XLOOKUP($C12, INDIRECT("'在庫使用計画 ("&AV$1&")'!D:D"), INDIRECT("'在庫使用計画 ("&AV$1&")'!I:I") ),"")} | AW12: {=IFERROR(_xlfn.XLOOKUP($C12, INDIRECT("'在庫使用計画 ("&AW$1&")'!D:D"), INDIRECT("'在庫使用計画 ("&AW$1&")'!I:I") ),"")} | AX12: {=IFERROR(_xlfn.XLOOKUP($C12, INDIRECT("'在庫使用計画 ("&AX$1&")'!D:D"), INDIRECT("'在庫使用計画 ("&AX$1&")'!I:I") ),"")}
B13: UNW-U-255HX-5060-L6 | C13: XL7C-R56-6A | D13: #REF! | E13: ARL-HX U7-255HX | F13: 5060 | G13: DDR5 | H13: 5 | I13: #REF! | J13: #REF! | K13: 587.65526 | L13: 619.74084 | M13: 187.94817 | N13: 187.94817 | O13: 185.94817 | P13: 185.94817 | Q13: 185.94817 | R13: 185.94817 | S13: 185.94817 | T13: 284.75548 | U13: 284.75548 | V13: 284.75548 | W13: 284.75548 | X13: 284.75548 | Y13: 284.75548 | Z13: 284.75548 | AA13: 284.75548 | AB13: 423.82859 | AC13: 423.82859 | AD13: 448.82859 | AE13: 332.44696 | AF13: 332.44696 | AG13: 318.3989 | AH13: 318.3989 | AI13: 332.07136 | AJ13: 332.07136 | AK13: 351.20739 | AL13: 351.20739 | AM13: 351.20739 | AN13: 351.20739 | AO13: 351.20739 | AP13: 346.23578 | AQ13: 350.23578 | AR13: 233.23578 | AS13: 233.23578 | AT13: 233.23578 | AU13: 233.23578 | AV13: {=IFERROR(_xlfn.XLOOKUP($C13, INDIRECT("'在庫使用計画 ("&AV$1&")'!D:D"), INDIRECT("'在庫使用計画 ("&AV$1&")'!I:I") ),"")} | AW13: {=IFERROR(_xlfn.XLOOKUP($C13, INDIRECT("'在庫使用計画 ("&AW$1&")'!D:D"), INDIRECT("'在庫使用計画 ("&AW$1&")'!I:I") ),"")} | AX13: {=IFERROR(_xlfn.XLOOKUP($C13, INDIRECT("'在庫使用計画 ("&AX$1&")'!D:D"), INDIRECT("'在庫使用計画 ("&AX$1&")'!I:I") ),"")}
AV14: {=IFERROR(_xlfn.XLOOKUP($C14, INDIRECT("'在庫使用計画 ("&AV$1&")'!D:D"), INDIRECT("'在庫使用計画 ("&AV$1&")'!I:I") ),"")} | AW14: {=IFERROR(_xlfn.XLOOKUP($C14, INDIRECT("'在庫使用計画 ("&AW$1&")'!D:D"), INDIRECT("'在庫使用計画 ("&AW$1&")'!I:I") ),"")} | AX14: {=IFERROR(_xlfn.XLOOKUP($C14, INDIRECT("'在庫使用計画 ("&AX$1&")'!D:D"), INDIRECT("'在庫使用計画 ("&AX$1&")'!I:I") ),"")}
A15: 15"-G | B15: UNW-2-14650HX-5070-L6-DDR5-15.3 | C15: NPC7L-R57-G5 | D15: #REF! | E15: RPL i7-14650HX | F15: 5060 | G15: DDR5 | H15: 0 | I15: #REF! | J15: #REF! | K15: 1605.1239 | L15: 2223.3461 | M15: 2223.3461 | N15: 2223.3461 | O15: 2178.3461 | P15: 2178.3461 | Q15: 2178.3461 | R15: 2178.3461 | S15: 2178.3461 | T15: 1619.5342 | U15: 1619.5342 | V15: 1619.5342 | W15: 1619.5342 | X15: 1619.5342 | Y15: 1619.5342 | Z15: 1844.5342 | AA15: 1844.5342 | AB15: 2046.9289 | AC15: 2046.9289 | AD15: 2046.9289 | AE15: 1183.767 | AF15: 1183.767 | AG15: 1587.7976 | AH15: 1587.7976 | AI15: 1574.4075 | AJ15: 1574.4075 | AK15: 1772.2819 | AL15: 1772.2819 | AM15: 1772.2819 | AN15: 1772.2819 | AO15: 1772.2819 | AP15: 1702.7196 | AQ15: 0 | AR15: 0 | AS15: 0 | AT15: 0 | AU15: 0 | AV15: {=IFERROR(_xlfn.XLOOKUP($C15, INDIRECT("'在庫使用計画 ("&AV$1&")'!D:D"), INDIRECT("'在庫使用計画 ("&AV$1&")'!I:I") ),"")} | AW15: {=IFERROR(_xlfn.XLOOKUP($C15, INDIRECT("'在庫使用計画 ("&AW$1&")'!D:D"), INDIRECT("'在庫使用計画 ("&AW$1&")'!I:I") ),"")} | AX15: {=IFERROR(_xlfn.XLOOKUP($C15, INDIRECT("'在庫使用計画 ("&AX$1&")'!D:D"), INDIRECT("'在庫使用計画 ("&AX$1&")'!I:I") ),"")}
